Workbook

Sheet 테스트 케이스
A2: ="Dream 3.0 "&CLEAN(A6)&" 단위테스트" -> Dream 3.0 정기점검실행_AP591 단위테스트
A4: 공통 | I4: G,H,I 행 수식 수정 금지
A5: 메뉴명 | B5: 기능 | C5: 테스트ID | D5: CASE | E5: STEP | F5: 테스트 예상 결과 | G5: 최근 실행 결과 | H5: 최근 실행 날짜 | I5: 이슈
A6: 정기점검실행_AP591 | B6: 카렌다(월간), 목록(조건) 검색 | C6: AP591_TC_001 | D6: 검색 필드의 기본값 세팅을 확인한다. | E6: 메뉴 페이지 접속시, 각 필드의 기본값 세팅 확인 | F6: 기본값이 설정되어있을 시, 메뉴 접속했을 때 해당 필드에 입력됨 | G6: {=IFERROR( IF(LEN(INDEX('테스트 실행 로그'!G$6:G$1022, MATCH(1, ('테스트 실행 로그'!C$6:C$1022=C6)*('테스트 실행 로그'!H$6:H$1022=MAX(IF(('테스트 실행 로그'!C$6:C$1022=C6)*('테스트 실행 로그'!H$6:H$1022<>""), '테스트 실행 로그'!H$6:H$1022))), 0)))=0, "결과 없음", INDEX('테스트 실행 로그'!G$6:G$1022, MATCH(1, ('테스트 실행 로그'!C$6:C$1022=C6)*('테스트 실행 로그'!H$6:H$1022=MAX(IF(('테스트 실행 로그'!C$6:C$1022=C6)*('테스트 실행 로그'!H$6:H$1022<>""), '테스트 실행 로그'!H$6:H$1022))), 0))), "결과 없음" )} -> Y | H6: {=IFERROR( IF(MAX(IF(('테스트 실행 로그'!C$6:C$1022=C6)*('테스트 실행 로그'!H$6:H$1022<>""), '테스트 실행 로그'!H$6:H$1022))=0, "날짜 없음", MAX(IF(('테스트 실행 로그'!C$6:C$1022=C6)*('테스트 실행 로그'!H$6:H$1022<>""), '테스트 실행 로그'!H$6:H$1022))), "날짜 없음" )} -> 45747 | I6: {=IFERROR(IF(LEN(INDEX('테스트 실행 로그'!I$6:I$1022, MATCH(1, ('테스트 실행 로그'!C$6:C$1022=C6)*('테스트 실행 로그'!H$6:H$1022=MAX(IF('테스트 실행 로그'!C$6:C$1022=C6, '테스트 실행 로그'!H$6:H$1022))), 0)))=0,"이슈 없음",INDEX('테스트 실행 로그'!I$6:I$1022, MATCH(1, ('테스트 실행 로그'!C$6:C$1022=C6)*('테스트 실행 로그'!H$6:H$1022=MAX(IF('테스트 실행 로그'!C$6:C$1022=C6, '테스트 실행 로그'!H$6:H$1022))), 0))),"이슈 없음")} -> 이슈 없음
C7: AP591_TC_002 | D7: 검색 필드의 필수값 세팅을 확인한다. | E7: 메뉴 페이지 접속시, 각 필드의 필수값 세팅 확인 | F7: 필수값 설정되어있을 시, 필드라벨과 필드란에 색깔로 표기됨 | G7: {=IFERROR( IF(LEN(INDEX('테스트 실행 로그'!G$6:G$1022, MATCH(1, ('테스트 실행 로그'!C$6:C$1022=C7)*('테스트 실행 로그'!H$6:H$1022=MAX(IF(('테스트 실행 로그'!C$6:C$1022=C7)*('테스트 실행 로그'!H$6:H$1022<>""), '테스트 실행 로그'!H$6:H$1022))), 0)))=0, "결과 없음", INDEX('테스트 실행 로그'!G$6:G$1022, MATCH(1, ('테스트 실행 로그'!C$6:C$1022=C7)*('테스트 실행 로그'!H$6:H$1022=MAX(IF(('테스트 실행 로그'!C$6:C$1022=C7)*('테스트 실행 로그'!H$6:H$1022<>""), '테스트 실행 로그'!H$6:H$1022))), 0))), "결과 없음" )} -> Y | H7: {=IFERROR( IF(MAX(IF(('테스트 실행 로그'!C$6:C$1022=C7)*('테스트 실행 로그'!H$6:H$1022<>""), '테스트 실행 로그'!H$6:H$1022))=0, "날짜 없음", MAX(IF(('테스트 실행 로그'!C$6:C$1022=C7)*('테스트 실행 로그'!H$6:H$1022<>""), '테스트 실행 로그'!H$6:H$1022))), "날짜 없음" )} -> 45776 | I7: {=IFERROR(IF(LEN(INDEX('테스트 실행 로그'!I$6:I$1022, MATCH(1, ('테스트 실행 로그'!C$6:C$1022=C7)*('테스트 실행 로그'!H$6:H$1022=MAX(IF('테스트 실행 로그'!C$6:C$1022=C7, '테스트 실행 로그'!H$6:H$1022))), 0)))=0,"이슈 없음",INDEX('테스트 실행 로그'!I$6:I$1022, MATCH(1, ('테스트 실행 로그'!C$6:C$1022=C7)*('테스트 실행 로그'!H$6:H$1022=MAX(IF('테스트 실행 로그'!C$6:C$1022=C7, '테스트 실행 로그'!H$6:H$1022))), 0))),"이슈 없음")} -> 이슈 없음
C8: AP591_TC_003 | D8: 검색 필드 Lov 팝업창의 데이터 세팅을 확인한다. | E8: 각 필드의 Lov 버튼 클릭 | F8: 특정 필드에 해당되는 Lov 팝업창 데이터 확인 | G8: {=IFERROR( IF(LEN(INDEX('테스트 실행 로그'!G$6:G$1022, MATCH(1, ('테스트 실행 로그'!C$6:C$1022=C8)*('테스트 실행 로그'!H$6:H$1022=MAX(IF(('테스트 실행 로그'!C$6:C$1022=C8)*('테스트 실행 로그'!H$6:H$1022<>""), '테스트 실행 로그'!H$6:H$1022))), 0)))=0, "결과 없음", INDEX('테스트 실행 로그'!G$6:G$1022, MATCH(1, ('테스트 실행 로그'!C$6:C$1022=C8)*('테스트 실행 로그'!H$6:H$1022=MAX(IF(('테스트 실행 로그'!C$6:C$1022=C8)*('테스트 실행 로그'!H$6:H$1022<>""), '테스트 실행 로그'!H$6:H$1022))), 0))), "결과 없음" )} -> Y | H8: {=IFERROR( IF(MAX(IF(('테스트 실행 로그'!C$6:C$1022=C8)*('테스트 실행 로그'!H$6:H$1022<>""), '테스트 실행 로그'!H$6:H$1022))=0, "날짜 없음", MAX(IF(('테스트 실행 로그'!C$6:C$1022=C8)*('테스트 실행 로그'!H$6:H$1022<>""), '테스트 실행 로그'!H$6:H$1022))), "날짜 없음" )} -> 45757 | I8: {=IFERROR(IF(LEN(INDEX('테스트 실행 로그'!I$6:I$1022, MATCH(1, ('테스트 실행 로그'!C$6:C$1022=C8)*('테스트 실행 로그'!H$6:H$1022=MAX(IF('테스트 실행 로그'!C$6:C$1022=C8, '테스트 실행 로그'!H$6:H$1022))), 0)))=0,"이슈 없음",INDEX('테스트 실행 로그'!I$6:I$1022, MATCH(1, ('테스트 실행 로그'!C$6:C$1022=C8)*('테스트 실행 로그'!H$6:H$1022=MAX(IF('테스트 실행 로그'!C$6:C$1022=C8, '테스트 실행 로그'!H$6:H$1022))), 0))),"이슈 없음")} -> 이슈 없음
C9: AP591_TC_004 | D9: 조건에 맞는 정기점검실행 데이터를 검색한다. | E9: 각 검색필드에 데이터 입력 후 검색 버튼 클릭 | F9: 입력한 필드 값에 해당되는 데이터만 목록에 표시됨 (목록 우측하단 total : n/n 숫자와 조회된 데이터 개수(순번)와 일치) | G9: {=IFERROR( IF(LEN(INDEX('테스트 실행 로그'!G$6:G$1022, MATCH(1, ('테스트 실행 로그'!C$6:C$1022=C9)*('테스트 실행 로그'!H$6:H$1022=MAX(IF(('테스트 실행 로그'!C$6:C$1022=C9)*('테스트 실행 로그'!H$6:H$1022<>""), '테스트 실행 로그'!H$6:H$1022))), 0)))=0, "결과 없음", INDEX('테스트 실행 로그'!G$6:G$1022, MATCH(1, ('테스트 실행 로그'!C$6:C$1022=C9)*('테스트 실행 로그'!H$6:H$1022=MAX(IF(('테스트 실행 로그'!C$6:C$1022=C9)*('테스트 실행 로그'!H$6:H$1022<>""), '테스트 실행 로그'!H$6:H$1022))), 0))), "결과 없음" )} -> Y | H9: {=IFERROR( IF(MAX(IF(('테스트 실행 로그'!C$6:C$1022=C9)*('테스트 실행 로그'!H$6:H$1022<>""), '테스트 실행 로그'!H$6:H$1022))=0, "날짜 없음", MAX(IF(('테스트 실행 로그'!C$6:C$1022=C9)*('테스트 실행 로그'!H$6:H$1022<>""), '테스트 실행 로그'!H$6:H$1022))), "날짜 없음" )} -> 45747 | I9: {=IFERROR(IF(LEN(INDEX('테스트 실행 로그'!I$6:I$1022, MATCH(1, ('테스트 실행 로그'!C$6:C$1022=C9)*('테스트 실행 로그'!H$6:H$1022=MAX(IF('테스트 실행 로그'!C$6:C$1022=C9, '테스트 실행 로그'!H$6:H$1022))), 0)))=0,"이슈 없음",INDEX('테스트 실행 로그'!I$6:I$1022, MATCH(1, ('테스트 실행 로그'!C$6:C$1022=C9)*('테스트 실행 로그'!H$6:H$1022=MAX(IF('테스트 실행 로그'!C$6:C$1022=C9, '테스트 실행 로그'!H$6:H$1022))), 0))),"이슈 없음")} -> 이슈 없음
C10: AP591_TC_005 | D10: 정기점검실행 데이터를 전체 검색한다. | E10: 각 검색필드에 입력된 데이터 전체 삭제 후 검색 버튼 클릭 | F10: 등록된 전체 데이터가 목록에 표시됨 (목록 우측하단 total : n/n 숫자와 조회된 데이터 개수(순번)와 일치) | G10: {=IFERROR( IF(LEN(INDEX('테스트 실행 로그'!G$6:G$1022, MATCH(1, ('테스트 실행 로그'!C$6:C$1022=C10)*('테스트 실행 로그'!H$6:H$1022=MAX(IF(('테스트 실행 로그'!C$6:C$1022=C10)*('테스트 실행 로그'!H$6:H$1022<>""), '테스트 실행 로그'!H$6:H$1022))), 0)))=0, "결과 없음", INDEX('테스트 실행 로그'!G$6:G$1022, MATCH(1, ('테스트 실행 로그'!C$6:C$1022=C10)*('테스트 실행 로그'!H$6:H$1022=MAX(IF(('테스트 실행 로그'!C$6:C$1022=C10)*('테스트 실행 로그'!H$6:H$1022<>""), '테스트 실행 로그'!H$6:H$1022))), 0))), "결과 없음" )} -> Y | H10: {=IFERROR( IF(MAX(IF(('테스트 실행 로그'!C$6:C$1022=C10)*('테스트 실행 로그'!H$6:H$1022<>""), '테스트 실행 로그'!H$6:H$1022))=0, "날짜 없음", MAX(IF(('테스트 실행 로그'!C$6:C$1022=C10)*('테스트 실행 로그'!H$6:H$1022<>""), '테스트 실행 로그'!H$6:H$1022))), "날짜 없음" )} -> 45747 | I10: {=IFERROR(IF(LEN(INDEX('테스트 실행 로그'!I$6:I$1022, MATCH(1, ('테스트 실행 로그'!C$6:C$1022=C10)*('테스트 실행 로그'!H$6:H$1022=MAX(IF('테스트 실행 로그'!C$6:C$1022=C10, '테스트 실행 로그'!H$6:H$1022))), 0)))=0,"이슈 없음",INDEX('테스트 실행 로그'!I$6:I$1022, MATCH(1, ('테스트 실행 로그'!C$6:C$1022=C10)*('테스트 실행 로그'!H$6:H$1022=MAX(IF('테스트 실행 로그'!C$6:C$1022=C10, '테스트 실행 로그'!H$6:H$1022))), 0))),"이슈 없음")} -> 이슈 없음
C11: AP591_TC_006 | D11: 조회된 데이터의 목록을 정렬한다. | E11: 목록의 그리드 헤더 클릭 | F11: 선택한 헤더의 필드값 기준으로 오름차순, 내림차순 정렬됨 | G11: {=IFERROR( IF(LEN(INDEX('테스트 실행 로그'!G$6:G$1022, MATCH(1, ('테스트 실행 로그'!C$6:C$1022=C11)*('테스트 실행 로그'!H$6:H$1022=MAX(IF(('테스트 실행 로그'!C$6:C$1022=C11)*('테스트 실행 로그'!H$6:H$1022<>""), '테스트 실행 로그'!H$6:H$1022))), 0)))=0, "결과 없음", INDEX('테스트 실행 로그'!G$6:G$1022, MATCH(1, ('테스트 실행 로그'!C$6:C$1022=C11)*('테스트 실행 로그'!H$6:H$1022=MAX(IF(('테스트 실행 로그'!C$6:C$1022=C11)*('테스트 실행 로그'!H$6:H$1022<>""), '테스트 실행 로그'!H$6:H$1022))), 0))), "결과 없음" )} -> Y | H11: {=IFERROR( IF(MAX(IF(('테스트 실행 로그'!C$6:C$1022=C11)*('테스트 실행 로그'!H$6:H$1022<>""), '테스트 실행 로그'!H$6:H$1022))=0, "날짜 없음", MAX(IF(('테스트 실행 로그'!C$6:C$1022=C11)*('테스트 실행 로그'!H$6:H$1022<>""), '테스트 실행 로그'!H$6:H$1022))), "날짜 없음" )} -> 45747 | I11: {=IFERROR(IF(LEN(INDEX('테스트 실행 로그'!I$6:I$1022, MATCH(1, ('테스트 실행 로그'!C$6:C$1022=C11)*('테스트 실행 로그'!H$6:H$1022=MAX(IF('테스트 실행 로그'!C$6:C$1022=C11, '테스트 실행 로그'!H$6:H$1022))), 0)))=0,"이슈 없음",INDEX('테스트 실행 로그'!I$6:I$1022, MATCH(1, ('테스트 실행 로그'!C$6:C$1022=C11)*('테스트 실행 로그'!H$6:H$1022=MAX(IF('테스트 실행 로그'!C$6:C$1022=C11, '테스트 실행 로그'!H$6:H$1022))), 0))),"이슈 없음")} -> 이슈 없음
C12: AP591_TC_007 | D12: (행 클릭) 조회된 데이터의 상세정보를 조회한다. | E12: 검색된 목록 데이터 행 클릭 | F12: 검색된 목록 하단에 펼쳐지는 상세페이지에서 해당 데이터의 각 항목에 입력된 값을 확인할 수 있음 | G12: {=IFERROR( IF(LEN(INDEX('테스트 실행 로그'!G$6:G$1022, MATCH(1, ('테스트 실행 로그'!C$6:C$1022=C12)*('테스트 실행 로그'!H$6:H$1022=MAX(IF(('테스트 실행 로그'!C$6:C$1022=C12)*('테스트 실행 로그'!H$6:H$1022<>""), '테스트 실행 로그'!H$6:H$1022))), 0)))=0, "결과 없음", INDEX('테스트 실행 로그'!G$6:G$1022, MATCH(1, ('테스트 실행 로그'!C$6:C$1022=C12)*('테스트 실행 로그'!H$6:H$1022=MAX(IF(('테스트 실행 로그'!C$6:C$1022=C12)*('테스트 실행 로그'!H$6:H$1022<>""), '테스트 실행 로그'!H$6:H$1022))), 0))), "결과 없음" )} -> Y | H12: {=IFERROR( IF(MAX(IF(('테스트 실행 로그'!C$6:C$1022=C12)*('테스트 실행 로그'!H$6:H$1022<>""), '테스트 실행 로그'!H$6:H$1022))=0, "날짜 없음", MAX(IF(('테스트 실행 로그'!C$6:C$1022=C12)*('테스트 실행 로그'!H$6:H$1022<>""), '테스트 실행 로그'!H$6:H$1022))), "날짜 없음" )} -> 45757 | I12: {=IFERROR(IF(LEN(INDEX('테스트 실행 로그'!I$6:I$1022, MATCH(1, ('테스트 실행 로그'!C$6:C$1022=C12)*('테스트 실행 로그'!H$6:H$1022=MAX(IF('테스트 실행 로그'!C$6:C$1022=C12, '테스트 실행 로그'!H$6:H$1022))), 0)))=0,"이슈 없음",INDEX('테스트 실행 로그'!I$6:I$1022, MATCH(1, ('테스트 실행 로그'!C$6:C$1022=C12)*('테스트 실행 로그'!H$6:H$1022=MAX(IF('테스트 실행 로그'!C$6:C$1022=C12, '테스트 실행 로그'!H$6:H$1022))), 0))),"이슈 없음")} -> 이슈 없음
C13: AP591_TC_008 | D13: (상세보기 버튼 클릭) 조회된 데이터의 상세정보를 조회한다. | E13: 목록에서 특정 데이터 행 클릭 후 상세보기 버튼 클릭 | F13: 선택한 데이터의 상세페이지가 팝업창으로 열림 (목록 하단에 펼쳐지는 상세페이지와 내용 동일) | G13: {=IFERROR( IF(LEN(INDEX('테스트 실행 로그'!G$6:G$1022, MATCH(1, ('테스트 실행 로그'!C$6:C$1022=C13)*('테스트 실행 로그'!H$6:H$1022=MAX(IF(('테스트 실행 로그'!C$6:C$1022=C13)*('테스트 실행 로그'!H$6:H$1022<>""), '테스트 실행 로그'!H$6:H$1022))), 0)))=0, "결과 없음", INDEX('테스트 실행 로그'!G$6:G$1022, MATCH(1, ('테스트 실행 로그'!C$6:C$1022=C13)*('테스트 실행 로그'!H$6:H$1022=MAX(IF(('테스트 실행 로그'!C$6:C$1022=C13)*('테스트 실행 로그'!H$6:H$1022<>""), '테스트 실행 로그'!H$6:H$1022))), 0))), "결과 없음" )} -> Y | H13: {=IFERROR( IF(MAX(IF(('테스트 실행 로그'!C$6:C$1022=C13)*('테스트 실행 로그'!H$6:H$1022<>""), '테스트 실행 로그'!H$6:H$1022))=0, "날짜 없음", MAX(IF(('테스트 실행 로그'!C$6:C$1022=C13)*('테스트 실행 로그'!H$6:H$1022<>""), '테스트 실행 로그'!H$6:H$1022))), "날짜 없음" )} -> 45747 | I13: {=IFERROR(IF(LEN(INDEX('테스트 실행 로그'!I$6:I$1022, MATCH(1, ('테스트 실행 로그'!C$6:C$1022=C13)*('테스트 실행 로그'!H$6:H$1022=MAX(IF('테스트 실행 로그'!C$6:C$1022=C13, '테스트 실행 로그'!H$6:H$1022))), 0)))=0,"이슈 없음",INDEX('테스트 실행 로그'!I$6:I$1022, MATCH(1, ('테스트 실행 로그'!C$6:C$1022=C13)*('테스트 실행 로그'!H$6:H$1022=MAX(IF('테스트 실행 로그'!C$6:C$1022=C13, '테스트 실행 로그'!H$6:H$1022))), 0))),"이슈 없음")} -> 이슈 없음
C14: AP591_TC_009 | D14: (목록) 검색된 데이터의 포맷 형태를 확인한다. | E14: 검색 후 목록에 조회된 각 데이터 종류에 따른 포맷 형태를 확인한다. | F14: 숫자는 천단위 반점표기, 날짜는 yyyy-mm-dd (숫자 : 오른쪽 정렬 , 텍스트 : 왼쪽 정렬 , 코드/날짜 : 가운데 정렬) | G14: {=IFERROR( IF(LEN(INDEX('테스트 실행 로그'!G$6:G$1022, MATCH(1, ('테스트 실행 로그'!C$6:C$1022=C14)*('테스트 실행 로그'!H$6:H$1022=MAX(IF(('테스트 실행 로그'!C$6:C$1022=C14)*('테스트 실행 로그'!H$6:H$1022<>""), '테스트 실행 로그'!H$6:H$1022))), 0)))=0, "결과 없음", INDEX('테스트 실행 로그'!G$6:G$1022, MATCH(1, ('테스트 실행 로그'!C$6:C$1022=C14)*('테스트 실행 로그'!H$6:H$1022=MAX(IF(('테스트 실행 로그'!C$6:C$1022=C14)*('테스트 실행 로그'!H$6:H$1022<>""), '테스트 실행 로그'!H$6:H$1022))), 0))), "결과 없음" )} -> Y | H14: {=IFERROR( IF(MAX(IF(('테스트 실행 로그'!C$6:C$1022=C14)*('테스트 실행 로그'!H$6:H$1022<>""), '테스트 실행 로그'!H$6:H$1022))=0, "날짜 없음", MAX(IF(('테스트 실행 로그'!C$6:C$1022=C14)*('테스트 실행 로그'!H$6:H$1022<>""), '테스트 실행 로그'!H$6:H$1022))), "날짜 없음" )} -> 45747 | I14: {=IFERROR(IF(LEN(INDEX('테스트 실행 로그'!I$6:I$1022, MATCH(1, ('테스트 실행 로그'!C$6:C$1022=C14)*('테스트 실행 로그'!H$6:H$1022=MAX(IF('테스트 실행 로그'!C$6:C$1022=C14, '테스트 실행 로그'!H$6:H$1022))), 0)))=0,"이슈 없음",INDEX('테스트 실행 로그'!I$6:I$1022, MATCH(1, ('테스트 실행 로그'!C$6:C$1022=C14)*('테스트 실행 로그'!H$6:H$1022=MAX(IF('테스트 실행 로그'!C$6:C$1022=C14, '테스트 실행 로그'!H$6:H$1022))), 0))),"이슈 없음")} -> 이슈 없음
C15: AP591_TC_010 | D15: (상세) 검색된 데이터의 포맷 형태를 확인한다. | E15: 검색 후 상세에 조회된 각 데이터 종류에 따른 포맷 형태를 확인한다. | F15: 숫자는 천단위 반점표기, 날짜는 yyyy-mm-dd (숫자 : 오른쪽 정렬 , 텍스트 : 왼쪽 정렬 , 코드/날짜 : 가운데 정렬) | G15: {=IFERROR( IF(LEN(INDEX('테스트 실행 로그'!G$6:G$1022, MATCH(1, ('테스트 실행 로그'!C$6:C$1022=C15)*('테스트 실행 로그'!H$6:H$1022=MAX(IF(('테스트 실행 로그'!C$6:C$1022=C15)*('테스트 실행 로그'!H$6:H$1022<>""), '테스트 실행 로그'!H$6:H$1022))), 0)))=0, "결과 없음", INDEX('테스트 실행 로그'!G$6:G$1022, MATCH(1, ('테스트 실행 로그'!C$6:C$1022=C15)*('테스트 실행 로그'!H$6:H$1022=MAX(IF(('테스트 실행 로그'!C$6:C$1022=C15)*('테스트 실행 로그'!H$6:H$1022<>""), '테스트 실행 로그'!H$6:H$1022))), 0))), "결과 없음" )} -> Y | H15: {=IFERROR( IF(MAX(IF(('테스트 실행 로그'!C$6:C$1022=C15)*('테스트 실행 로그'!H$6:H$1022<>""), '테스트 실행 로그'!H$6:H$1022))=0, "날짜 없음", MAX(IF(('테스트 실행 로그'!C$6:C$1022=C15)*('테스트 실행 로그'!H$6:H$1022<>""), '테스트 실행 로그'!H$6:H$1022))), "날짜 없음" )} -> 45747 | I15: {=IFERROR(IF(LEN(INDEX('테스트 실행 로그'!I$6:I$1022, MATCH(1, ('테스트 실행 로그'!C$6:C$1022=C15)*('테스트 실행 로그'!H$6:H$1022=MAX(IF('테스트 실행 로그'!C$6:C$1022=C15, '테스트 실행 로그'!H$6:H$1022))), 0)))=0,"이슈 없음",INDEX('테스트 실행 로그'!I$6:I$1022, MATCH(1, ('테스트 실행 로그'!C$6:C$1022=C15)*('테스트 실행 로그'!H$6:H$1022=MAX(IF('테스트 실행 로그'!C$6:C$1022=C15, '테스트 실행 로그'!H$6:H$1022))), 0))),"이슈 없음")} -> 이슈 없음
B16: 닫기 | C16: AP591_TC_011 | D16: 상세페이지를 닫는다. | E16: 하단에 펼쳐진 상세페이지 닫기버튼 (ⓧ) 클릭 | F16: 상세페이지 닫힘 | G16: {=IFERROR( IF(LEN(INDEX('테스트 실행 로그'!G$6:G$1022, MATCH(1, ('테스트 실행 로그'!C$6:C$1022=C16)*('테스트 실행 로그'!H$6:H$1022=MAX(IF(('테스트 실행 로그'!C$6:C$1022=C16)*('테스트 실행 로그'!H$6:H$1022<>""), '테스트 실행 로그'!H$6:H$1022))), 0)))=0, "결과 없음", INDEX('테스트 실행 로그'!G$6:G$1022, MATCH(1, ('테스트 실행 로그'!C$6:C$1022=C16)*('테스트 실행 로그'!H$6:H$1022=MAX(IF(('테스트 실행 로그'!C$6:C$1022=C16)*('테스트 실행 로그'!H$6:H$1022<>""), '테스트 실행 로그'!H$6:H$1022))), 0))), "결과 없음" )} -> Y | H16: {=IFERROR( IF(MAX(IF(('테스트 실행 로그'!C$6:C$1022=C16)*('테스트 실행 로그'!H$6:H$1022<>""), '테스트 실행 로그'!H$6:H$1022))=0, "날짜 없음", MAX(IF(('테스트 실행 로그'!C$6:C$1022=C16)*('테스트 실행 로그'!H$6:H$1022<>""), '테스트 실행 로그'!H$6:H$1022))), "날짜 없음" )} -> 45747 | I16: {=IFERROR(IF(LEN(INDEX('테스트 실행 로그'!I$6:I$1022, MATCH(1, ('테스트 실행 로그'!C$6:C$1022=C16)*('테스트 실행 로그'!H$6:H$1022=MAX(IF('테스트 실행 로그'!C$6:C$1022=C16, '테스트 실행 로그'!H$6:H$1022))), 0)))=0,"이슈 없음",INDEX('테스트 실행 로그'!I$6:I$1022, MATCH(1, ('테스트 실행 로그'!C$6:C$1022=C16)*('테스트 실행 로그'!H$6:H$1022=MAX(IF('테스트 실행 로그'!C$6:C$1022=C16, '테스트 실행 로그'!H$6:H$1022))), 0))),"이슈 없음")} -> 이슈 없음
C17: AP591_TC_012 | D17: (팝업창) 상세페이지를 닫는다. | E17: 창닫기 X 버튼 클릭 | F17: 상세페이지 닫힘 | G17: {=IFERROR( IF(LEN(INDEX('테스트 실행 로그'!G$6:G$1022, MATCH(1, ('테스트 실행 로그'!C$6:C$1022=C17)*('테스트 실행 로그'!H$6:H$1022=MAX(IF(('테스트 실행 로그'!C$6:C$1022=C17)*('테스트 실행 로그'!H$6:H$1022<>""), '테스트 실행 로그'!H$6:H$1022))), 0)))=0, "결과 없음", INDEX('테스트 실행 로그'!G$6:G$1022, MATCH(1, ('테스트 실행 로그'!C$6:C$1022=C17)*('테스트 실행 로그'!H$6:H$1022=MAX(IF(('테스트 실행 로그'!C$6:C$1022=C17)*('테스트 실행 로그'!H$6:H$1022<>""), '테스트 실행 로그'!H$6:H$1022))), 0))), "결과 없음" )} -> Y | H17: {=IFERROR( IF(MAX(IF(('테스트 실행 로그'!C$6:C$1022=C17)*('테스트 실행 로그'!H$6:H$1022<>""), '테스트 실행 로그'!H$6:H$1022))=0, "날짜 없음", MAX(IF(('테스트 실행 로그'!C$6:C$1022=C17)*('테스트 실행 로그'!H$6:H$1022<>""), '테스트 실행 로그'!H$6:H$1022))), "날짜 없음" )} -> 45747 | I17: {=IFERROR(IF(LEN(INDEX('테스트 실행 로그'!I$6:I$1022, MATCH(1, ('테스트 실행 로그'!C$6:C$1022=C17)*('테스트 실행 로그'!H$6:H$1022=MAX(IF('테스트 실행 로그'!C$6:C$1022=C17, '테스트 실행 로그'!H$6:H$1022))), 0)))=0,"이슈 없음",INDEX('테스트 실행 로그'!I$6:I$1022, MATCH(1, ('테스트 실행 로그'!C$6:C$1022=C17)*('테스트 실행 로그'!H$6:H$1022=MAX(IF('테스트 실행 로그'!C$6:C$1022=C17, '테스트 실행 로그'!H$6:H$1022))), 0))),"이슈 없음")} -> 이슈 없음
B18: 카렌다(월간), 목록(조건) 수정 | C18: AP591_TC_013 | D18: 저장된 정기점검실행 데이터의 필수값과 그 외 값을 수정한다. | E18: 상세화면(혹은 상세보기 팝업)에서 데이터 수정, 저장 클릭 후 저장 팝업창에서 OK 버튼 클릭 | F18: 변경사항이 저장됨 (상세보기 팝업창에서 수정 후 목록에 반영되려면 재검색 혹은 새로고침해야함) | G18: {=IFERROR( IF(LEN(INDEX('테스트 실행 로그'!G$6:G$1022, MATCH(1, ('테스트 실행 로그'!C$6:C$1022=C18)*('테스트 실행 로그'!H$6:H$1022=MAX(IF(('테스트 실행 로그'!C$6:C$1022=C18)*('테스트 실행 로그'!H$6:H$1022<>""), '테스트 실행 로그'!H$6:H$1022))), 0)))=0, "결과 없음", INDEX('테스트 실행 로그'!G$6:G$1022, MATCH(1, ('테스트 실행 로그'!C$6:C$1022=C18)*('테스트 실행 로그'!H$6:H$1022=MAX(IF(('테스트 실행 로그'!C$6:C$1022=C18)*('테스트 실행 로그'!H$6:H$1022<>""), '테스트 실행 로그'!H$6:H$1022))), 0))), "결과 없음" )} -> Y | H18: {=IFERROR( IF(MAX(IF(('테스트 실행 로그'!C$6:C$1022=C18)*('테스트 실행 로그'!H$6:H$1022<>""), '테스트 실행 로그'!H$6:H$1022))=0, "날짜 없음", MAX(IF(('테스트 실행 로그'!C$6:C$1022=C18)*('테스트 실행 로그'!H$6:H$1022<>""), '테스트 실행 로그'!H$6:H$1022))), "날짜 없음" )} -> 45747 | I18: {=IFERROR(IF(LEN(INDEX('테스트 실행 로그'!I$6:I$1022, MATCH(1, ('테스트 실행 로그'!C$6:C$1022=C18)*('테스트 실행 로그'!H$6:H$1022=MAX(IF('테스트 실행 로그'!C$6:C$1022=C18, '테스트 실행 로그'!H$6:H$1022))), 0)))=0,"이슈 없음",INDEX('테스트 실행 로그'!I$6:I$1022, MATCH(1, ('테스트 실행 로그'!C$6:C$1022=C18)*('테스트 실행 로그'!H$6:H$1022=MAX(IF('테스트 실행 로그'!C$6:C$1022=C18, '테스트 실행 로그'!H$6:H$1022))), 0))),"이슈 없음")} -> 이슈 없음
C19: AP591_TC_014 | D19: 저장된 정기점검실행 데이터의 필수값을 제외 한 후 그 외 값을 수정한다. | E19: 상세화면(혹은 상세보기 팝업)에서 필수값 삭제 후 데이터 수정, 저장 클릭 후 저장 팝업창에서 OK 버튼 클릭 | F19: 필수값 누락에 대한 팝업 표시. 수정 불가 확인 | G19: {=IFERROR( IF(LEN(INDEX('테스트 실행 로그'!G$6:G$1022, MATCH(1, ('테스트 실행 로그'!C$6:C$1022=C19)*('테스트 실행 로그'!H$6:H$1022=MAX(IF(('테스트 실행 로그'!C$6:C$1022=C19)*('테스트 실행 로그'!H$6:H$1022<>""), '테스트 실행 로그'!H$6:H$1022))), 0)))=0, "결과 없음", INDEX('테스트 실행 로그'!G$6:G$1022, MATCH(1, ('테스트 실행 로그'!C$6:C$1022=C19)*('테스트 실행 로그'!H$6:H$1022=MAX(IF(('테스트 실행 로그'!C$6:C$1022=C19)*('테스트 실행 로그'!H$6:H$1022<>""), '테스트 실행 로그'!H$6:H$1022))), 0))), "결과 없음" )} -> Y | H19: {=IFERROR( IF(MAX(IF(('테스트 실행 로그'!C$6:C$1022=C19)*('테스트 실행 로그'!H$6:H$1022<>""), '테스트 실행 로그'!H$6:H$1022))=0, "날짜 없음", MAX(IF(('테스트 실행 로그'!C$6:C$1022=C19)*('테스트 실행 로그'!H$6:H$1022<>""), '테스트 실행 로그'!H$6:H$1022))), "날짜 없음" )} -> 45747 | I19: {=IFERROR(IF(LEN(INDEX('테스트 실행 로그'!I$6:I$1022, MATCH(1, ('테스트 실행 로그'!C$6:C$1022=C19)*('테스트 실행 로그'!H$6:H$1022=MAX(IF('테스트 실행 로그'!C$6:C$1022=C19, '테스트 실행 로그'!H$6:H$1022))), 0)))=0,"이슈 없음",INDEX('테스트 실행 로그'!I$6:I$1022, MATCH(1, ('테스트 실행 로그'!C$6:C$1022=C19)*('테스트 실행 로그'!H$6:H$1022=MAX(IF('테스트 실행 로그'!C$6:C$1022=C19, '테스트 실행 로그'!H$6:H$1022))), 0))),"이슈 없음")} -> 이슈 없음
B20: 카렌다(월간), 목록(조건) Excel | C20: AP591_TC_015 | D20: 목록에 조회된 데이터를 Excel 다운로드한다. | E20: 1. 검색필드에 필요한 데이터 입력 후 검색 2. Excel 버튼 클릭 | F20: 1. 검색 조건에 맞는 데이터가 조회됨 2. 검색된 데이터가 입력된 Excel 파일이 다운로드됨 (검색결과가 없는 상태에서 클릭시, 목록 헤더만 입력된 Excel 파일이 다운로드 됨) | G20: {=IFERROR( IF(LEN(INDEX('테스트 실행 로그'!G$6:G$1022, MATCH(1, ('테스트 실행 로그'!C$6:C$1022=C20)*('테스트 실행 로그'!H$6:H$1022=MAX(IF(('테스트 실행 로그'!C$6:C$1022=C20)*('테스트 실행 로그'!H$6:H$1022<>""), '테스트 실행 로그'!H$6:H$1022))), 0)))=0, "결과 없음", INDEX('테스트 실행 로그'!G$6:G$1022, MATCH(1, ('테스트 실행 로그'!C$6:C$1022=C20)*('테스트 실행 로그'!H$6:H$1022=MAX(IF(('테스트 실행 로그'!C$6:C$1022=C20)*('테스트 실행 로그'!H$6:H$1022<>""), '테스트 실행 로그'!H$6:H$1022))), 0))), "결과 없음" )} -> Y | H20: {=IFERROR( IF(MAX(IF(('테스트 실행 로그'!C$6:C$1022=C20)*('테스트 실행 로그'!H$6:H$1022<>""), '테스트 실행 로그'!H$6:H$1022))=0, "날짜 없음", MAX(IF(('테스트 실행 로그'!C$6:C$1022=C20)*('테스트 실행 로그'!H$6:H$1022<>""), '테스트 실행 로그'!H$6:H$1022))), "날짜 없음" )} -> 45747 | I20: {=IFERROR(IF(LEN(INDEX('테스트 실행 로그'!I$6:I$1022, MATCH(1, ('테스트 실행 로그'!C$6:C$1022=C20)*('테스트 실행 로그'!H$6:H$1022=MAX(IF('테스트 실행 로그'!C$6:C$1022=C20, '테스트 실행 로그'!H$6:H$1022))), 0)))=0,"이슈 없음",INDEX('테스트 실행 로그'!I$6:I$1022, MATCH(1, ('테스트 실행 로그'!C$6:C$1022=C20)*('테스트 실행 로그'!H$6:H$1022=MAX(IF('테스트 실행 로그'!C$6:C$1022=C20, '테스트 실행 로그'!H$6:H$1022))), 0))),"이슈 없음")} -> 이슈 없음
B21: 카렌다(월간), 목록(조건) 검색 Setting | C21: AP591_TC_016 | D21: 검색 입력필드 순서를 변경한다. | E21: Setting 버튼 클릭, Setting 팝업창에서 특정 필드 항목의 정렬값 숫자를 변경 후 저장 | F21: 해당 필드가 정렬값대로 나열됨 (작은 숫자일수록 앞에 나열됨) | G21: {=IFERROR( IF(LEN(INDEX('테스트 실행 로그'!G$6:G$1022, MATCH(1, ('테스트 실행 로그'!C$6:C$1022=C21)*('테스트 실행 로그'!H$6:H$1022=MAX(IF(('테스트 실행 로그'!C$6:C$1022=C21)*('테스트 실행 로그'!H$6:H$1022<>""), '테스트 실행 로그'!H$6:H$1022))), 0)))=0, "결과 없음", INDEX('테스트 실행 로그'!G$6:G$1022, MATCH(1, ('테스트 실행 로그'!C$6:C$1022=C21)*('테스트 실행 로그'!H$6:H$1022=MAX(IF(('테스트 실행 로그'!C$6:C$1022=C21)*('테스트 실행 로그'!H$6:H$1022<>""), '테스트 실행 로그'!H$6:H$1022))), 0))), "결과 없음" )} -> Y | H21: {=IFERROR( IF(MAX(IF(('테스트 실행 로그'!C$6:C$1022=C21)*('테스트 실행 로그'!H$6:H$1022<>""), '테스트 실행 로그'!H$6:H$1022))=0, "날짜 없음", MAX(IF(('테스트 실행 로그'!C$6:C$1022=C21)*('테스트 실행 로그'!H$6:H$1022<>""), '테스트 실행 로그'!H$6:H$1022))), "날짜 없음" )} -> 45807 | I21: {=IFERROR(IF(LEN(INDEX('테스트 실행 로그'!I$6:I$1022, MATCH(1, ('테스트 실행 로그'!C$6:C$1022=C21)*('테스트 실행 로그'!H$6:H$1022=MAX(IF('테스트 실행 로그'!C$6:C$1022=C21, '테스트 실행 로그'!H$6:H$1022))), 0)))=0,"이슈 없음",INDEX('테스트 실행 로그'!I$6:I$1022, MATCH(1, ('테스트 실행 로그'!C$6:C$1022=C21)*('테스트 실행 로그'!H$6:H$1022=MAX(IF('테스트 실행 로그'!C$6:C$1022=C21, '테스트 실행 로그'!H$6:H$1022))), 0))),"이슈 없음")} -> 이슈 없음
C22: AP591_TC_017 | D22: 검색 입력필드를 보이지 않게 숨긴다. | E22: Setting 버튼 클릭, Setting 팝업창에서 특정 필드 숨김 설정 (화면 Display여부 N) 후 저장 | F22: 해당 필드가 검색에서 숨겨짐 | G22: {=IFERROR( IF(LEN(INDEX('테스트 실행 로그'!G$6:G$1022, MATCH(1, ('테스트 실행 로그'!C$6:C$1022=C22)*('테스트 실행 로그'!H$6:H$1022=MAX(IF(('테스트 실행 로그'!C$6:C$1022=C22)*('테스트 실행 로그'!H$6:H$1022<>""), '테스트 실행 로그'!H$6:H$1022))), 0)))=0, "결과 없음", INDEX('테스트 실행 로그'!G$6:G$1022, MATCH(1, ('테스트 실행 로그'!C$6:C$1022=C22)*('테스트 실행 로그'!H$6:H$1022=MAX(IF(('테스트 실행 로그'!C$6:C$1022=C22)*('테스트 실행 로그'!H$6:H$1022<>""), '테스트 실행 로그'!H$6:H$1022))), 0))), "결과 없음" )} -> Y | H22: {=IFERROR( IF(MAX(IF(('테스트 실행 로그'!C$6:C$1022=C22)*('테스트 실행 로그'!H$6:H$1022<>""), '테스트 실행 로그'!H$6:H$1022))=0, "날짜 없음", MAX(IF(('테스트 실행 로그'!C$6:C$1022=C22)*('테스트 실행 로그'!H$6:H$1022<>""), '테스트 실행 로그'!H$6:H$1022))), "날짜 없음" )} -> 45807 | I22: {=IFERROR(IF(LEN(INDEX('테스트 실행 로그'!I$6:I$1022, MATCH(1, ('테스트 실행 로그'!C$6:C$1022=C22)*('테스트 실행 로그'!H$6:H$1022=MAX(IF('테스트 실행 로그'!C$6:C$1022=C22, '테스트 실행 로그'!H$6:H$1022))), 0)))=0,"이슈 없음",INDEX('테스트 실행 로그'!I$6:I$1022, MATCH(1, ('테스트 실행 로그'!C$6:C$1022=C22)*('테스트 실행 로그'!H$6:H$1022=MAX(IF('테스트 실행 로그'!C$6:C$1022=C22, '테스트 실행 로그'!H$6:H$1022))), 0))),"이슈 없음")} -> 이슈 없음
C23: AP591_TC_018 | D23: 검색 입력필드를 보이도록 한다. | E23: Setting 버튼 클릭, Setting 팝업창에서 특정 필드 숨김 설정 (화면 Display여부 Y) 후 저장 | F23: 해당 필드가 검색에서 보임 | G23: {=IFERROR( IF(LEN(INDEX('테스트 실행 로그'!G$6:G$1022, MATCH(1, ('테스트 실행 로그'!C$6:C$1022=C23)*('테스트 실행 로그'!H$6:H$1022=MAX(IF(('테스트 실행 로그'!C$6:C$1022=C23)*('테스트 실행 로그'!H$6:H$1022<>""), '테스트 실행 로그'!H$6:H$1022))), 0)))=0, "결과 없음", INDEX('테스트 실행 로그'!G$6:G$1022, MATCH(1, ('테스트 실행 로그'!C$6:C$1022=C23)*('테스트 실행 로그'!H$6:H$1022=MAX(IF(('테스트 실행 로그'!C$6:C$1022=C23)*('테스트 실행 로그'!H$6:H$1022<>""), '테스트 실행 로그'!H$6:H$1022))), 0))), "결과 없음" )} -> Y | H23: {=IFERROR( IF(MAX(IF(('테스트 실행 로그'!C$6:C$1022=C23)*('테스트 실행 로그'!H$6:H$1022<>""), '테스트 실행 로그'!H$6:H$1022))=0, "날짜 없음", MAX(IF(('테스트 실행 로그'!C$6:C$1022=C23)*('테스트 실행 로그'!H$6:H$1022<>""), '테스트 실행 로그'!H$6:H$1022))), "날짜 없음" )} -> 45807 | I23: {=IFERROR(IF(LEN(INDEX('테스트 실행 로그'!I$6:I$1022, MATCH(1, ('테스트 실행 로그'!C$6:C$1022=C23)*('테스트 실행 로그'!H$6:H$1022=MAX(IF('테스트 실행 로그'!C$6:C$1022=C23, '테스트 실행 로그'!H$6:H$1022))), 0)))=0,"이슈 없음",INDEX('테스트 실행 로그'!I$6:I$1022, MATCH(1, ('테스트 실행 로그'!C$6:C$1022=C23)*('테스트 실행 로그'!H$6:H$1022=MAX(IF('테스트 실행 로그'!C$6:C$1022=C23, '테스트 실행 로그'!H$6:H$1022))), 0))),"이슈 없음")} -> 이슈 없음
C24: AP591_TC_019 | D24: 검색 입력필드명을 변경한다. | E24: Setting 버튼 클릭, Setting 팝업창에서 특정 필드 항목의 화면표시명 필드 값 변경 후 저장 | F24: 해당 필드의 필드명이 변경됨 (새로고침 후 반영 확인) | G24: {=IFERROR( IF(LEN(INDEX('테스트 실행 로그'!G$6:G$1022, MATCH(1, ('테스트 실행 로그'!C$6:C$1022=C24)*('테스트 실행 로그'!H$6:H$1022=MAX(IF(('테스트 실행 로그'!C$6:C$1022=C24)*('테스트 실행 로그'!H$6:H$1022<>""), '테스트 실행 로그'!H$6:H$1022))), 0)))=0, "결과 없음", INDEX('테스트 실행 로그'!G$6:G$1022, MATCH(1, ('테스트 실행 로그'!C$6:C$1022=C24)*('테스트 실행 로그'!H$6:H$1022=MAX(IF(('테스트 실행 로그'!C$6:C$1022=C24)*('테스트 실행 로그'!H$6:H$1022<>""), '테스트 실행 로그'!H$6:H$1022))), 0))), "결과 없음" )} -> Y | H24: {=IFERROR( IF(MAX(IF(('테스트 실행 로그'!C$6:C$1022=C24)*('테스트 실행 로그'!H$6:H$1022<>""), '테스트 실행 로그'!H$6:H$1022))=0, "날짜 없음", MAX(IF(('테스트 실행 로그'!C$6:C$1022=C24)*('테스트 실행 로그'!H$6:H$1022<>""), '테스트 실행 로그'!H$6:H$1022))), "날짜 없음" )} -> 45807 | I24: {=IFERROR(IF(LEN(INDEX('테스트 실행 로그'!I$6:I$1022, MATCH(1, ('테스트 실행 로그'!C$6:C$1022=C24)*('테스트 실행 로그'!H$6:H$1022=MAX(IF('테스트 실행 로그'!C$6:C$1022=C24, '테스트 실행 로그'!H$6:H$1022))), 0)))=0,"이슈 없음",INDEX('테스트 실행 로그'!I$6:I$1022, MATCH(1, ('테스트 실행 로그'!C$6:C$1022=C24)*('테스트 실행 로그'!H$6:H$1022=MAX(IF('테스트 실행 로그'!C$6:C$1022=C24, '테스트 실행 로그'!H$6:H$1022))), 0))),"이슈 없음")} -> 이슈 없음
B25: 상세 Setting | C25: AP591_TC_020 | D25: 상세 입력필드 순서를 변경한다. | E25: Setting 버튼 클릭, Setting 팝업창에서 특정 필드 항목의 정렬값 숫자를 변경 후 저장 | F25: 해당 필드가 정렬값대로 나열됨 (작은 숫자일수록 앞에 나열됨, 새로고침 후 반영 확인) | G25: {=IFERROR( IF(LEN(INDEX('테스트 실행 로그'!G$6:G$1022, MATCH(1, ('테스트 실행 로그'!C$6:C$1022=C25)*('테스트 실행 로그'!H$6:H$1022=MAX(IF(('테스트 실행 로그'!C$6:C$1022=C25)*('테스트 실행 로그'!H$6:H$1022<>""), '테스트 실행 로그'!H$6:H$1022))), 0)))=0, "결과 없음", INDEX('테스트 실행 로그'!G$6:G$1022, MATCH(1, ('테스트 실행 로그'!C$6:C$1022=C25)*('테스트 실행 로그'!H$6:H$1022=MAX(IF(('테스트 실행 로그'!C$6:C$1022=C25)*('테스트 실행 로그'!H$6:H$1022<>""), '테스트 실행 로그'!H$6:H$1022))), 0))), "결과 없음" )} -> Y | H25: {=IFERROR( IF(MAX(IF(('테스트 실행 로그'!C$6:C$1022=C25)*('테스트 실행 로그'!H$6:H$1022<>""), '테스트 실행 로그'!H$6:H$1022))=0, "날짜 없음", MAX(IF(('테스트 실행 로그'!C$6:C$1022=C25)*('테스트 실행 로그'!H$6:H$1022<>""), '테스트 실행 로그'!H$6:H$1022))), "날짜 없음" )} -> 45807 | I25: {=IFERROR(IF(LEN(INDEX('테스트 실행 로그'!I$6:I$1022, MATCH(1, ('테스트 실행 로그'!C$6:C$1022=C25)*('테스트 실행 로그'!H$6:H$1022=MAX(IF('테스트 실행 로그'!C$6:C$1022=C25, '테스트 실행 로그'!H$6:H$1022))), 0)))=0,"이슈 없음",INDEX('테스트 실행 로그'!I$6:I$1022, MATCH(1, ('테스트 실행 로그'!C$6:C$1022=C25)*('테스트 실행 로그'!H$6:H$1022=MAX(IF('테스트 실행 로그'!C$6:C$1022=C25, '테스트 실행 로그'!H$6:H$1022))), 0))),"이슈 없음")} -> 이슈 없음
C26: AP591_TC_021 | D26: 상세 입력필드를 보이지 않게 숨긴다. | E26: Setting 버튼 클릭, Setting 팝업창에서 특정 필드 숨김 설정 (화면 Display여부 N) 후 저장 | F26: 해당 필드가 상세에서 숨겨짐 | G26: {=IFERROR( IF(LEN(INDEX('테스트 실행 로그'!G$6:G$1022, MATCH(1, ('테스트 실행 로그'!C$6:C$1022=C26)*('테스트 실행 로그'!H$6:H$1022=MAX(IF(('테스트 실행 로그'!C$6:C$1022=C26)*('테스트 실행 로그'!H$6:H$1022<>""), '테스트 실행 로그'!H$6:H$1022))), 0)))=0, "결과 없음", INDEX('테스트 실행 로그'!G$6:G$1022, MATCH(1, ('테스트 실행 로그'!C$6:C$1022=C26)*('테스트 실행 로그'!H$6:H$1022=MAX(IF(('테스트 실행 로그'!C$6:C$1022=C26)*('테스트 실행 로그'!H$6:H$1022<>""), '테스트 실행 로그'!H$6:H$1022))), 0))), "결과 없음" )} -> Y | H26: {=IFERROR( IF(MAX(IF(('테스트 실행 로그'!C$6:C$1022=C26)*('테스트 실행 로그'!H$6:H$1022<>""), '테스트 실행 로그'!H$6:H$1022))=0, "날짜 없음", MAX(IF(('테스트 실행 로그'!C$6:C$1022=C26)*('테스트 실행 로그'!H$6:H$1022<>""), '테스트 실행 로그'!H$6:H$1022))), "날짜 없음" )} -> 45807 | I26: {=IFERROR(IF(LEN(INDEX('테스트 실행 로그'!I$6:I$1022, MATCH(1, ('테스트 실행 로그'!C$6:C$1022=C26)*('테스트 실행 로그'!H$6:H$1022=MAX(IF('테스트 실행 로그'!C$6:C$1022=C26, '테스트 실행 로그'!H$6:H$1022))), 0)))=0,"이슈 없음",INDEX('테스트 실행 로그'!I$6:I$1022, MATCH(1, ('테스트 실행 로그'!C$6:C$1022=C26)*('테스트 실행 로그'!H$6:H$1022=MAX(IF('테스트 실행 로그'!C$6:C$1022=C26, '테스트 실행 로그'!H$6:H$1022))), 0))),"이슈 없음")} -> 이슈 없음
C27: AP591_TC_022 | D27: 상세 입력필드를 보이도록 한다. | E27: Setting 버튼 클릭, Setting 팝업창에서 특정 필드 숨김 설정 (화면 Display여부 Y) 후 저장 | F27: 해당 필드가 상세에서 보임 | G27: {=IFERROR( IF(LEN(INDEX('테스트 실행 로그'!G$6:G$1022, MATCH(1, ('테스트 실행 로그'!C$6:C$1022=C27)*('테스트 실행 로그'!H$6:H$1022=MAX(IF(('테스트 실행 로그'!C$6:C$1022=C27)*('테스트 실행 로그'!H$6:H$1022<>""), '테스트 실행 로그'!H$6:H$1022))), 0)))=0, "결과 없음", INDEX('테스트 실행 로그'!G$6:G$1022, MATCH(1, ('테스트 실행 로그'!C$6:C$1022=C27)*('테스트 실행 로그'!H$6:H$1022=MAX(IF(('테스트 실행 로그'!C$6:C$1022=C27)*('테스트 실행 로그'!H$6:H$1022<>""), '테스트 실행 로그'!H$6:H$1022))), 0))), "결과 없음" )} -> Y | H27: {=IFERROR( IF(MAX(IF(('테스트 실행 로그'!C$6:C$1022=C27)*('테스트 실행 로그'!H$6:H$1022<>""), '테스트 실행 로그'!H$6:H$1022))=0, "날짜 없음", MAX(IF(('테스트 실행 로그'!C$6:C$1022=C27)*('테스트 실행 로그'!H$6:H$1022<>""), '테스트 실행 로그'!H$6:H$1022))), "날짜 없음" )} -> 45807 | I27: {=IFERROR(IF(LEN(INDEX('테스트 실행 로그'!I$6:I$1022, MATCH(1, ('테스트 실행 로그'!C$6:C$1022=C27)*('테스트 실행 로그'!H$6:H$1022=MAX(IF('테스트 실행 로그'!C$6:C$1022=C27, '테스트 실행 로그'!H$6:H$1022))), 0)))=0,"이슈 없음",INDEX('테스트 실행 로그'!I$6:I$1022, MATCH(1, ('테스트 실행 로그'!C$6:C$1022=C27)*('테스트 실행 로그'!H$6:H$1022=MAX(IF('테스트 실행 로그'!C$6:C$1022=C27, '테스트 실행 로그'!H$6:H$1022))), 0))),"이슈 없음")} -> 이슈 없음
C28: AP591_TC_023 | D28: 상세 입력필드명을 변경한다. | E28: Setting 버튼 클릭, Setting 팝업창에서 특정 필드 항목의 화면표시명 필드 값 변경 후 저장 | F28: 해당 필드의 필드명이 변경됨 (새로고침 후 반영 확인) | G28: {=IFERROR( IF(LEN(INDEX('테스트 실행 로그'!G$6:G$1022, MATCH(1, ('테스트 실행 로그'!C$6:C$1022=C28)*('테스트 실행 로그'!H$6:H$1022=MAX(IF(('테스트 실행 로그'!C$6:C$1022=C28)*('테스트 실행 로그'!H$6:H$1022<>""), '테스트 실행 로그'!H$6:H$1022))), 0)))=0, "결과 없음", INDEX('테스트 실행 로그'!G$6:G$1022, MATCH(1, ('테스트 실행 로그'!C$6:C$1022=C28)*('테스트 실행 로그'!H$6:H$1022=MAX(IF(('테스트 실행 로그'!C$6:C$1022=C28)*('테스트 실행 로그'!H$6:H$1022<>""), '테스트 실행 로그'!H$6:H$1022))), 0))), "결과 없음" )} -> Y | H28: {=IFERROR( IF(MAX(IF(('테스트 실행 로그'!C$6:C$1022=C28)*('테스트 실행 로그'!H$6:H$1022<>""), '테스트 실행 로그'!H$6:H$1022))=0, "날짜 없음", MAX(IF(('테스트 실행 로그'!C$6:C$1022=C28)*('테스트 실행 로그'!H$6:H$1022<>""), '테스트 실행 로그'!H$6:H$1022))), "날짜 없음" )} -> 45807 | I28: {=IFERROR(IF(LEN(INDEX('테스트 실행 로그'!I$6:I$1022, MATCH(1, ('테스트 실행 로그'!C$6:C$1022=C28)*('테스트 실행 로그'!H$6:H$1022=MAX(IF('테스트 실행 로그'!C$6:C$1022=C28, '테스트 실행 로그'!H$6:H$1022))), 0)))=0,"이슈 없음",INDEX('테스트 실행 로그'!I$6:I$1022, MATCH(1, ('테스트 실행 로그'!C$6:C$1022=C28)*('테스트 실행 로그'!H$6:H$1022=MAX(IF('테스트 실행 로그'!C$6:C$1022=C28, '테스트 실행 로그'!H$6:H$1022))), 0))),"이슈 없음")} -> 이슈 없음
B29: 카렌다(월간), 목록(조건) 목록 Setting | C29: AP591_TC_024 | D29: 목록 칼럼을 보이지 않게 숨긴다. | E29: Setting 버튼 클릭, Setting 팝업창에서 특정 칼럼 숨김 설정 (화면 Display여부 N) 후 저장 | F29: 해당 칼럼이 목록에서 숨겨짐 (새로고침 후 반영 확인) | G29: {=IFERROR( IF(LEN(INDEX('테스트 실행 로그'!G$6:G$1022, MATCH(1, ('테스트 실행 로그'!C$6:C$1022=C29)*('테스트 실행 로그'!H$6:H$1022=MAX(IF(('테스트 실행 로그'!C$6:C$1022=C29)*('테스트 실행 로그'!H$6:H$1022<>""), '테스트 실행 로그'!H$6:H$1022))), 0)))=0, "결과 없음", INDEX('테스트 실행 로그'!G$6:G$1022, MATCH(1, ('테스트 실행 로그'!C$6:C$1022=C29)*('테스트 실행 로그'!H$6:H$1022=MAX(IF(('테스트 실행 로그'!C$6:C$1022=C29)*('테스트 실행 로그'!H$6:H$1022<>""), '테스트 실행 로그'!H$6:H$1022))), 0))), "결과 없음" )} -> Y | H29: {=IFERROR( IF(MAX(IF(('테스트 실행 로그'!C$6:C$1022=C29)*('테스트 실행 로그'!H$6:H$1022<>""), '테스트 실행 로그'!H$6:H$1022))=0, "날짜 없음", MAX(IF(('테스트 실행 로그'!C$6:C$1022=C29)*('테스트 실행 로그'!H$6:H$1022<>""), '테스트 실행 로그'!H$6:H$1022))), "날짜 없음" )} -> 45807 | I29: {=IFERROR(IF(LEN(INDEX('테스트 실행 로그'!I$6:I$1022, MATCH(1, ('테스트 실행 로그'!C$6:C$1022=C29)*('테스트 실행 로그'!H$6:H$1022=MAX(IF('테스트 실행 로그'!C$6:C$1022=C29, '테스트 실행 로그'!H$6:H$1022))), 0)))=0,"이슈 없음",INDEX('테스트 실행 로그'!I$6:I$1022, MATCH(1, ('테스트 실행 로그'!C$6:C$1022=C29)*('테스트 실행 로그'!H$6:H$1022=MAX(IF('테스트 실행 로그'!C$6:C$1022=C29, '테스트 실행 로그'!H$6:H$1022))), 0))),"이슈 없음")} -> 이슈 없음
C30: AP591_TC_025 | D30: 목록 칼럼을 보이도록 한다. | E30: Setting 버튼 클릭, Setting 팝업창에서 특정 칼럼 숨김 설정 (화면 Display여부 Y) 후 저장 | F30: 해당 칼럼이 목록에서 보임 (새로고침 후 반영 확인) | G30: {=IFERROR( IF(LEN(INDEX('테스트 실행 로그'!G$6:G$1022, MATCH(1, ('테스트 실행 로그'!C$6:C$1022=C30)*('테스트 실행 로그'!H$6:H$1022=MAX(IF(('테스트 실행 로그'!C$6:C$1022=C30)*('테스트 실행 로그'!H$6:H$1022<>""), '테스트 실행 로그'!H$6:H$1022))), 0)))=0, "결과 없음", INDEX('테스트 실행 로그'!G$6:G$1022, MATCH(1, ('테스트 실행 로그'!C$6:C$1022=C30)*('테스트 실행 로그'!H$6:H$1022=MAX(IF(('테스트 실행 로그'!C$6:C$1022=C30)*('테스트 실행 로그'!H$6:H$1022<>""), '테스트 실행 로그'!H$6:H$1022))), 0))), "결과 없음" )} -> Y | H30: {=IFERROR( IF(MAX(IF(('테스트 실행 로그'!C$6:C$1022=C30)*('테스트 실행 로그'!H$6:H$1022<>""), '테스트 실행 로그'!H$6:H$1022))=0, "날짜 없음", MAX(IF(('테스트 실행 로그'!C$6:C$1022=C30)*('테스트 실행 로그'!H$6:H$1022<>""), '테스트 실행 로그'!H$6:H$1022))), "날짜 없음" )} -> 45807 | I30: {=IFERROR(IF(LEN(INDEX('테스트 실행 로그'!I$6:I$1022, MATCH(1, ('테스트 실행 로그'!C$6:C$1022=C30)*('테스트 실행 로그'!H$6:H$1022=MAX(IF('테스트 실행 로그'!C$6:C$1022=C30, '테스트 실행 로그'!H$6:H$1022))), 0)))=0,"이슈 없음",INDEX('테스트 실행 로그'!I$6:I$1022, MATCH(1, ('테스트 실행 로그'!C$6:C$1022=C30)*('테스트 실행 로그'!H$6:H$1022=MAX(IF('테스트 실행 로그'!C$6:C$1022=C30, '테스트 실행 로그'!H$6:H$1022))), 0))),"이슈 없음")} -> 이슈 없음
C31: AP591_TC_026 | D31: 목록 칼럼 순서를 변경한다. | E31: Setting 버튼 클릭, Setting 팝업창에서 특정 칼럼 항목의 정렬값 숫자를 변경 후 저장 | F31: 해당 칼럼이 정렬값대로 나열됨 (작은 숫자일수록 앞에 나열됨, 새로고침 후 반영 확인) | G31: {=IFERROR( IF(LEN(INDEX('테스트 실행 로그'!G$6:G$1022, MATCH(1, ('테스트 실행 로그'!C$6:C$1022=C31)*('테스트 실행 로그'!H$6:H$1022=MAX(IF(('테스트 실행 로그'!C$6:C$1022=C31)*('테스트 실행 로그'!H$6:H$1022<>""), '테스트 실행 로그'!H$6:H$1022))), 0)))=0, "결과 없음", INDEX('테스트 실행 로그'!G$6:G$1022, MATCH(1, ('테스트 실행 로그'!C$6:C$1022=C31)*('테스트 실행 로그'!H$6:H$1022=MAX(IF(('테스트 실행 로그'!C$6:C$1022=C31)*('테스트 실행 로그'!H$6:H$1022<>""), '테스트 실행 로그'!H$6:H$1022))), 0))), "결과 없음" )} -> Y | H31: {=IFERROR( IF(MAX(IF(('테스트 실행 로그'!C$6:C$1022=C31)*('테스트 실행 로그'!H$6:H$1022<>""), '테스트 실행 로그'!H$6:H$1022))=0, "날짜 없음", MAX(IF(('테스트 실행 로그'!C$6:C$1022=C31)*('테스트 실행 로그'!H$6:H$1022<>""), '테스트 실행 로그'!H$6:H$1022))), "날짜 없음" )} -> 45807 | I31: {=IFERROR(IF(LEN(INDEX('테스트 실행 로그'!I$6:I$1022, MATCH(1, ('테스트 실행 로그'!C$6:C$1022=C31)*('테스트 실행 로그'!H$6:H$1022=MAX(IF('테스트 실행 로그'!C$6:C$1022=C31, '테스트 실행 로그'!H$6:H$1022))), 0)))=0,"이슈 없음",INDEX('테스트 실행 로그'!I$6:I$1022, MATCH(1, ('테스트 실행 로그'!C$6:C$1022=C31)*('테스트 실행 로그'!H$6:H$1022=MAX(IF('테스트 실행 로그'!C$6:C$1022=C31, '테스트 실행 로그'!H$6:H$1022))), 0))),"이슈 없음")} -> 이슈 없음
C32: AP591_TC_027 | D32: 목록 칼럼 너비를 변경한다. | E32: Setting 버튼 클릭, Setting 팝업창에서 특정 칼럼 항목의 칼럼너비(숫자)를 입력 후 저장 | F32: 해당 칼럼의 너비가 변경됨 (새로고침 후 반영 확인) | G32: {=IFERROR( IF(LEN(INDEX('테스트 실행 로그'!G$6:G$1022, MATCH(1, ('테스트 실행 로그'!C$6:C$1022=C32)*('테스트 실행 로그'!H$6:H$1022=MAX(IF(('테스트 실행 로그'!C$6:C$1022=C32)*('테스트 실행 로그'!H$6:H$1022<>""), '테스트 실행 로그'!H$6:H$1022))), 0)))=0, "결과 없음", INDEX('테스트 실행 로그'!G$6:G$1022, MATCH(1, ('테스트 실행 로그'!C$6:C$1022=C32)*('테스트 실행 로그'!H$6:H$1022=MAX(IF(('테스트 실행 로그'!C$6:C$1022=C32)*('테스트 실행 로그'!H$6:H$1022<>""), '테스트 실행 로그'!H$6:H$1022))), 0))), "결과 없음" )} -> Y | H32: {=IFERROR( IF(MAX(IF(('테스트 실행 로그'!C$6:C$1022=C32)*('테스트 실행 로그'!H$6:H$1022<>""), '테스트 실행 로그'!H$6:H$1022))=0, "날짜 없음", MAX(IF(('테스트 실행 로그'!C$6:C$1022=C32)*('테스트 실행 로그'!H$6:H$1022<>""), '테스트 실행 로그'!H$6:H$1022))), "날짜 없음" )} -> 45807 | I32: {=IFERROR(IF(LEN(INDEX('테스트 실행 로그'!I$6:I$1022, MATCH(1, ('테스트 실행 로그'!C$6:C$1022=C32)*('테스트 실행 로그'!H$6:H$1022=MAX(IF('테스트 실행 로그'!C$6:C$1022=C32, '테스트 실행 로그'!H$6:H$1022))), 0)))=0,"이슈 없음",INDEX('테스트 실행 로그'!I$6:I$1022, MATCH(1, ('테스트 실행 로그'!C$6:C$1022=C32)*('테스트 실행 로그'!H$6:H$1022=MAX(IF('테스트 실행 로그'!C$6:C$1022=C32, '테스트 실행 로그'!H$6:H$1022))), 0))),"이슈 없음")} -> 이슈 없음
C33: AP591_TC_028 | D33: 목록 칼럼 정렬을 변경한다. | E33: Setting 버튼 클릭, Setting 팝업창에서 특정 칼럼 항목의 정렬 설정 (Left, Center, Right) 후 저장 | F33: 해당 칼럼의 텍스트 정렬 위치가 변경됨 (새로고침 후 반영 확인) | G33: {=IFERROR( IF(LEN(INDEX('테스트 실행 로그'!G$6:G$1022, MATCH(1, ('테스트 실행 로그'!C$6:C$1022=C33)*('테스트 실행 로그'!H$6:H$1022=MAX(IF(('테스트 실행 로그'!C$6:C$1022=C33)*('테스트 실행 로그'!H$6:H$1022<>""), '테스트 실행 로그'!H$6:H$1022))), 0)))=0, "결과 없음", INDEX('테스트 실행 로그'!G$6:G$1022, MATCH(1, ('테스트 실행 로그'!C$6:C$1022=C33)*('테스트 실행 로그'!H$6:H$1022=MAX(IF(('테스트 실행 로그'!C$6:C$1022=C33)*('테스트 실행 로그'!H$6:H$1022<>""), '테스트 실행 로그'!H$6:H$1022))), 0))), "결과 없음" )} -> Y | H33: {=IFERROR( IF(MAX(IF(('테스트 실행 로그'!C$6:C$1022=C33)*('테스트 실행 로그'!H$6:H$1022<>""), '테스트 실행 로그'!H$6:H$1022))=0, "날짜 없음", MAX(IF(('테스트 실행 로그'!C$6:C$1022=C33)*('테스트 실행 로그'!H$6:H$1022<>""), '테스트 실행 로그'!H$6:H$1022))), "날짜 없음" )} -> 45807 | I33: {=IFERROR(IF(LEN(INDEX('테스트 실행 로그'!I$6:I$1022, MATCH(1, ('테스트 실행 로그'!C$6:C$1022=C33)*('테스트 실행 로그'!H$6:H$1022=MAX(IF('테스트 실행 로그'!C$6:C$1022=C33, '테스트 실행 로그'!H$6:H$1022))), 0)))=0,"이슈 없음",INDEX('테스트 실행 로그'!I$6:I$1022, MATCH(1, ('테스트 실행 로그'!C$6:C$1022=C33)*('테스트 실행 로그'!H$6:H$1022=MAX(IF('테스트 실행 로그'!C$6:C$1022=C33, '테스트 실행 로그'!H$6:H$1022))), 0))),"이슈 없음")} -> 이슈 없음
C34: AP591_TC_029 | D34: 목록 칼럼의 데이터 조회순서를 변경한다. | E34: Setting 버튼 클릭, Setting 팝업창에서 특정 칼럼 항목의 조회순서 설정 (ASC, DESC) 후 저장 | F34: 해당 칼럼의 데이터 조회 순서 변경 (새로고침 후 반영 확인, ASC : 오름차순, DESC : 내림차순) | G34: {=IFERROR( IF(LEN(INDEX('테스트 실행 로그'!G$6:G$1022, MATCH(1, ('테스트 실행 로그'!C$6:C$1022=C34)*('테스트 실행 로그'!H$6:H$1022=MAX(IF(('테스트 실행 로그'!C$6:C$1022=C34)*('테스트 실행 로그'!H$6:H$1022<>""), '테스트 실행 로그'!H$6:H$1022))), 0)))=0, "결과 없음", INDEX('테스트 실행 로그'!G$6:G$1022, MATCH(1, ('테스트 실행 로그'!C$6:C$1022=C34)*('테스트 실행 로그'!H$6:H$1022=MAX(IF(('테스트 실행 로그'!C$6:C$1022=C34)*('테스트 실행 로그'!H$6:H$1022<>""), '테스트 실행 로그'!H$6:H$1022))), 0))), "결과 없음" )} -> Y | H34: {=IFERROR( IF(MAX(IF(('테스트 실행 로그'!C$6:C$1022=C34)*('테스트 실행 로그'!H$6:H$1022<>""), '테스트 실행 로그'!H$6:H$1022))=0, "날짜 없음", MAX(IF(('테스트 실행 로그'!C$6:C$1022=C34)*('테스트 실행 로그'!H$6:H$1022<>""), '테스트 실행 로그'!H$6:H$1022))), "날짜 없음" )} -> 45807 | I34: {=IFERROR(IF(LEN(INDEX('테스트 실행 로그'!I$6:I$1022, MATCH(1, ('테스트 실행 로그'!C$6:C$1022=C34)*('테스트 실행 로그'!H$6:H$1022=MAX(IF('테스트 실행 로그'!C$6:C$1022=C34, '테스트 실행 로그'!H$6:H$1022))), 0)))=0,"이슈 없음",INDEX('테스트 실행 로그'!I$6:I$1022, MATCH(1, ('테스트 실행 로그'!C$6:C$1022=C34)*('테스트 실행 로그'!H$6:H$1022=MAX(IF('테스트 실행 로그'!C$6:C$1022=C34, '테스트 실행 로그'!H$6:H$1022))), 0))),"이슈 없음")} -> 이슈 없음
C35: AP591_TC_030 | D35: 목록 칼럼의 배경 색상을 변경한다. | E35: Setting 버튼 클릭, Setting 팝업창에서 특정 칼럼 항목의 Background Color 선택 (>,>=,<,<=,!=,Not in,In / Blue, Red) 후 저장 | F35: 해당 칼럼의 배경 색상 변경 (새로고침 후 반영 확인, 특정값을 기준으로 크거나 작을 때 배경 색깔이 바뀌도록 설정 가능함) | G35: {=IFERROR( IF(LEN(INDEX('테스트 실행 로그'!G$6:G$1022, MATCH(1, ('테스트 실행 로그'!C$6:C$1022=C35)*('테스트 실행 로그'!H$6:H$1022=MAX(IF(('테스트 실행 로그'!C$6:C$1022=C35)*('테스트 실행 로그'!H$6:H$1022<>""), '테스트 실행 로그'!H$6:H$1022))), 0)))=0, "결과 없음", INDEX('테스트 실행 로그'!G$6:G$1022, MATCH(1, ('테스트 실행 로그'!C$6:C$1022=C35)*('테스트 실행 로그'!H$6:H$1022=MAX(IF(('테스트 실행 로그'!C$6:C$1022=C35)*('테스트 실행 로그'!H$6:H$1022<>""), '테스트 실행 로그'!H$6:H$1022))), 0))), "결과 없음" )} -> Y | H35: {=IFERROR( IF(MAX(IF(('테스트 실행 로그'!C$6:C$1022=C35)*('테스트 실행 로그'!H$6:H$1022<>""), '테스트 실행 로그'!H$6:H$1022))=0, "날짜 없음", MAX(IF(('테스트 실행 로그'!C$6:C$1022=C35)*('테스트 실행 로그'!H$6:H$1022<>""), '테스트 실행 로그'!H$6:H$1022))), "날짜 없음" )} -> 45807 | I35: {=IFERROR(IF(LEN(INDEX('테스트 실행 로그'!I$6:I$1022, MATCH(1, ('테스트 실행 로그'!C$6:C$1022=C35)*('테스트 실행 로그'!H$6:H$1022=MAX(IF('테스트 실행 로그'!C$6:C$1022=C35, '테스트 실행 로그'!H$6:H$1022))), 0)))=0,"이슈 없음",INDEX('테스트 실행 로그'!I$6:I$1022, MATCH(1, ('테스트 실행 로그'!C$6:C$1022=C35)*('테스트 실행 로그'!H$6:H$1022=MAX(IF('테스트 실행 로그'!C$6:C$1022=C35, '테스트 실행 로그'!H$6:H$1022))), 0))),"이슈 없음")} -> 이슈 없음
C36: AP591_TC_031 | D36: 목록 칼럼의 리스트 길이를 변경한다. (-/+ 버튼) | E36: Setting 버튼 클릭, Setting 팝업창에서 특정 칼럼 항목의 리스트 길이 (-,+) 설정 후 저장 | F36: 해당 칼럼의 목록 리스트 길이가 증가 또는 감소됨 (새로고침 후 반영 확인, - : 숫자 감소, + : 숫자 증가) | G36: {=IFERROR( IF(LEN(INDEX('테스트 실행 로그'!G$6:G$1022, MATCH(1, ('테스트 실행 로그'!C$6:C$1022=C36)*('테스트 실행 로그'!H$6:H$1022=MAX(IF(('테스트 실행 로그'!C$6:C$1022=C36)*('테스트 실행 로그'!H$6:H$1022<>""), '테스트 실행 로그'!H$6:H$1022))), 0)))=0, "결과 없음", INDEX('테스트 실행 로그'!G$6:G$1022, MATCH(1, ('테스트 실행 로그'!C$6:C$1022=C36)*('테스트 실행 로그'!H$6:H$1022=MAX(IF(('테스트 실행 로그'!C$6:C$1022=C36)*('테스트 실행 로그'!H$6:H$1022<>""), '테스트 실행 로그'!H$6:H$1022))), 0))), "결과 없음" )} -> Y | H36: {=IFERROR( IF(MAX(IF(('테스트 실행 로그'!C$6:C$1022=C36)*('테스트 실행 로그'!H$6:H$1022<>""), '테스트 실행 로그'!H$6:H$1022))=0, "날짜 없음", MAX(IF(('테스트 실행 로그'!C$6:C$1022=C36)*('테스트 실행 로그'!H$6:H$1022<>""), '테스트 실행 로그'!H$6:H$1022))), "날짜 없음" )} -> 45807 | I36: {=IFERROR(IF(LEN(INDEX('테스트 실행 로그'!I$6:I$1022, MATCH(1, ('테스트 실행 로그'!C$6:C$1022=C36)*('테스트 실행 로그'!H$6:H$1022=MAX(IF('테스트 실행 로그'!C$6:C$1022=C36, '테스트 실행 로그'!H$6:H$1022))), 0)))=0,"이슈 없음",INDEX('테스트 실행 로그'!I$6:I$1022, MATCH(1, ('테스트 실행 로그'!C$6:C$1022=C36)*('테스트 실행 로그'!H$6:H$1022=MAX(IF('테스트 실행 로그'!C$6:C$1022=C36, '테스트 실행 로그'!H$6:H$1022))), 0))),"이슈 없음")} -> 이슈 없음
C37: AP591_TC_032 | D37: 목록 칼럼의 리스트 길이를 변경한다. (숫자 입력) | E37: Setting 버튼 클릭, Setting 팝업창에서 리스트 길이 숫자 입력 후 저장 | F37: 해당 칼럼의 리스트 길이가 입력한 숫자만큼 변경됨 (새로고침 후 반영 확인) | G37: {=IFERROR( IF(LEN(INDEX('테스트 실행 로그'!G$6:G$1022, MATCH(1, ('테스트 실행 로그'!C$6:C$1022=C37)*('테스트 실행 로그'!H$6:H$1022=MAX(IF(('테스트 실행 로그'!C$6:C$1022=C37)*('테스트 실행 로그'!H$6:H$1022<>""), '테스트 실행 로그'!H$6:H$1022))), 0)))=0, "결과 없음", INDEX('테스트 실행 로그'!G$6:G$1022, MATCH(1, ('테스트 실행 로그'!C$6:C$1022=C37)*('테스트 실행 로그'!H$6:H$1022=MAX(IF(('테스트 실행 로그'!C$6:C$1022=C37)*('테스트 실행 로그'!H$6:H$1022<>""), '테스트 실행 로그'!H$6:H$1022))), 0))), "결과 없음" )} -> Y | H37: {=IFERROR( IF(MAX(IF(('테스트 실행 로그'!C$6:C$1022=C37)*('테스트 실행 로그'!H$6:H$1022<>""), '테스트 실행 로그'!H$6:H$1022))=0, "날짜 없음", MAX(IF(('테스트 실행 로그'!C$6:C$1022=C37)*('테스트 실행 로그'!H$6:H$1022<>""), '테스트 실행 로그'!H$6:H$1022))), "날짜 없음" )} -> 45807 | I37: {=IFERROR(IF(LEN(INDEX('테스트 실행 로그'!I$6:I$1022, MATCH(1, ('테스트 실행 로그'!C$6:C$1022=C37)*('테스트 실행 로그'!H$6:H$1022=MAX(IF('테스트 실행 로그'!C$6:C$1022=C37, '테스트 실행 로그'!H$6:H$1022))), 0)))=0,"이슈 없음",INDEX('테스트 실행 로그'!I$6:I$1022, MATCH(1, ('테스트 실행 로그'!C$6:C$1022=C37)*('테스트 실행 로그'!H$6:H$1022=MAX(IF('테스트 실행 로그'!C$6:C$1022=C37, '테스트 실행 로그'!H$6:H$1022))), 0))),"이슈 없음")} -> 이슈 없음
B38: 탭조회 | C38: AP591_TC_033 | D38: 탭목록 데이터 개수 확인한다. | E38: 탭목록 클릭 | F38: 탭목록 데이터 개수가 조회됨(탭목록 우측하단 total : n/n 숫자와 조회된 데이터 개수(순번)와 일치하는지 확인) | G38: {=IFERROR( IF(LEN(INDEX('테스트 실행 로그'!G$6:G$1022, MATCH(1, ('테스트 실행 로그'!C$6:C$1022=C38)*('테스트 실행 로그'!H$6:H$1022=MAX(IF(('테스트 실행 로그'!C$6:C$1022=C38)*('테스트 실행 로그'!H$6:H$1022<>""), '테스트 실행 로그'!H$6:H$1022))), 0)))=0, "결과 없음", INDEX('테스트 실행 로그'!G$6:G$1022, MATCH(1, ('테스트 실행 로그'!C$6:C$1022=C38)*('테스트 실행 로그'!H$6:H$1022=MAX(IF(('테스트 실행 로그'!C$6:C$1022=C38)*('테스트 실행 로그'!H$6:H$1022<>""), '테스트 실행 로그'!H$6:H$1022))), 0))), "결과 없음" )} -> Y | H38: {=IFERROR( IF(MAX(IF(('테스트 실행 로그'!C$6:C$1022=C38)*('테스트 실행 로그'!H$6:H$1022<>""), '테스트 실행 로그'!H$6:H$1022))=0, "날짜 없음", MAX(IF(('테스트 실행 로그'!C$6:C$1022=C38)*('테스트 실행 로그'!H$6:H$1022<>""), '테스트 실행 로그'!H$6:H$1022))), "날짜 없음" )} -> 45747 | I38: {=IFERROR(IF(LEN(INDEX('테스트 실행 로그'!I$6:I$1022, MATCH(1, ('테스트 실행 로그'!C$6:C$1022=C38)*('테스트 실행 로그'!H$6:H$1022=MAX(IF('테스트 실행 로그'!C$6:C$1022=C38, '테스트 실행 로그'!H$6:H$1022))), 0)))=0,"이슈 없음",INDEX('테스트 실행 로그'!I$6:I$1022, MATCH(1, ('테스트 실행 로그'!C$6:C$1022=C38)*('테스트 실행 로그'!H$6:H$1022=MAX(IF('테스트 실행 로그'!C$6:C$1022=C38, '테스트 실행 로그'!H$6:H$1022))), 0))),"이슈 없음")} -> 이슈 없음
C39: AP591_TC_034 | D39: 탭목록을 정렬한다. | E39: 탭목록의 그리드 헤더 클릭 | F39: 선택한 헤더의 필드값 기준으로 오름차순, 내림차순 정렬됨 | G39: {=IFERROR( IF(LEN(INDEX('테스트 실행 로그'!G$6:G$1022, MATCH(1, ('테스트 실행 로그'!C$6:C$1022=C39)*('테스트 실행 로그'!H$6:H$1022=MAX(IF(('테스트 실행 로그'!C$6:C$1022=C39)*('테스트 실행 로그'!H$6:H$1022<>""), '테스트 실행 로그'!H$6:H$1022))), 0)))=0, "결과 없음", INDEX('테스트 실행 로그'!G$6:G$1022, MATCH(1, ('테스트 실행 로그'!C$6:C$1022=C39)*('테스트 실행 로그'!H$6:H$1022=MAX(IF(('테스트 실행 로그'!C$6:C$1022=C39)*('테스트 실행 로그'!H$6:H$1022<>""), '테스트 실행 로그'!H$6:H$1022))), 0))), "결과 없음" )} -> Y | H39: {=IFERROR( IF(MAX(IF(('테스트 실행 로그'!C$6:C$1022=C39)*('테스트 실행 로그'!H$6:H$1022<>""), '테스트 실행 로그'!H$6:H$1022))=0, "날짜 없음", MAX(IF(('테스트 실행 로그'!C$6:C$1022=C39)*('테스트 실행 로그'!H$6:H$1022<>""), '테스트 실행 로그'!H$6:H$1022))), "날짜 없음" )} -> 45747 | I39: {=IFERROR(IF(LEN(INDEX('테스트 실행 로그'!I$6:I$1022, MATCH(1, ('테스트 실행 로그'!C$6:C$1022=C39)*('테스트 실행 로그'!H$6:H$1022=MAX(IF('테스트 실행 로그'!C$6:C$1022=C39, '테스트 실행 로그'!H$6:H$1022))), 0)))=0,"이슈 없음",INDEX('테스트 실행 로그'!I$6:I$1022, MATCH(1, ('테스트 실행 로그'!C$6:C$1022=C39)*('테스트 실행 로그'!H$6:H$1022=MAX(IF('테스트 실행 로그'!C$6:C$1022=C39, '테스트 실행 로그'!H$6:H$1022))), 0))),"이슈 없음")} -> 이슈 없음
C40: AP591_TC_035 | D40: (행 클릭) 조회된 데이터의 상세정보를 조회한다. | E40: 탭목록 데이터 행 클릭 | F40: 탭목록 하단에 펼쳐지는 상세페이지에서 해당 데이터의 각 항목에 입력된 값을 확인할 수 있음 | G40: {=IFERROR( IF(LEN(INDEX('테스트 실행 로그'!G$6:G$1022, MATCH(1, ('테스트 실행 로그'!C$6:C$1022=C40)*('테스트 실행 로그'!H$6:H$1022=MAX(IF(('테스트 실행 로그'!C$6:C$1022=C40)*('테스트 실행 로그'!H$6:H$1022<>""), '테스트 실행 로그'!H$6:H$1022))), 0)))=0, "결과 없음", INDEX('테스트 실행 로그'!G$6:G$1022, MATCH(1, ('테스트 실행 로그'!C$6:C$1022=C40)*('테스트 실행 로그'!H$6:H$1022=MAX(IF(('테스트 실행 로그'!C$6:C$1022=C40)*('테스트 실행 로그'!H$6:H$1022<>""), '테스트 실행 로그'!H$6:H$1022))), 0))), "결과 없음" )} -> Y | H40: {=IFERROR( IF(MAX(IF(('테스트 실행 로그'!C$6:C$1022=C40)*('테스트 실행 로그'!H$6:H$1022<>""), '테스트 실행 로그'!H$6:H$1022))=0, "날짜 없음", MAX(IF(('테스트 실행 로그'!C$6:C$1022=C40)*('테스트 실행 로그'!H$6:H$1022<>""), '테스트 실행 로그'!H$6:H$1022))), "날짜 없음" )} -> 45747 | I40: {=IFERROR(IF(LEN(INDEX('테스트 실행 로그'!I$6:I$1022, MATCH(1, ('테스트 실행 로그'!C$6:C$1022=C40)*('테스트 실행 로그'!H$6:H$1022=MAX(IF('테스트 실행 로그'!C$6:C$1022=C40, '테스트 실행 로그'!H$6:H$1022))), 0)))=0,"이슈 없음",INDEX('테스트 실행 로그'!I$6:I$1022, MATCH(1, ('테스트 실행 로그'!C$6:C$1022=C40)*('테스트 실행 로그'!H$6:H$1022=MAX(IF('테스트 실행 로그'!C$6:C$1022=C40, '테스트 실행 로그'!H$6:H$1022))), 0))),"이슈 없음")} -> 이슈 없음
C41: AP591_TC_036 | D41: (상세보기 버튼 클릭) 조회된 데이터의 상세정보를 조회한다. | E41: 탭목록에서 특정 데이터 행 클릭 후 상세보기 버튼 클릭 | F41: 선택한 탭데이터의 상세페이지가 팝업창으로 열림 (탭목록 하단에 펼쳐지는 상세페이지와 내용 동일) | G41: {=IFERROR( IF(LEN(INDEX('테스트 실행 로그'!G$6:G$1022, MATCH(1, ('테스트 실행 로그'!C$6:C$1022=C41)*('테스트 실행 로그'!H$6:H$1022=MAX(IF(('테스트 실행 로그'!C$6:C$1022=C41)*('테스트 실행 로그'!H$6:H$1022<>""), '테스트 실행 로그'!H$6:H$1022))), 0)))=0, "결과 없음", INDEX('테스트 실행 로그'!G$6:G$1022, MATCH(1, ('테스트 실행 로그'!C$6:C$1022=C41)*('테스트 실행 로그'!H$6:H$1022=MAX(IF(('테스트 실행 로그'!C$6:C$1022=C41)*('테스트 실행 로그'!H$6:H$1022<>""), '테스트 실행 로그'!H$6:H$1022))), 0))), "결과 없음" )} -> Y | H41: {=IFERROR( IF(MAX(IF(('테스트 실행 로그'!C$6:C$1022=C41)*('테스트 실행 로그'!H$6:H$1022<>""), '테스트 실행 로그'!H$6:H$1022))=0, "날짜 없음", MAX(IF(('테스트 실행 로그'!C$6:C$1022=C41)*('테스트 실행 로그'!H$6:H$1022<>""), '테스트 실행 로그'!H$6:H$1022))), "날짜 없음" )} -> 45747 | I41: {=IFERROR(IF(LEN(INDEX('테스트 실행 로그'!I$6:I$1022, MATCH(1, ('테스트 실행 로그'!C$6:C$1022=C41)*('테스트 실행 로그'!H$6:H$1022=MAX(IF('테스트 실행 로그'!C$6:C$1022=C41, '테스트 실행 로그'!H$6:H$1022))), 0)))=0,"이슈 없음",INDEX('테스트 실행 로그'!I$6:I$1022, MATCH(1, ('테스트 실행 로그'!C$6:C$1022=C41)*('테스트 실행 로그'!H$6:H$1022=MAX(IF('테스트 실행 로그'!C$6:C$1022=C41, '테스트 실행 로그'!H$6:H$1022))), 0))),"이슈 없음")} -> 이슈 없음
C42: AP591_TC_037 | D42: 탭목록 데이터의 포맷 형태를 확인한다. | E42: 탭목록에 조회된 각 데이터 종류에 따른 포맷 형태를 확인한다. | F42: 숫자는 천단위 반점표기, 날짜는 yyyy-mm-dd (숫자 : 오른쪽 정렬 , 텍스트 : 왼쪽 정렬 , 코드/날짜 : 가운데 정렬) | G42: {=IFERROR( IF(LEN(INDEX('테스트 실행 로그'!G$6:G$1022, MATCH(1, ('테스트 실행 로그'!C$6:C$1022=C42)*('테스트 실행 로그'!H$6:H$1022=MAX(IF(('테스트 실행 로그'!C$6:C$1022=C42)*('테스트 실행 로그'!H$6:H$1022<>""), '테스트 실행 로그'!H$6:H$1022))), 0)))=0, "결과 없음", INDEX('테스트 실행 로그'!G$6:G$1022, MATCH(1, ('테스트 실행 로그'!C$6:C$1022=C42)*('테스트 실행 로그'!H$6:H$1022=MAX(IF(('테스트 실행 로그'!C$6:C$1022=C42)*('테스트 실행 로그'!H$6:H$1022<>""), '테스트 실행 로그'!H$6:H$1022))), 0))), "결과 없음" )} -> Y | H42: {=IFERROR( IF(MAX(IF(('테스트 실행 로그'!C$6:C$1022=C42)*('테스트 실행 로그'!H$6:H$1022<>""), '테스트 실행 로그'!H$6:H$1022))=0, "날짜 없음", MAX(IF(('테스트 실행 로그'!C$6:C$1022=C42)*('테스트 실행 로그'!H$6:H$1022<>""), '테스트 실행 로그'!H$6:H$1022))), "날짜 없음" )} -> 45747 | I42: {=IFERROR(IF(LEN(INDEX('테스트 실행 로그'!I$6:I$1022, MATCH(1, ('테스트 실행 로그'!C$6:C$1022=C42)*('테스트 실행 로그'!H$6:H$1022=MAX(IF('테스트 실행 로그'!C$6:C$1022=C42, '테스트 실행 로그'!H$6:H$1022))), 0)))=0,"이슈 없음",INDEX('테스트 실행 로그'!I$6:I$1022, MATCH(1, ('테스트 실행 로그'!C$6:C$1022=C42)*('테스트 실행 로그'!H$6:H$1022=MAX(IF('테스트 실행 로그'!C$6:C$1022=C42, '테스트 실행 로그'!H$6:H$1022))), 0))),"이슈 없음")} -> 이슈 없음
...

Sheet 테스트 실행 로그
A2: ="Dream 3.0 "&CLEAN(A6)&" 단위테스트 실행 로그" -> Dream 3.0 정기점검실행_AP591 단위테스트 실행 로그
A4: 공통
A5: 메뉴명 | B5: 기능 | C5: 테스트ID | D5: CASE | E5: STEP | F5: 테스트 예상 결과 | G5: 최근 실행 결과 | H5: 최근 실행 날짜 | I5: 이슈
A6: 정기점검실행_AP591 | B6: 카렌다(월간), 목록(조건) 검색 | C6: AP591_TC_001 | D6: =IFERROR(VLOOKUP($C6, '테스트 케이스'!$C$6:$F$1002, 2, FALSE), "") -> 검색 필드의 기본값 세팅을 확인한다. | E6: =IFERROR(VLOOKUP($C6, '테스트 케이스'!$C$6:$F$1002, 3, FALSE), "") -> 메뉴 페이지 접속시, 각 필드의 기본값 세팅 확인 | F6: =IFERROR(VLOOKUP($C6, '테스트 케이스'!$C$6:$F$1002, 4, FALSE), "") -> 기본값이 설정되어있을 시, 메뉴 접속했을 때 해당 필드에 입력됨 | G6: Y | H6: 45747
C7: AP591_TC_002 | D7: =IFERROR(VLOOKUP($C7, '테스트 케이스'!$C$6:$F$1002, 2, FALSE), "") -> 검색 필드의 필수값 세팅을 확인한다. | E7: =IFERROR(VLOOKUP($C7, '테스트 케이스'!$C$6:$F$1002, 3, FALSE), "") -> 메뉴 페이지 접속시, 각 필드의 필수값 세팅 확인 | F7: =IFERROR(VLOOKUP($C7, '테스트 케이스'!$C$6:$F$1002, 4, FALSE), "") -> 필수값 설정되어있을 시, 필드라벨과 필드란에 색깔로 표기됨 | G7: N | H7: 45747 | I7: ORACLE, MS-SQL - 카렌다(월간)/목록(조건) 검색조건 년월 필수값 체크 필요(필수값 입력에 대한 팝업 메시지도 필요)
C8: AP591_TC_003 | D8: =IFERROR(VLOOKUP($C8, '테스트 케이스'!$C$6:$F$1002, 2, FALSE), "") -> 검색 필드 Lov 팝업창의 데이터 세팅을 확인한다. | E8: =IFERROR(VLOOKUP($C8, '테스트 케이스'!$C$6:$F$1002, 3, FALSE), "") -> 각 필드의 Lov 버튼 클릭 | F8: =IFERROR(VLOOKUP($C8, '테스트 케이스'!$C$6:$F$1002, 4, FALSE), "") -> 특정 필드에 해당되는 Lov 팝업창 데이터 확인 | G8: N | H8: 45747 | I8: ORACLE, MS-SQL - 카렌다(월간)/목록(조건) 점검Group 필드 숨김처리 필요(점검Group 메뉴 숨김처리해서 사용x)
C9: AP591_TC_004 | D9: =IFERROR(VLOOKUP($C9, '테스트 케이스'!$C$6:$F$1002, 2, FALSE), "") -> 조건에 맞는 정기점검실행 데이터를 검색한다. | E9: =IFERROR(VLOOKUP($C9, '테스트 케이스'!$C$6:$F$1002, 3, FALSE), "") -> 각 검색필드에 데이터 입력 후 검색 버튼 클릭 | F9: =IFERROR(VLOOKUP($C9, '테스트 케이스'!$C$6:$F$1002, 4, FALSE), "") -> 입력한 필드 값에 해당되는 데이터만 목록에 표시됨 (목록 우측하단 total : n/n 숫자와 조회된 데이터 개수(순번)와 일치) | G9: Y | H9: 45747
C10: AP591_TC_005 | D10: =IFERROR(VLOOKUP($C10, '테스트 케이스'!$C$6:$F$1002, 2, FALSE), "") -> 정기점검실행 데이터를 전체 검색한다. | E10: =IFERROR(VLOOKUP($C10, '테스트 케이스'!$C$6:$F$1002, 3, FALSE), "") -> 각 검색필드에 입력된 데이터 전체 삭제 후 검색 버튼 클릭 | F10: =IFERROR(VLOOKUP($C10, '테스트 케이스'!$C$6:$F$1002, 4, FALSE), "") -> 등록된 전체 데이터가 목록에 표시됨 (목록 우측하단 total : n/n 숫자와 조회된 데이터 개수(순번)와 일치) | G10: Y | H10: 45747
C11: AP591_TC_006 | D11: =IFERROR(VLOOKUP($C11, '테스트 케이스'!$C$6:$F$1002, 2, FALSE), "") -> 조회된 데이터의 목록을 정렬한다. | E11: =IFERROR(VLOOKUP($C11, '테스트 케이스'!$C$6:$F$1002, 3, FALSE), "") -> 목록의 그리드 헤더 클릭 | F11: =IFERROR(VLOOKUP($C11, '테스트 케이스'!$C$6:$F$1002, 4, FALSE), "") -> 선택한 헤더의 필드값 기준으로 오름차순, 내림차순 정렬됨 | G11: Y | H11: 45747
C12: AP591_TC_007 | D12: =IFERROR(VLOOKUP($C12, '테스트 케이스'!$C$6:$F$1002, 2, FALSE), "") -> (행 클릭) 조회된 데이터의 상세정보를 조회한다. | E12: =IFERROR(VLOOKUP($C12, '테스트 케이스'!$C$6:$F$1002, 3, FALSE), "") -> 검색된 목록 데이터 행 클릭 | F12: =IFERROR(VLOOKUP($C12, '테스트 케이스'!$C$6:$F$1002, 4, FALSE), "") -> 검색된 목록 하단에 펼쳐지는 상세페이지에서 해당 데이터의 각 항목에 입력된 값을 확인할 수 있음 | G12: N | H12: 45747 | I12: ORACLE, MS-SQL - 목록 점검시간 컬럼 숨김 필요 (상세나 기준서에 점검시간 관련 내용이 없음)
C13: AP591_TC_008 | D13: =IFERROR(VLOOKUP($C13, '테스트 케이스'!$C$6:$F$1002, 2, FALSE), "") -> (상세보기 버튼 클릭) 조회된 데이터의 상세정보를 조회한다. | E13: =IFERROR(VLOOKUP($C13, '테스트 케이스'!$C$6:$F$1002, 3, FALSE), "") -> 목록에서 특정 데이터 행 클릭 후 상세보기 버튼 클릭 | F13: =IFERROR(VLOOKUP($C13, '테스트 케이스'!$C$6:$F$1002, 4, FALSE), "") -> 선택한 데이터의 상세페이지가 팝업창으로 열림 (목록 하단에 펼쳐지는 상세페이지와 내용 동일) | G13: Y | H13: 45747
C14: AP591_TC_009 | D14: =IFERROR(VLOOKUP($C14, '테스트 케이스'!$C$6:$F$1002, 2, FALSE), "") -> (목록) 검색된 데이터의 포맷 형태를 확인한다. | E14: =IFERROR(VLOOKUP($C14, '테스트 케이스'!$C$6:$F$1002, 3, FALSE), "") -> 검색 후 목록에 조회된 각 데이터 종류에 따른 포맷 형태를 확인한다. | F14: =IFERROR(VLOOKUP($C14, '테스트 케이스'!$C$6:$F$1002, 4, FALSE), "") -> 숫자는 천단위 반점표기, 날짜는 yyyy-mm-dd (숫자 : 오른쪽 정렬 , 텍스트 : 왼쪽 정렬 , 코드/날짜 : 가운데 정렬) | G14: Y | H14: 45747
C15: AP591_TC_010 | D15: =IFERROR(VLOOKUP($C15, '테스트 케이스'!$C$6:$F$1002, 2, FALSE), "") -> (상세) 검색된 데이터의 포맷 형태를 확인한다. | E15: =IFERROR(VLOOKUP($C15, '테스트 케이스'!$C$6:$F$1002, 3, FALSE), "") -> 검색 후 상세에 조회된 각 데이터 종류에 따른 포맷 형태를 확인한다. | F15: =IFERROR(VLOOKUP($C15, '테스트 케이스'!$C$6:$F$1002, 4, FALSE), "") -> 숫자는 천단위 반점표기, 날짜는 yyyy-mm-dd (숫자 : 오른쪽 정렬 , 텍스트 : 왼쪽 정렬 , 코드/날짜 : 가운데 정렬) | G15: Y | H15: 45747
B16: 카렌다(월간), 목록(조건) 닫기 | C16: AP591_TC_011 | D16: =IFERROR(VLOOKUP($C16, '테스트 케이스'!$C$6:$F$1002, 2, FALSE), "") -> 상세페이지를 닫는다. | E16: =IFERROR(VLOOKUP($C16, '테스트 케이스'!$C$6:$F$1002, 3, FALSE), "") -> 하단에 펼쳐진 상세페이지 닫기버튼 (ⓧ) 클릭 | F16: =IFERROR(VLOOKUP($C16, '테스트 케이스'!$C$6:$F$1002, 4, FALSE), "") -> 상세페이지 닫힘 | G16: Y | H16: 45747
C17: AP591_TC_012 | D17: =IFERROR(VLOOKUP($C17, '테스트 케이스'!$C$6:$F$1002, 2, FALSE), "") -> (팝업창) 상세페이지를 닫는다. | E17: =IFERROR(VLOOKUP($C17, '테스트 케이스'!$C$6:$F$1002, 3, FALSE), "") -> 창닫기 X 버튼 클릭 | F17: =IFERROR(VLOOKUP($C17, '테스트 케이스'!$C$6:$F$1002, 4, FALSE), "") -> 상세페이지 닫힘 | G17: Y | H17: 45747
B18: 카렌다(월간), 목록(조건) 수정 | C18: AP591_TC_013 | D18: =IFERROR(VLOOKUP($C18, '테스트 케이스'!$C$6:$F$1002, 2, FALSE), "") -> 저장된 정기점검실행 데이터의 필수값과 그 외 값을 수정한다. | E18: =IFERROR(VLOOKUP($C18, '테스트 케이스'!$C$6:$F$1002, 3, FALSE), "") -> 상세화면(혹은 상세보기 팝업)에서 데이터 수정, 저장 클릭 후 저장 팝업창에서 OK 버튼 클릭 | F18: =IFERROR(VLOOKUP($C18, '테스트 케이스'!$C$6:$F$1002, 4, FALSE), "") -> 변경사항이 저장됨 (상세보기 팝업창에서 수정 후 목록에 반영되려면 재검색 혹은 새로고침해야함) | G18: Y | H18: 45747
C19: AP591_TC_014 | D19: =IFERROR(VLOOKUP($C19, '테스트 케이스'!$C$6:$F$1002, 2, FALSE), "") -> 저장된 정기점검실행 데이터의 필수값을 제외 한 후 그 외 값을 수정한다. | E19: =IFERROR(VLOOKUP($C19, '테스트 케이스'!$C$6:$F$1002, 3, FALSE), "") -> 상세화면(혹은 상세보기 팝업)에서 필수값 삭제 후 데이터 수정, 저장 클릭 후 저장 팝업창에서 OK 버튼 클릭 | F19: =IFERROR(VLOOKUP($C19, '테스트 케이스'!$C$6:$F$1002, 4, FALSE), "") -> 필수값 누락에 대한 팝업 표시. 수정 불가 확인 | G19: Y | H19: 45747
B20: 카렌다(월간), 목록(조건) Excel | C20: AP591_TC_015 | D20: =IFERROR(VLOOKUP($C20, '테스트 케이스'!$C$6:$F$1002, 2, FALSE), "") -> 목록에 조회된 데이터를 Excel 다운로드한다. | E20: =IFERROR(VLOOKUP($C20, '테스트 케이스'!$C$6:$F$1002, 3, FALSE), "") -> 1. 검색필드에 필요한 데이터 입력 후 검색 2. Excel 버튼 클릭 | F20: =IFERROR(VLOOKUP($C20, '테스트 케이스'!$C$6:$F$1002, 4, FALSE), "") -> 1. 검색 조건에 맞는 데이터가 조회됨 2. 검색된 데이터가 입력된 Excel 파일이 다운로드됨 (검색결과가 없는 상태에서 클릭시, 목록 헤더만 입력된 Excel 파일이 다운로드 됨) | G20: Y | H20: 45747
B21: 카렌다(월간), 목록(조건) 검색 Setting | C21: AP591_TC_016 | D21: =IFERROR(VLOOKUP($C21, '테스트 케이스'!$C$6:$F$1002, 2, FALSE), "") -> 검색 입력필드 순서를 변경한다. | E21: =IFERROR(VLOOKUP($C21, '테스트 케이스'!$C$6:$F$1002, 3, FALSE), "") -> Setting 버튼 클릭, Setting 팝업창에서 특정 필드 항목의 정렬값 숫자를 변경 후 저장 | F21: =IFERROR(VLOOKUP($C21, '테스트 케이스'!$C$6:$F$1002, 4, FALSE), "") -> 해당 필드가 정렬값대로 나열됨 (작은 숫자일수록 앞에 나열됨) | G21: Y | H21: 45807
C22: AP591_TC_017 | D22: =IFERROR(VLOOKUP($C22, '테스트 케이스'!$C$6:$F$1002, 2, FALSE), "") -> 검색 입력필드를 보이지 않게 숨긴다. | E22: =IFERROR(VLOOKUP($C22, '테스트 케이스'!$C$6:$F$1002, 3, FALSE), "") -> Setting 버튼 클릭, Setting 팝업창에서 특정 필드 숨김 설정 (화면 Display여부 N) 후 저장 | F22: =IFERROR(VLOOKUP($C22, '테스트 케이스'!$C$6:$F$1002, 4, FALSE), "") -> 해당 필드가 검색에서 숨겨짐 | G22: Y | H22: 45807
C23: AP591_TC_018 | D23: =IFERROR(VLOOKUP($C23, '테스트 케이스'!$C$6:$F$1002, 2, FALSE), "") -> 검색 입력필드를 보이도록 한다. | E23: =IFERROR(VLOOKUP($C23, '테스트 케이스'!$C$6:$F$1002, 3, FALSE), "") -> Setting 버튼 클릭, Setting 팝업창에서 특정 필드 숨김 설정 (화면 Display여부 Y) 후 저장 | F23: =IFERROR(VLOOKUP($C23, '테스트 케이스'!$C$6:$F$1002, 4, FALSE), "") -> 해당 필드가 검색에서 보임 | G23: Y | H23: 45807
C24: AP591_TC_019 | D24: =IFERROR(VLOOKUP($C24, '테스트 케이스'!$C$6:$F$1002, 2, FALSE), "") -> 검색 입력필드명을 변경한다. | E24: =IFERROR(VLOOKUP($C24, '테스트 케이스'!$C$6:$F$1002, 3, FALSE), "") -> Setting 버튼 클릭, Setting 팝업창에서 특정 필드 항목의 화면표시명 필드 값 변경 후 저장 | F24: =IFERROR(VLOOKUP($C24, '테스트 케이스'!$C$6:$F$1002, 4, FALSE), "") -> 해당 필드의 필드명이 변경됨 (새로고침 후 반영 확인) | G24: Y | H24: 45807
B25: 상세 Setting | C25: AP591_TC_020 | D25: =IFERROR(VLOOKUP($C25, '테스트 케이스'!$C$6:$F$1002, 2, FALSE), "") -> 상세 입력필드 순서를 변경한다. | E25: =IFERROR(VLOOKUP($C25, '테스트 케이스'!$C$6:$F$1002, 3, FALSE), "") -> Setting 버튼 클릭, Setting 팝업창에서 특정 필드 항목의 정렬값 숫자를 변경 후 저장 | F25: =IFERROR(VLOOKUP($C25, '테스트 케이스'!$C$6:$F$1002, 4, FALSE), "") -> 해당 필드가 정렬값대로 나열됨 (작은 숫자일수록 앞에 나열됨, 새로고침 후 반영 확인) | G25: Y | H25: 45807
C26: AP591_TC_021 | D26: =IFERROR(VLOOKUP($C26, '테스트 케이스'!$C$6:$F$1002, 2, FALSE), "") -> 상세 입력필드를 보이지 않게 숨긴다. | E26: =IFERROR(VLOOKUP($C26, '테스트 케이스'!$C$6:$F$1002, 3, FALSE), "") -> Setting 버튼 클릭, Setting 팝업창에서 특정 필드 숨김 설정 (화면 Display여부 N) 후 저장 | F26: =IFERROR(VLOOKUP($C26, '테스트 케이스'!$C$6:$F$1002, 4, FALSE), "") -> 해당 필드가 상세에서 숨겨짐 | G26: Y | H26: 45807
C27: AP591_TC_022 | D27: =IFERROR(VLOOKUP($C27, '테스트 케이스'!$C$6:$F$1002, 2, FALSE), "") -> 상세 입력필드를 보이도록 한다. | E27: =IFERROR(VLOOKUP($C27, '테스트 케이스'!$C$6:$F$1002, 3, FALSE), "") -> Setting 버튼 클릭, Setting 팝업창에서 특정 필드 숨김 설정 (화면 Display여부 Y) 후 저장 | F27: =IFERROR(VLOOKUP($C27, '테스트 케이스'!$C$6:$F$1002, 4, FALSE), "") -> 해당 필드가 상세에서 보임 | G27: Y | H27: 45807
C28: AP591_TC_023 | D28: =IFERROR(VLOOKUP($C28, '테스트 케이스'!$C$6:$F$1002, 2, FALSE), "") -> 상세 입력필드명을 변경한다. | E28: =IFERROR(VLOOKUP($C28, '테스트 케이스'!$C$6:$F$1002, 3, FALSE), "") -> Setting 버튼 클릭, Setting 팝업창에서 특정 필드 항목의 화면표시명 필드 값 변경 후 저장 | F28: =IFERROR(VLOOKUP($C28, '테스트 케이스'!$C$6:$F$1002, 4, FALSE), "") -> 해당 필드의 필드명이 변경됨 (새로고침 후 반영 확인) | G28: Y | H28: 45807
B29: 카렌다(월간), 목록(조건) 목록 Setting | C29: AP591_TC_024 | D29: =IFERROR(VLOOKUP($C29, '테스트 케이스'!$C$6:$F$1002, 2, FALSE), "") -> 목록 칼럼을 보이지 않게 숨긴다. | E29: =IFERROR(VLOOKUP($C29, '테스트 케이스'!$C$6:$F$1002, 3, FALSE), "") -> Setting 버튼 클릭, Setting 팝업창에서 특정 칼럼 숨김 설정 (화면 Display여부 N) 후 저장 | F29: =IFERROR(VLOOKUP($C29, '테스트 케이스'!$C$6:$F$1002, 4, FALSE), "") -> 해당 칼럼이 목록에서 숨겨짐 (새로고침 후 반영 확인) | G29: Y | H29: 45807
C30: AP591_TC_025 | D30: =IFERROR(VLOOKUP($C30, '테스트 케이스'!$C$6:$F$1002, 2, FALSE), "") -> 목록 칼럼을 보이도록 한다. | E30: =IFERROR(VLOOKUP($C30, '테스트 케이스'!$C$6:$F$1002, 3, FALSE), "") -> Setting 버튼 클릭, Setting 팝업창에서 특정 칼럼 숨김 설정 (화면 Display여부 Y) 후 저장 | F30: =IFERROR(VLOOKUP($C30, '테스트 케이스'!$C$6:$F$1002, 4, FALSE), "") -> 해당 칼럼이 목록에서 보임 (새로고침 후 반영 확인) | G30: Y | H30: 45807
C31: AP591_TC_026 | D31: =IFERROR(VLOOKUP($C31, '테스트 케이스'!$C$6:$F$1002, 2, FALSE), "") -> 목록 칼럼 순서를 변경한다. | E31: =IFERROR(VLOOKUP($C31, '테스트 케이스'!$C$6:$F$1002, 3, FALSE), "") -> Setting 버튼 클릭, Setting 팝업창에서 특정 칼럼 항목의 정렬값 숫자를 변경 후 저장 | F31: =IFERROR(VLOOKUP($C31, '테스트 케이스'!$C$6:$F$1002, 4, FALSE), "") -> 해당 칼럼이 정렬값대로 나열됨 (작은 숫자일수록 앞에 나열됨, 새로고침 후 반영 확인) | G31: Y | H31: 45807
C32: AP591_TC_027 | D32: =IFERROR(VLOOKUP($C32, '테스트 케이스'!$C$6:$F$1002, 2, FALSE), "") -> 목록 칼럼 너비를 변경한다. | E32: =IFERROR(VLOOKUP($C32, '테스트 케이스'!$C$6:$F$1002, 3, FALSE), "") -> Setting 버튼 클릭, Setting 팝업창에서 특정 칼럼 항목의 칼럼너비(숫자)를 입력 후 저장 | F32: =IFERROR(VLOOKUP($C32, '테스트 케이스'!$C$6:$F$1002, 4, FALSE), "") -> 해당 칼럼의 너비가 변경됨 (새로고침 후 반영 확인) | G32: Y | H32: 45807
C33: AP591_TC_028 | D33: =IFERROR(VLOOKUP($C33, '테스트 케이스'!$C$6:$F$1002, 2, FALSE), "") -> 목록 칼럼 정렬을 변경한다. | E33: =IFERROR(VLOOKUP($C33, '테스트 케이스'!$C$6:$F$1002, 3, FALSE), "") -> Setting 버튼 클릭, Setting 팝업창에서 특정 칼럼 항목의 정렬 설정 (Left, Center, Right) 후 저장 | F33: =IFERROR(VLOOKUP($C33, '테스트 케이스'!$C$6:$F$1002, 4, FALSE), "") -> 해당 칼럼의 텍스트 정렬 위치가 변경됨 (새로고침 후 반영 확인) | G33: Y | H33: 45807
C34: AP591_TC_029 | D34: =IFERROR(VLOOKUP($C34, '테스트 케이스'!$C$6:$F$1002, 2, FALSE), "") -> 목록 칼럼의 데이터 조회순서를 변경한다. | E34: =IFERROR(VLOOKUP($C34, '테스트 케이스'!$C$6:$F$1002, 3, FALSE), "") -> Setting 버튼 클릭, Setting 팝업창에서 특정 칼럼 항목의 조회순서 설정 (ASC, DESC) 후 저장 | F34: =IFERROR(VLOOKUP($C34, '테스트 케이스'!$C$6:$F$1002, 4, FALSE), "") -> 해당 칼럼의 데이터 조회 순서 변경 (새로고침 후 반영 확인, ASC : 오름차순, DESC : 내림차순) | G34: Y | H34: 45807
C35: AP591_TC_030 | D35: =IFERROR(VLOOKUP($C35, '테스트 케이스'!$C$6:$F$1002, 2, FALSE), "") -> 목록 칼럼의 배경 색상을 변경한다. | E35: =IFERROR(VLOOKUP($C35, '테스트 케이스'!$C$6:$F$1002, 3, FALSE), "") -> Setting 버튼 클릭, Setting 팝업창에서 특정 칼럼 항목의 Background Color 선택 (>,>=,<,<=,!=,Not in,In / Blue, Red) 후 저장 | F35: =IFERROR(VLOOKUP($C35, '테스트 케이스'!$C$6:$F$1002, 4, FALSE), "") -> 해당 칼럼의 배경 색상 변경 (새로고침 후 반영 확인, 특정값을 기준으로 크거나 작을 때 배경 색깔이 바뀌도록 설정 가능함) | G35: Y | H35: 45807
C36: AP591_TC_031 | D36: =IFERROR(VLOOKUP($C36, '테스트 케이스'!$C$6:$F$1002, 2, FALSE), "") -> 목록 칼럼의 리스트 길이를 변경한다. (-/+ 버튼) | E36: =IFERROR(VLOOKUP($C36, '테스트 케이스'!$C$6:$F$1002, 3, FALSE), "") -> Setting 버튼 클릭, Setting 팝업창에서 특정 칼럼 항목의 리스트 길이 (-,+) 설정 후 저장 | F36: =IFERROR(VLOOKUP($C36, '테스트 케이스'!$C$6:$F$1002, 4, FALSE), "") -> 해당 칼럼의 목록 리스트 길이가 증가 또는 감소됨 (새로고침 후 반영 확인, - : 숫자 감소, + : 숫자 증가) | G36: Y | H36: 45807
C37: AP591_TC_032 | D37: =IFERROR(VLOOKUP($C37, '테스트 케이스'!$C$6:$F$1002, 2, FALSE), "") -> 목록 칼럼의 리스트 길이를 변경한다. (숫자 입력) | E37: =IFERROR(VLOOKUP($C37, '테스트 케이스'!$C$6:$F$1002, 3, FALSE), "") -> Setting 버튼 클릭, Setting 팝업창에서 리스트 길이 숫자 입력 후 저장 | F37: =IFERROR(VLOOKUP($C37, '테스트 케이스'!$C$6:$F$1002, 4, FALSE), "") -> 해당 칼럼의 리스트 길이가 입력한 숫자만큼 변경됨 (새로고침 후 반영 확인) | G37: Y | H37: 45807
B38: 탭조회 | C38: AP591_TC_033 | D38: =IFERROR(VLOOKUP($C38, '테스트 케이스'!$C$6:$F$1002, 2, FALSE), "") -> 탭목록 데이터 개수 확인한다. | E38: =IFERROR(VLOOKUP($C38, '테스트 케이스'!$C$6:$F$1002, 3, FALSE), "") -> 탭목록 클릭 | F38: =IFERROR(VLOOKUP($C38, '테스트 케이스'!$C$6:$F$1002, 4, FALSE), "") -> 탭목록 데이터 개수가 조회됨(탭목록 우측하단 total : n/n 숫자와 조회된 데이터 개수(순번)와 일치하는지 확인) | G38: Y | H38: 45747
C39: AP591_TC_034 | D39: =IFERROR(VLOOKUP($C39, '테스트 케이스'!$C$6:$F$1002, 2, FALSE), "") -> 탭목록을 정렬한다. | E39: =IFERROR(VLOOKUP($C39, '테스트 케이스'!$C$6:$F$1002, 3, FALSE), "") -> 탭목록의 그리드 헤더 클릭 | F39: =IFERROR(VLOOKUP($C39, '테스트 케이스'!$C$6:$F$1002, 4, FALSE), "") -> 선택한 헤더의 필드값 기준으로 오름차순, 내림차순 정렬됨 | G39: Y | H39: 45747
C40: AP591_TC_035 | D40: =IFERROR(VLOOKUP($C40, '테스트 케이스'!$C$6:$F$1002, 2, FALSE), "") -> (행 클릭) 조회된 데이터의 상세정보를 조회한다. | E40: =IFERROR(VLOOKUP($C40, '테스트 케이스'!$C$6:$F$1002, 3, FALSE), "") -> 탭목록 데이터 행 클릭 | F40: =IFERROR(VLOOKUP($C40, '테스트 케이스'!$C$6:$F$1002, 4, FALSE), "") -> 탭목록 하단에 펼쳐지는 상세페이지에서 해당 데이터의 각 항목에 입력된 값을 확인할 수 있음 | G40: Y | H40: 45747
C41: AP591_TC_036 | D41: =IFERROR(VLOOKUP($C41, '테스트 케이스'!$C$6:$F$1002, 2, FALSE), "") -> (상세보기 버튼 클릭) 조회된 데이터의 상세정보를 조회한다. | E41: =IFERROR(VLOOKUP($C41, '테스트 케이스'!$C$6:$F$1002, 3, FALSE), "") -> 탭목록에서 특정 데이터 행 클릭 후 상세보기 버튼 클릭 | F41: =IFERROR(VLOOKUP($C41, '테스트 케이스'!$C$6:$F$1002, 4, FALSE), "") -> 선택한 탭데이터의 상세페이지가 팝업창으로 열림 (탭목록 하단에 펼쳐지는 상세페이지와 내용 동일) | G41: Y | H41: 45747
C42: AP591_TC_037 | D42: =IFERROR(VLOOKUP($C42, '테스트 케이스'!$C$6:$F$1002, 2, FALSE), "") -> 탭목록 데이터의 포맷 형태를 확인한다. | E42: =IFERROR(VLOOKUP($C42, '테스트 케이스'!$C$6:$F$1002, 3, FALSE), "") -> 탭목록에 조회된 각 데이터 종류에 따른 포맷 형태를 확인한다. | F42: =IFERROR(VLOOKUP($C42, '테스트 케이스'!$C$6:$F$1002, 4, FALSE), "") -> 숫자는 천단위 반점표기, 날짜는 yyyy-mm-dd (숫자 : 오른쪽 정렬 , 텍스트 : 왼쪽 정렬 , 코드/날짜 : 가운데 정렬) | G42: Y | H42: 45747
...
