Workbook

Sheet 테스트 케이스
A2: ="Dream 4.1 "&CLEAN(A6)&" 단위테스트" -> Dream 4.1 정기점검주기_AD230 단위테스트
A4: 공통 | K4: H,I,J,K 행 수식 수정 금지
A5: 메뉴명 | B5: 탭 명 | C5: 기능 | D5: 테스트ID | E5: CASE | F5: STEP | G5: 테스트 예상 결과 | H5: QA | I5: QA결과 (정상/오류) | J5: QA내용 | K5: QA날짜
A6: 정기점검주기_AD230 | B6: 목록(조건) | C6: 검색 | D6: AD230_TC_001 | E6: 검색 필드의 기본값을 확인한다. | F6: 메뉴 접속 후 목록(조건) 탭 클릭 | G6: 시행여부 = Y 로 입력되어 있고, 나머지 검색 필드(예방작업번호, 작업명, 설비, 설비위치, 공장명, 부서명, 작업그룹명, 담당자, 거래처)는 비어 있음 | H6: {=INDEX('Dev 조치사항'!$H$6:$H$1004, MATCH(1, ('Dev 조치사항'!$D$6:$D$1004=D6)*('Dev 조치사항'!$K$6:$K$1004=_xlfn.MAXIFS('Dev 조치사항'!$K$6:$K$1004, 'Dev 조치사항'!$D$6:$D$1004, D6)), 0))} -> 최신영 | I6: {=INDEX('Dev 조치사항'!$I$6:$I$1004, MATCH(1, ('Dev 조치사항'!$D$6:$D$1004=D6)*('Dev 조치사항'!$K$6:$K$1004=_xlfn.MAXIFS('Dev 조치사항'!$K$6:$K$1004, 'Dev 조치사항'!$D$6:$D$1004, D6)), 0))} -> 정상 | J6: {=IF( INDEX('Dev 조치사항'!$J$6:$J$1004, MATCH(1, ('Dev 조치사항'!$D$6:$D$1004=D6)* ('Dev 조치사항'!$K$6:$K$1004=_xlfn.MAXIFS('Dev 조치사항'!$K$6:$K$1004, 'Dev 조치사항'!$D$6:$D$1004, D6)), 0) ) = "", "-", INDEX('Dev 조치사항'!$J$6:$J$1004, MATCH(1, ('Dev 조치사항'!$D$6:$D$1004=D6)* ('Dev 조치사항'!$K$6:$K$1004=_xlfn.MAXIFS('Dev 조치사항'!$K$6:$K$1004, 'Dev 조치사항'!$D$6:$D$1004, D6)), 0) ) )} -> - | K6: =_xlfn.MAXIFS('Dev 조치사항'!$K$6:$K$1004, 'Dev 조치사항'!$D$6:$D$1004, D6) -> 46315
C7: 검색 | D7: AD230_TC_002 | E7: 설비 Lov 팝업의 데이터를 확인한다. | F7: 설비 필드의 돋보기(Lov) 클릭 → 팝업의 목록(위치) 탭 Total 확인 | G7: "설비" Lov 팝업이 열리고, 목록 건수와 내용이 [설비자산 > 설비] 메뉴 목록과 일치함 | H7: {=INDEX('Dev 조치사항'!$H$6:$H$1004, MATCH(1, ('Dev 조치사항'!$D$6:$D$1004=D7)*('Dev 조치사항'!$K$6:$K$1004=_xlfn.MAXIFS('Dev 조치사항'!$K$6:$K$1004, 'Dev 조치사항'!$D$6:$D$1004, D7)), 0))} -> 최신영 | I7: {=INDEX('Dev 조치사항'!$I$6:$I$1004, MATCH(1, ('Dev 조치사항'!$D$6:$D$1004=D7)*('Dev 조치사항'!$K$6:$K$1004=_xlfn.MAXIFS('Dev 조치사항'!$K$6:$K$1004, 'Dev 조치사항'!$D$6:$D$1004, D7)), 0))} -> 정상 | J7: {=IF( INDEX('Dev 조치사항'!$J$6:$J$1004, MATCH(1, ('Dev 조치사항'!$D$6:$D$1004=D7)* ('Dev 조치사항'!$K$6:$K$1004=_xlfn.MAXIFS('Dev 조치사항'!$K$6:$K$1004, 'Dev 조치사항'!$D$6:$D$1004, D7)), 0) ) = "", "-", INDEX('Dev 조치사항'!$J$6:$J$1004, MATCH(1, ('Dev 조치사항'!$D$6:$D$1004=D7)* ('Dev 조치사항'!$K$6:$K$1004=_xlfn.MAXIFS('Dev 조치사항'!$K$6:$K$1004, 'Dev 조치사항'!$D$6:$D$1004, D7)), 0) ) )} -> - | K7: =_xlfn.MAXIFS('Dev 조치사항'!$K$6:$K$1004, 'Dev 조치사항'!$D$6:$D$1004, D7) -> 46315
D8: AD230_TC_003 | E8: 그 외 검색 필드 Lov 팝업의 데이터를 확인한다. | F8: 설비위치, 공장명, 부서명, 작업그룹명, 담당자, 거래처, 시행여부의 돋보기(Lov)를 하나씩 클릭 | G8: 각 Lov 팝업이 열리고, 목록이 원본 메뉴(설비위치설정, 공장설정, 부서, 작업그룹, 사원, 거래처, 시스템코드 IS_USE)와 일치함 | H8: {=INDEX('Dev 조치사항'!$H$6:$H$1004, MATCH(1, ('Dev 조치사항'!$D$6:$D$1004=D8)*('Dev 조치사항'!$K$6:$K$1004=_xlfn.MAXIFS('Dev 조치사항'!$K$6:$K$1004, 'Dev 조치사항'!$D$6:$D$1004, D8)), 0))} -> 최신영 | I8: {=INDEX('Dev 조치사항'!$I$6:$I$1004, MATCH(1, ('Dev 조치사항'!$D$6:$D$1004=D8)*('Dev 조치사항'!$K$6:$K$1004=_xlfn.MAXIFS('Dev 조치사항'!$K$6:$K$1004, 'Dev 조치사항'!$D$6:$D$1004, D8)), 0))} -> 정상 | J8: {=IF( INDEX('Dev 조치사항'!$J$6:$J$1004, MATCH(1, ('Dev 조치사항'!$D$6:$D$1004=D8)* ('Dev 조치사항'!$K$6:$K$1004=_xlfn.MAXIFS('Dev 조치사항'!$K$6:$K$1004, 'Dev 조치사항'!$D$6:$D$1004, D8)), 0) ) = "", "-", INDEX('Dev 조치사항'!$J$6:$J$1004, MATCH(1, ('Dev 조치사항'!$D$6:$D$1004=D8)* ('Dev 조치사항'!$K$6:$K$1004=_xlfn.MAXIFS('Dev 조치사항'!$K$6:$K$1004, 'Dev 조치사항'!$D$6:$D$1004, D8)), 0) ) )} -> - | K8: =_xlfn.MAXIFS('Dev 조치사항'!$K$6:$K$1004, 'Dev 조치사항'!$D$6:$D$1004, D8) -> 46315
D9: AD230_TC_004 | E9: 조건 하나로 정기점검주기를 검색한다. | F9: 검색 필드마다 실제 데이터 값 1개씩 입력(Lov 필드는 Lov에서 선택) 후 검색 버튼 클릭 | G9: 입력한 조건에 맞는 데이터만 목록에 표시되고, 우측 하단 Total 숫자와 조회 건수가 일치함 | H9: {=INDEX('Dev 조치사항'!$H$6:$H$1004, MATCH(1, ('Dev 조치사항'!$D$6:$D$1004=D9)*('Dev 조치사항'!$K$6:$K$1004=_xlfn.MAXIFS('Dev 조치사항'!$K$6:$K$1004, 'Dev 조치사항'!$D$6:$D$1004, D9)), 0))} -> 최신영 | I9: {=INDEX('Dev 조치사항'!$I$6:$I$1004, MATCH(1, ('Dev 조치사항'!$D$6:$D$1004=D9)*('Dev 조치사항'!$K$6:$K$1004=_xlfn.MAXIFS('Dev 조치사항'!$K$6:$K$1004, 'Dev 조치사항'!$D$6:$D$1004, D9)), 0))} -> 정상 | J9: {=IF( INDEX('Dev 조치사항'!$J$6:$J$1004, MATCH(1, ('Dev 조치사항'!$D$6:$D$1004=D9)* ('Dev 조치사항'!$K$6:$K$1004=_xlfn.MAXIFS('Dev 조치사항'!$K$6:$K$1004, 'Dev 조치사항'!$D$6:$D$1004, D9)), 0) ) = "", "-", INDEX('Dev 조치사항'!$J$6:$J$1004, MATCH(1, ('Dev 조치사항'!$D$6:$D$1004=D9)* ('Dev 조치사항'!$K$6:$K$1004=_xlfn.MAXIFS('Dev 조치사항'!$K$6:$K$1004, 'Dev 조치사항'!$D$6:$D$1004, D9)), 0) ) )} -> - | K9: =_xlfn.MAXIFS('Dev 조치사항'!$K$6:$K$1004, 'Dev 조치사항'!$D$6:$D$1004, D9) -> 46315
D10: AD230_TC_005 | E10: 여러 조건을 조합하여 검색한다. | F10: ① 공장명 + 시행여부 ② 설비 + 부서명 을 함께 입력 후 검색 | G10: 모든 조건을 동시에 만족하는 데이터만 표시됨 | H10: {=INDEX('Dev 조치사항'!$H$6:$H$1004, MATCH(1, ('Dev 조치사항'!$D$6:$D$1004=D10)*('Dev 조치사항'!$K$6:$K$1004=_xlfn.MAXIFS('Dev 조치사항'!$K$6:$K$1004, 'Dev 조치사항'!$D$6:$D$1004, D10)), 0))} -> 최신영 | I10: {=INDEX('Dev 조치사항'!$I$6:$I$1004, MATCH(1, ('Dev 조치사항'!$D$6:$D$1004=D10)*('Dev 조치사항'!$K$6:$K$1004=_xlfn.MAXIFS('Dev 조치사항'!$K$6:$K$1004, 'Dev 조치사항'!$D$6:$D$1004, D10)), 0))} -> 정상 | J10: {=IF( INDEX('Dev 조치사항'!$J$6:$J$1004, MATCH(1, ('Dev 조치사항'!$D$6:$D$1004=D10)* ('Dev 조치사항'!$K$6:$K$1004=_xlfn.MAXIFS('Dev 조치사항'!$K$6:$K$1004, 'Dev 조치사항'!$D$6:$D$1004, D10)), 0) ) = "", "-", INDEX('Dev 조치사항'!$J$6:$J$1004, MATCH(1, ('Dev 조치사항'!$D$6:$D$1004=D10)* ('Dev 조치사항'!$K$6:$K$1004=_xlfn.MAXIFS('Dev 조치사항'!$K$6:$K$1004, 'Dev 조치사항'!$D$6:$D$1004, D10)), 0) ) )} -> - | K10: =_xlfn.MAXIFS('Dev 조치사항'!$K$6:$K$1004, 'Dev 조치사항'!$D$6:$D$1004, D10) -> 46315
D11: AD230_TC_006 | E11: 정기점검주기 전체를 검색한다. | F11: 검색 필드의 값을 모두 지운 뒤 검색 버튼 클릭 | G11: 시행여부 Y/N 구분 없이 등록된 전체 데이터가 표시되고 Total n/n 이 전체 건수와 일치함 | H11: {=INDEX('Dev 조치사항'!$H$6:$H$1004, MATCH(1, ('Dev 조치사항'!$D$6:$D$1004=D11)*('Dev 조치사항'!$K$6:$K$1004=_xlfn.MAXIFS('Dev 조치사항'!$K$6:$K$1004, 'Dev 조치사항'!$D$6:$D$1004, D11)), 0))} -> 최신영 | I11: {=INDEX('Dev 조치사항'!$I$6:$I$1004, MATCH(1, ('Dev 조치사항'!$D$6:$D$1004=D11)*('Dev 조치사항'!$K$6:$K$1004=_xlfn.MAXIFS('Dev 조치사항'!$K$6:$K$1004, 'Dev 조치사항'!$D$6:$D$1004, D11)), 0))} -> 정상 | J11: {=IF( INDEX('Dev 조치사항'!$J$6:$J$1004, MATCH(1, ('Dev 조치사항'!$D$6:$D$1004=D11)* ('Dev 조치사항'!$K$6:$K$1004=_xlfn.MAXIFS('Dev 조치사항'!$K$6:$K$1004, 'Dev 조치사항'!$D$6:$D$1004, D11)), 0) ) = "", "-", INDEX('Dev 조치사항'!$J$6:$J$1004, MATCH(1, ('Dev 조치사항'!$D$6:$D$1004=D11)* ('Dev 조치사항'!$K$6:$K$1004=_xlfn.MAXIFS('Dev 조치사항'!$K$6:$K$1004, 'Dev 조치사항'!$D$6:$D$1004, D11)), 0) ) )} -> - | K11: =_xlfn.MAXIFS('Dev 조치사항'!$K$6:$K$1004, 'Dev 조치사항'!$D$6:$D$1004, D11) -> 46315
D12: AD230_TC_007 | E12: 검색 결과가 없는 조건으로 검색한다. | F12: 존재하지 않는 작업명 입력 후 검색 | G12: 목록이 비어 있고 Total 0/0 표시, 오류 팝업 없음 | H12: {=INDEX('Dev 조치사항'!$H$6:$H$1004, MATCH(1, ('Dev 조치사항'!$D$6:$D$1004=D12)*('Dev 조치사항'!$K$6:$K$1004=_xlfn.MAXIFS('Dev 조치사항'!$K$6:$K$1004, 'Dev 조치사항'!$D$6:$D$1004, D12)), 0))} -> 최신영 | I12: {=INDEX('Dev 조치사항'!$I$6:$I$1004, MATCH(1, ('Dev 조치사항'!$D$6:$D$1004=D12)*('Dev 조치사항'!$K$6:$K$1004=_xlfn.MAXIFS('Dev 조치사항'!$K$6:$K$1004, 'Dev 조치사항'!$D$6:$D$1004, D12)), 0))} -> 정상 | J12: {=IF( INDEX('Dev 조치사항'!$J$6:$J$1004, MATCH(1, ('Dev 조치사항'!$D$6:$D$1004=D12)* ('Dev 조치사항'!$K$6:$K$1004=_xlfn.MAXIFS('Dev 조치사항'!$K$6:$K$1004, 'Dev 조치사항'!$D$6:$D$1004, D12)), 0) ) = "", "-", INDEX('Dev 조치사항'!$J$6:$J$1004, MATCH(1, ('Dev 조치사항'!$D$6:$D$1004=D12)* ('Dev 조치사항'!$K$6:$K$1004=_xlfn.MAXIFS('Dev 조치사항'!$K$6:$K$1004, 'Dev 조치사항'!$D$6:$D$1004, D12)), 0) ) )} -> - | K12: =_xlfn.MAXIFS('Dev 조치사항'!$K$6:$K$1004, 'Dev 조치사항'!$D$6:$D$1004, D12) -> 46315
B13: 목록(위치), 목록(종류) | C13: 검색 | D13: AD230_TC_008 | E13: 트리에서 위치/종류를 선택하여 조회한다. | F13: ① 목록(위치) 탭에서 위치명 트리의 위치 클릭 ② 목록(종류) 탭에서 설비종류 트리의 종류 클릭 | G13: 선택한 위치/종류에 속한 설비의 정기점검주기만 오른쪽 목록에 표시됨 | H13: {=INDEX('Dev 조치사항'!$H$6:$H$1004, MATCH(1, ('Dev 조치사항'!$D$6:$D$1004=D13)*('Dev 조치사항'!$K$6:$K$1004=_xlfn.MAXIFS('Dev 조치사항'!$K$6:$K$1004, 'Dev 조치사항'!$D$6:$D$1004, D13)), 0))} -> 최신영 | I13: {=INDEX('Dev 조치사항'!$I$6:$I$1004, MATCH(1, ('Dev 조치사항'!$D$6:$D$1004=D13)*('Dev 조치사항'!$K$6:$K$1004=_xlfn.MAXIFS('Dev 조치사항'!$K$6:$K$1004, 'Dev 조치사항'!$D$6:$D$1004, D13)), 0))} -> 정상 | J13: {=IF( INDEX('Dev 조치사항'!$J$6:$J$1004, MATCH(1, ('Dev 조치사항'!$D$6:$D$1004=D13)* ('Dev 조치사항'!$K$6:$K$1004=_xlfn.MAXIFS('Dev 조치사항'!$K$6:$K$1004, 'Dev 조치사항'!$D$6:$D$1004, D13)), 0) ) = "", "-", INDEX('Dev 조치사항'!$J$6:$J$1004, MATCH(1, ('Dev 조치사항'!$D$6:$D$1004=D13)* ('Dev 조치사항'!$K$6:$K$1004=_xlfn.MAXIFS('Dev 조치사항'!$K$6:$K$1004, 'Dev 조치사항'!$D$6:$D$1004, D13)), 0) ) )} -> - | K13: =_xlfn.MAXIFS('Dev 조치사항'!$K$6:$K$1004, 'Dev 조치사항'!$D$6:$D$1004, D13) -> 46315
B14: 목록(위치), 목록(종류), 목록(조건) | C14: 조회 | D14: AD230_TC_009 | E14: 조회된 목록을 정렬한다. | F14: 목록 그리드 헤더(예방작업번호, 작업명, 설비번호) 클릭 2회 | G14: 선택한 열 기준으로 오름차순 → 내림차순 정렬됨 | H14: {=INDEX('Dev 조치사항'!$H$6:$H$1004, MATCH(1, ('Dev 조치사항'!$D$6:$D$1004=D14)*('Dev 조치사항'!$K$6:$K$1004=_xlfn.MAXIFS('Dev 조치사항'!$K$6:$K$1004, 'Dev 조치사항'!$D$6:$D$1004, D14)), 0))} -> 최신영 | I14: {=INDEX('Dev 조치사항'!$I$6:$I$1004, MATCH(1, ('Dev 조치사항'!$D$6:$D$1004=D14)*('Dev 조치사항'!$K$6:$K$1004=_xlfn.MAXIFS('Dev 조치사항'!$K$6:$K$1004, 'Dev 조치사항'!$D$6:$D$1004, D14)), 0))} -> 정상 | J14: {=IF( INDEX('Dev 조치사항'!$J$6:$J$1004, MATCH(1, ('Dev 조치사항'!$D$6:$D$1004=D14)* ('Dev 조치사항'!$K$6:$K$1004=_xlfn.MAXIFS('Dev 조치사항'!$K$6:$K$1004, 'Dev 조치사항'!$D$6:$D$1004, D14)), 0) ) = "", "-", INDEX('Dev 조치사항'!$J$6:$J$1004, MATCH(1, ('Dev 조치사항'!$D$6:$D$1004=D14)* ('Dev 조치사항'!$K$6:$K$1004=_xlfn.MAXIFS('Dev 조치사항'!$K$6:$K$1004, 'Dev 조치사항'!$D$6:$D$1004, D14)), 0) ) )} -> - | K14: =_xlfn.MAXIFS('Dev 조치사항'!$K$6:$K$1004, 'Dev 조치사항'!$D$6:$D$1004, D14) -> 46315
C15: 조회 | D15: AD230_TC_010 | E15: 목록 건수 표시를 확인한다. | F15: 전체 검색 후 목록을 끝까지 스크롤 | G15: Total a/b 에서 a 는 화면에 불러온 건수, b 는 전체 건수이며 스크롤 시 끝까지 불러오면 a = b | H15: {=INDEX('Dev 조치사항'!$H$6:$H$1004, MATCH(1, ('Dev 조치사항'!$D$6:$D$1004=D15)*('Dev 조치사항'!$K$6:$K$1004=_xlfn.MAXIFS('Dev 조치사항'!$K$6:$K$1004, 'Dev 조치사항'!$D$6:$D$1004, D15)), 0))} -> 최신영 | I15: {=INDEX('Dev 조치사항'!$I$6:$I$1004, MATCH(1, ('Dev 조치사항'!$D$6:$D$1004=D15)*('Dev 조치사항'!$K$6:$K$1004=_xlfn.MAXIFS('Dev 조치사항'!$K$6:$K$1004, 'Dev 조치사항'!$D$6:$D$1004, D15)), 0))} -> 정상 | J15: {=IF( INDEX('Dev 조치사항'!$J$6:$J$1004, MATCH(1, ('Dev 조치사항'!$D$6:$D$1004=D15)* ('Dev 조치사항'!$K$6:$K$1004=_xlfn.MAXIFS('Dev 조치사항'!$K$6:$K$1004, 'Dev 조치사항'!$D$6:$D$1004, D15)), 0) ) = "", "-", INDEX('Dev 조치사항'!$J$6:$J$1004, MATCH(1, ('Dev 조치사항'!$D$6:$D$1004=D15)* ('Dev 조치사항'!$K$6:$K$1004=_xlfn.MAXIFS('Dev 조치사항'!$K$6:$K$1004, 'Dev 조치사항'!$D$6:$D$1004, D15)), 0) ) )} -> - | K15: =_xlfn.MAXIFS('Dev 조치사항'!$K$6:$K$1004, 'Dev 조치사항'!$D$6:$D$1004, D15) -> 46315
D16: AD230_TC_011 | E16: (행 클릭) 상세정보를 조회한다. | F16: 목록의 데이터 행 클릭 | G16: 목록 하단에 상세(정기점검주기설정 : 번호 / 작업명)가 열리고 해당 데이터 값이 표시됨 | H16: {=INDEX('Dev 조치사항'!$H$6:$H$1004, MATCH(1, ('Dev 조치사항'!$D$6:$D$1004=D16)*('Dev 조치사항'!$K$6:$K$1004=_xlfn.MAXIFS('Dev 조치사항'!$K$6:$K$1004, 'Dev 조치사항'!$D$6:$D$1004, D16)), 0))} -> 최신영 | I16: {=INDEX('Dev 조치사항'!$I$6:$I$1004, MATCH(1, ('Dev 조치사항'!$D$6:$D$1004=D16)*('Dev 조치사항'!$K$6:$K$1004=_xlfn.MAXIFS('Dev 조치사항'!$K$6:$K$1004, 'Dev 조치사항'!$D$6:$D$1004, D16)), 0))} -> 정상 | J16: {=IF( INDEX('Dev 조치사항'!$J$6:$J$1004, MATCH(1, ('Dev 조치사항'!$D$6:$D$1004=D16)* ('Dev 조치사항'!$K$6:$K$1004=_xlfn.MAXIFS('Dev 조치사항'!$K$6:$K$1004, 'Dev 조치사항'!$D$6:$D$1004, D16)), 0) ) = "", "-", INDEX('Dev 조치사항'!$J$6:$J$1004, MATCH(1, ('Dev 조치사항'!$D$6:$D$1004=D16)* ('Dev 조치사항'!$K$6:$K$1004=_xlfn.MAXIFS('Dev 조치사항'!$K$6:$K$1004, 'Dev 조치사항'!$D$6:$D$1004, D16)), 0) ) )} -> - | K16: =_xlfn.MAXIFS('Dev 조치사항'!$K$6:$K$1004, 'Dev 조치사항'!$D$6:$D$1004, D16) -> 46315
D17: AD230_TC_012 | E17: (상세보기 버튼) 상세정보를 조회한다. | F17: 목록에서 행 선택 후 상세보기 버튼 클릭 | G17: 선택한 데이터의 상세가 팝업창으로 열리며 하단 상세와 내용이 같음 | H17: {=INDEX('Dev 조치사항'!$H$6:$H$1004, MATCH(1, ('Dev 조치사항'!$D$6:$D$1004=D17)*('Dev 조치사항'!$K$6:$K$1004=_xlfn.MAXIFS('Dev 조치사항'!$K$6:$K$1004, 'Dev 조치사항'!$D$6:$D$1004, D17)), 0))} -> 최신영 | I17: {=INDEX('Dev 조치사항'!$I$6:$I$1004, MATCH(1, ('Dev 조치사항'!$D$6:$D$1004=D17)*('Dev 조치사항'!$K$6:$K$1004=_xlfn.MAXIFS('Dev 조치사항'!$K$6:$K$1004, 'Dev 조치사항'!$D$6:$D$1004, D17)), 0))} -> 정상 | J17: {=IF( INDEX('Dev 조치사항'!$J$6:$J$1004, MATCH(1, ('Dev 조치사항'!$D$6:$D$1004=D17)* ('Dev 조치사항'!$K$6:$K$1004=_xlfn.MAXIFS('Dev 조치사항'!$K$6:$K$1004, 'Dev 조치사항'!$D$6:$D$1004, D17)), 0) ) = "", "-", INDEX('Dev 조치사항'!$J$6:$J$1004, MATCH(1, ('Dev 조치사항'!$D$6:$D$1004=D17)* ('Dev 조치사항'!$K$6:$K$1004=_xlfn.MAXIFS('Dev 조치사항'!$K$6:$K$1004, 'Dev 조치사항'!$D$6:$D$1004, D17)), 0) ) )} -> - | K17: =_xlfn.MAXIFS('Dev 조치사항'!$K$6:$K$1004, 'Dev 조치사항'!$D$6:$D$1004, D17) -> 46315
D18: AD230_TC_013 | E18: 목록과 상세의 값이 일치하는지 확인한다. | F18: 목록 한 행의 예방작업번호, 작업명, 설비, 작업그룹명, 담당자, 일정생성방법, 주기를 상세 값과 비교 | G18: 목록과 상세의 값이 모두 같음 | H18: {=INDEX('Dev 조치사항'!$H$6:$H$1004, MATCH(1, ('Dev 조치사항'!$D$6:$D$1004=D18)*('Dev 조치사항'!$K$6:$K$1004=_xlfn.MAXIFS('Dev 조치사항'!$K$6:$K$1004, 'Dev 조치사항'!$D$6:$D$1004, D18)), 0))} -> 최신영 | I18: {=INDEX('Dev 조치사항'!$I$6:$I$1004, MATCH(1, ('Dev 조치사항'!$D$6:$D$1004=D18)*('Dev 조치사항'!$K$6:$K$1004=_xlfn.MAXIFS('Dev 조치사항'!$K$6:$K$1004, 'Dev 조치사항'!$D$6:$D$1004, D18)), 0))} -> 정상 | J18: {=IF( INDEX('Dev 조치사항'!$J$6:$J$1004, MATCH(1, ('Dev 조치사항'!$D$6:$D$1004=D18)* ('Dev 조치사항'!$K$6:$K$1004=_xlfn.MAXIFS('Dev 조치사항'!$K$6:$K$1004, 'Dev 조치사항'!$D$6:$D$1004, D18)), 0) ) = "", "-", INDEX('Dev 조치사항'!$J$6:$J$1004, MATCH(1, ('Dev 조치사항'!$D$6:$D$1004=D18)* ('Dev 조치사항'!$K$6:$K$1004=_xlfn.MAXIFS('Dev 조치사항'!$K$6:$K$1004, 'Dev 조치사항'!$D$6:$D$1004, D18)), 0) ) )} -> - | K18: =_xlfn.MAXIFS('Dev 조치사항'!$K$6:$K$1004, 'Dev 조치사항'!$D$6:$D$1004, D18) -> 46315
D19: AD230_TC_014 | E19: (목록) 데이터 표시 형식을 확인한다. | F19: 목록의 숫자, 날짜, 텍스트, 코드 열 확인 | G19: 숫자: 천단위 쉼표, 오른쪽 정렬 / 날짜: yyyy-mm-dd, 가운데 정렬 / 텍스트: 왼쪽 정렬 / 코드: 가운데 정렬 | H19: {=INDEX('Dev 조치사항'!$H$6:$H$1004, MATCH(1, ('Dev 조치사항'!$D$6:$D$1004=D19)*('Dev 조치사항'!$K$6:$K$1004=_xlfn.MAXIFS('Dev 조치사항'!$K$6:$K$1004, 'Dev 조치사항'!$D$6:$D$1004, D19)), 0))} -> 최신영 | I19: {=INDEX('Dev 조치사항'!$I$6:$I$1004, MATCH(1, ('Dev 조치사항'!$D$6:$D$1004=D19)*('Dev 조치사항'!$K$6:$K$1004=_xlfn.MAXIFS('Dev 조치사항'!$K$6:$K$1004, 'Dev 조치사항'!$D$6:$D$1004, D19)), 0))} -> 정상 | J19: {=IF( INDEX('Dev 조치사항'!$J$6:$J$1004, MATCH(1, ('Dev 조치사항'!$D$6:$D$1004=D19)* ('Dev 조치사항'!$K$6:$K$1004=_xlfn.MAXIFS('Dev 조치사항'!$K$6:$K$1004, 'Dev 조치사항'!$D$6:$D$1004, D19)), 0) ) = "", "-", INDEX('Dev 조치사항'!$J$6:$J$1004, MATCH(1, ('Dev 조치사항'!$D$6:$D$1004=D19)* ('Dev 조치사항'!$K$6:$K$1004=_xlfn.MAXIFS('Dev 조치사항'!$K$6:$K$1004, 'Dev 조치사항'!$D$6:$D$1004, D19)), 0) ) )} -> - | K19: =_xlfn.MAXIFS('Dev 조치사항'!$K$6:$K$1004, 'Dev 조치사항'!$D$6:$D$1004, D19) -> 46315
D20: AD230_TC_015 | E20: (상세) 데이터 표시 형식을 확인한다. | F20: 상세의 숫자(주기, 몇일전 일정생성?, 예상작업시간), 날짜 필드 확인 | G20: 숫자는 오른쪽 정렬, 날짜는 yyyy-mm-dd | H20: {=INDEX('Dev 조치사항'!$H$6:$H$1004, MATCH(1, ('Dev 조치사항'!$D$6:$D$1004=D20)*('Dev 조치사항'!$K$6:$K$1004=_xlfn.MAXIFS('Dev 조치사항'!$K$6:$K$1004, 'Dev 조치사항'!$D$6:$D$1004, D20)), 0))} -> 최신영 | I20: {=INDEX('Dev 조치사항'!$I$6:$I$1004, MATCH(1, ('Dev 조치사항'!$D$6:$D$1004=D20)*('Dev 조치사항'!$K$6:$K$1004=_xlfn.MAXIFS('Dev 조치사항'!$K$6:$K$1004, 'Dev 조치사항'!$D$6:$D$1004, D20)), 0))} -> 정상 | J20: {=IF( INDEX('Dev 조치사항'!$J$6:$J$1004, MATCH(1, ('Dev 조치사항'!$D$6:$D$1004=D20)* ('Dev 조치사항'!$K$6:$K$1004=_xlfn.MAXIFS('Dev 조치사항'!$K$6:$K$1004, 'Dev 조치사항'!$D$6:$D$1004, D20)), 0) ) = "", "-", INDEX('Dev 조치사항'!$J$6:$J$1004, MATCH(1, ('Dev 조치사항'!$D$6:$D$1004=D20)* ('Dev 조치사항'!$K$6:$K$1004=_xlfn.MAXIFS('Dev 조치사항'!$K$6:$K$1004, 'Dev 조치사항'!$D$6:$D$1004, D20)), 0) ) )} -> - | K20: =_xlfn.MAXIFS('Dev 조치사항'!$K$6:$K$1004, 'Dev 조치사항'!$D$6:$D$1004, D20) -> 46315
D21: AD230_TC_016 | E21: 읽기전용 필드를 확인한다. | F21: 상세에서 작업종류, 작업형태, 예방작업번호 클릭 후 입력 시도 | G21: 회색으로 표시되고 값을 수정할 수 없음 | H21: {=INDEX('Dev 조치사항'!$H$6:$H$1004, MATCH(1, ('Dev 조치사항'!$D$6:$D$1004=D21)*('Dev 조치사항'!$K$6:$K$1004=_xlfn.MAXIFS('Dev 조치사항'!$K$6:$K$1004, 'Dev 조치사항'!$D$6:$D$1004, D21)), 0))} -> 최신영 | I21: {=INDEX('Dev 조치사항'!$I$6:$I$1004, MATCH(1, ('Dev 조치사항'!$D$6:$D$1004=D21)*('Dev 조치사항'!$K$6:$K$1004=_xlfn.MAXIFS('Dev 조치사항'!$K$6:$K$1004, 'Dev 조치사항'!$D$6:$D$1004, D21)), 0))} -> 정상 | J21: {=IF( INDEX('Dev 조치사항'!$J$6:$J$1004, MATCH(1, ('Dev 조치사항'!$D$6:$D$1004=D21)* ('Dev 조치사항'!$K$6:$K$1004=_xlfn.MAXIFS('Dev 조치사항'!$K$6:$K$1004, 'Dev 조치사항'!$D$6:$D$1004, D21)), 0) ) = "", "-", INDEX('Dev 조치사항'!$J$6:$J$1004, MATCH(1, ('Dev 조치사항'!$D$6:$D$1004=D21)* ('Dev 조치사항'!$K$6:$K$1004=_xlfn.MAXIFS('Dev 조치사항'!$K$6:$K$1004, 'Dev 조치사항'!$D$6:$D$1004, D21)), 0) ) )} -> - | K21: =_xlfn.MAXIFS('Dev 조치사항'!$K$6:$K$1004, 'Dev 조치사항'!$D$6:$D$1004, D21) -> 46315
C22: 닫기 | D22: AD230_TC_017 | E22: 상세를 닫는다. | F22: ① 하단 상세의 닫기(ⓧ) 클릭 ② 상세보기 팝업의 X 클릭 | G22: 상세(팝업)가 닫히고 목록 화면만 남음 | H22: {=INDEX('Dev 조치사항'!$H$6:$H$1004, MATCH(1, ('Dev 조치사항'!$D$6:$D$1004=D22)*('Dev 조치사항'!$K$6:$K$1004=_xlfn.MAXIFS('Dev 조치사항'!$K$6:$K$1004, 'Dev 조치사항'!$D$6:$D$1004, D22)), 0))} -> 최신영 | I22: {=INDEX('Dev 조치사항'!$I$6:$I$1004, MATCH(1, ('Dev 조치사항'!$D$6:$D$1004=D22)*('Dev 조치사항'!$K$6:$K$1004=_xlfn.MAXIFS('Dev 조치사항'!$K$6:$K$1004, 'Dev 조치사항'!$D$6:$D$1004, D22)), 0))} -> 정상 | J22: {=IF( INDEX('Dev 조치사항'!$J$6:$J$1004, MATCH(1, ('Dev 조치사항'!$D$6:$D$1004=D22)* ('Dev 조치사항'!$K$6:$K$1004=_xlfn.MAXIFS('Dev 조치사항'!$K$6:$K$1004, 'Dev 조치사항'!$D$6:$D$1004, D22)), 0) ) = "", "-", INDEX('Dev 조치사항'!$J$6:$J$1004, MATCH(1, ('Dev 조치사항'!$D$6:$D$1004=D22)* ('Dev 조치사항'!$K$6:$K$1004=_xlfn.MAXIFS('Dev 조치사항'!$K$6:$K$1004, 'Dev 조치사항'!$D$6:$D$1004, D22)), 0) ) )} -> - | K22: =_xlfn.MAXIFS('Dev 조치사항'!$K$6:$K$1004, 'Dev 조치사항'!$D$6:$D$1004, D22) -> 46315
C23: 생성 | D23: AD230_TC_018 | E23: 생성 시 기본값을 확인한다. | F23: 목록의 생성 버튼 클릭 (목록(위치)/(종류)에서는 작업형태 선택) | G23: 빈 상세가 열리고 기본값이 채워짐: 작업종류·작업형태 = 정기점검, 예방작업번호 자동 부여, 시행여부 Y, 일정생성방법 TBM, 몇일전 일정생성? 7, 공장·부서명 = 로그인 사용자 소속 | H23: {=INDEX('Dev 조치사항'!$H$6:$H$1004, MATCH(1, ('Dev 조치사항'!$D$6:$D$1004=D23)*('Dev 조치사항'!$K$6:$K$1004=_xlfn.MAXIFS('Dev 조치사항'!$K$6:$K$1004, 'Dev 조치사항'!$D$6:$D$1004, D23)), 0))} -> 최신영 | I23: {=INDEX('Dev 조치사항'!$I$6:$I$1004, MATCH(1, ('Dev 조치사항'!$D$6:$D$1004=D23)*('Dev 조치사항'!$K$6:$K$1004=_xlfn.MAXIFS('Dev 조치사항'!$K$6:$K$1004, 'Dev 조치사항'!$D$6:$D$1004, D23)), 0))} -> 정상 | J23: {=IF( INDEX('Dev 조치사항'!$J$6:$J$1004, MATCH(1, ('Dev 조치사항'!$D$6:$D$1004=D23)* ('Dev 조치사항'!$K$6:$K$1004=_xlfn.MAXIFS('Dev 조치사항'!$K$6:$K$1004, 'Dev 조치사항'!$D$6:$D$1004, D23)), 0) ) = "", "-", INDEX('Dev 조치사항'!$J$6:$J$1004, MATCH(1, ('Dev 조치사항'!$D$6:$D$1004=D23)* ('Dev 조치사항'!$K$6:$K$1004=_xlfn.MAXIFS('Dev 조치사항'!$K$6:$K$1004, 'Dev 조치사항'!$D$6:$D$1004, D23)), 0) ) )} -> - | K23: =_xlfn.MAXIFS('Dev 조치사항'!$K$6:$K$1004, 'Dev 조치사항'!$D$6:$D$1004, D23) -> 46315
D24: AD230_TC_019 | E24: 필수값을 모두 넣어 정기점검주기를 생성한다. | F24: 1. 생성 클릭 2. 작업명, 주기(숫자+주기구분), 근무달력 입력(Lov 선택), 그 외 담당자·작업그룹 입력 3. 저장 → OK | G24: 저장 완료, 목록에 새 행 추가, 상세 제목에 예방작업번호 / 작업명 표시 | H24: {=INDEX('Dev 조치사항'!$H$6:$H$1004, MATCH(1, ('Dev 조치사항'!$D$6:$D$1004=D24)*('Dev 조치사항'!$K$6:$K$1004=_xlfn.MAXIFS('Dev 조치사항'!$K$6:$K$1004, 'Dev 조치사항'!$D$6:$D$1004, D24)), 0))} -> 최신영 | I24: {=INDEX('Dev 조치사항'!$I$6:$I$1004, MATCH(1, ('Dev 조치사항'!$D$6:$D$1004=D24)*('Dev 조치사항'!$K$6:$K$1004=_xlfn.MAXIFS('Dev 조치사항'!$K$6:$K$1004, 'Dev 조치사항'!$D$6:$D$1004, D24)), 0))} -> 정상 | J24: {=IF( INDEX('Dev 조치사항'!$J$6:$J$1004, MATCH(1, ('Dev 조치사항'!$D$6:$D$1004=D24)* ('Dev 조치사항'!$K$6:$K$1004=_xlfn.MAXIFS('Dev 조치사항'!$K$6:$K$1004, 'Dev 조치사항'!$D$6:$D$1004, D24)), 0) ) = "", "-", INDEX('Dev 조치사항'!$J$6:$J$1004, MATCH(1, ('Dev 조치사항'!$D$6:$D$1004=D24)* ('Dev 조치사항'!$K$6:$K$1004=_xlfn.MAXIFS('Dev 조치사항'!$K$6:$K$1004, 'Dev 조치사항'!$D$6:$D$1004, D24)), 0) ) )} -> - | K24: =_xlfn.MAXIFS('Dev 조치사항'!$K$6:$K$1004, 'Dev 조치사항'!$D$6:$D$1004, D24) -> 46315
D25: AD230_TC_020 | E25: 필수값을 하나씩 비우고 저장한다. | F25: 작업명, 일정생성방법, 주기, 몇일전 일정생성?, 근무달력, 부서명을 하나씩 비운 채 저장 → OK | G25: 각각 필수값 누락 팝업이 뜨고 저장되지 않음 (6건 모두) | H25: {=INDEX('Dev 조치사항'!$H$6:$H$1004, MATCH(1, ('Dev 조치사항'!$D$6:$D$1004=D25)*('Dev 조치사항'!$K$6:$K$1004=_xlfn.MAXIFS('Dev 조치사항'!$K$6:$K$1004, 'Dev 조치사항'!$D$6:$D$1004, D25)), 0))} -> 최신영 | I25: {=INDEX('Dev 조치사항'!$I$6:$I$1004, MATCH(1, ('Dev 조치사항'!$D$6:$D$1004=D25)*('Dev 조치사항'!$K$6:$K$1004=_xlfn.MAXIFS('Dev 조치사항'!$K$6:$K$1004, 'Dev 조치사항'!$D$6:$D$1004, D25)), 0))} -> 정상 | J25: {=IF( INDEX('Dev 조치사항'!$J$6:$J$1004, MATCH(1, ('Dev 조치사항'!$D$6:$D$1004=D25)* ('Dev 조치사항'!$K$6:$K$1004=_xlfn.MAXIFS('Dev 조치사항'!$K$6:$K$1004, 'Dev 조치사항'!$D$6:$D$1004, D25)), 0) ) = "", "-", INDEX('Dev 조치사항'!$J$6:$J$1004, MATCH(1, ('Dev 조치사항'!$D$6:$D$1004=D25)* ('Dev 조치사항'!$K$6:$K$1004=_xlfn.MAXIFS('Dev 조치사항'!$K$6:$K$1004, 'Dev 조치사항'!$D$6:$D$1004, D25)), 0) ) )} -> - | K25: =_xlfn.MAXIFS('Dev 조치사항'!$K$6:$K$1004, 'Dev 조치사항'!$D$6:$D$1004, D25) -> 46315
C26: 수정 | D26: AD230_TC_021 | E26: 저장된 정기점검주기를 수정한다. | F26: 상세에서 작업명, 주기, 담당자, 비고 변경 후 저장 → OK | G26: 변경 내용이 상세와 목록에 반영됨 (팝업에서 수정한 경우 재검색 후 반영) | H26: {=INDEX('Dev 조치사항'!$H$6:$H$1004, MATCH(1, ('Dev 조치사항'!$D$6:$D$1004=D26)*('Dev 조치사항'!$K$6:$K$1004=_xlfn.MAXIFS('Dev 조치사항'!$K$6:$K$1004, 'Dev 조치사항'!$D$6:$D$1004, D26)), 0))} -> 최신영 | I26: {=INDEX('Dev 조치사항'!$I$6:$I$1004, MATCH(1, ('Dev 조치사항'!$D$6:$D$1004=D26)*('Dev 조치사항'!$K$6:$K$1004=_xlfn.MAXIFS('Dev 조치사항'!$K$6:$K$1004, 'Dev 조치사항'!$D$6:$D$1004, D26)), 0))} -> 정상 | J26: {=IF( INDEX('Dev 조치사항'!$J$6:$J$1004, MATCH(1, ('Dev 조치사항'!$D$6:$D$1004=D26)* ('Dev 조치사항'!$K$6:$K$1004=_xlfn.MAXIFS('Dev 조치사항'!$K$6:$K$1004, 'Dev 조치사항'!$D$6:$D$1004, D26)), 0) ) = "", "-", INDEX('Dev 조치사항'!$J$6:$J$1004, MATCH(1, ('Dev 조치사항'!$D$6:$D$1004=D26)* ('Dev 조치사항'!$K$6:$K$1004=_xlfn.MAXIFS('Dev 조치사항'!$K$6:$K$1004, 'Dev 조치사항'!$D$6:$D$1004, D26)), 0) ) )} -> - | K26: =_xlfn.MAXIFS('Dev 조치사항'!$K$6:$K$1004, 'Dev 조치사항'!$D$6:$D$1004, D26) -> 46315
D27: AD230_TC_022 | E27: 필수값을 지우고 수정한다. | F27: 상세에서 작업명을 지운 뒤 저장 → OK | G27: 필수값 누락 팝업이 뜨고 수정되지 않음 | H27: {=INDEX('Dev 조치사항'!$H$6:$H$1004, MATCH(1, ('Dev 조치사항'!$D$6:$D$1004=D27)*('Dev 조치사항'!$K$6:$K$1004=_xlfn.MAXIFS('Dev 조치사항'!$K$6:$K$1004, 'Dev 조치사항'!$D$6:$D$1004, D27)), 0))} -> 최신영 | I27: {=INDEX('Dev 조치사항'!$I$6:$I$1004, MATCH(1, ('Dev 조치사항'!$D$6:$D$1004=D27)*('Dev 조치사항'!$K$6:$K$1004=_xlfn.MAXIFS('Dev 조치사항'!$K$6:$K$1004, 'Dev 조치사항'!$D$6:$D$1004, D27)), 0))} -> 정상 | J27: {=IF( INDEX('Dev 조치사항'!$J$6:$J$1004, MATCH(1, ('Dev 조치사항'!$D$6:$D$1004=D27)* ('Dev 조치사항'!$K$6:$K$1004=_xlfn.MAXIFS('Dev 조치사항'!$K$6:$K$1004, 'Dev 조치사항'!$D$6:$D$1004, D27)), 0) ) = "", "-", INDEX('Dev 조치사항'!$J$6:$J$1004, MATCH(1, ('Dev 조치사항'!$D$6:$D$1004=D27)* ('Dev 조치사항'!$K$6:$K$1004=_xlfn.MAXIFS('Dev 조치사항'!$K$6:$K$1004, 'Dev 조치사항'!$D$6:$D$1004, D27)), 0) ) )} -> - | K27: =_xlfn.MAXIFS('Dev 조치사항'!$K$6:$K$1004, 'Dev 조치사항'!$D$6:$D$1004, D27) -> 46315
C28: 삭제 | D28: AD230_TC_023 | E28: 선택한 정기점검주기를 삭제한다. (체크O) | F28: 목록 좌측 체크박스로 이 테스트에서 만든 데이터 선택 → 삭제 → OK (탭별로 확인) | G28: 선택한 데이터가 삭제되고 목록에서 사라짐 | H28: {=INDEX('Dev 조치사항'!$H$6:$H$1004, MATCH(1, ('Dev 조치사항'!$D$6:$D$1004=D28)*('Dev 조치사항'!$K$6:$K$1004=_xlfn.MAXIFS('Dev 조치사항'!$K$6:$K$1004, 'Dev 조치사항'!$D$6:$D$1004, D28)), 0))} -> 최신영 | I28: {=INDEX('Dev 조치사항'!$I$6:$I$1004, MATCH(1, ('Dev 조치사항'!$D$6:$D$1004=D28)*('Dev 조치사항'!$K$6:$K$1004=_xlfn.MAXIFS('Dev 조치사항'!$K$6:$K$1004, 'Dev 조치사항'!$D$6:$D$1004, D28)), 0))} -> 정상 | J28: {=IF( INDEX('Dev 조치사항'!$J$6:$J$1004, MATCH(1, ('Dev 조치사항'!$D$6:$D$1004=D28)* ('Dev 조치사항'!$K$6:$K$1004=_xlfn.MAXIFS('Dev 조치사항'!$K$6:$K$1004, 'Dev 조치사항'!$D$6:$D$1004, D28)), 0) ) = "", "-", INDEX('Dev 조치사항'!$J$6:$J$1004, MATCH(1, ('Dev 조치사항'!$D$6:$D$1004=D28)* ('Dev 조치사항'!$K$6:$K$1004=_xlfn.MAXIFS('Dev 조치사항'!$K$6:$K$1004, 'Dev 조치사항'!$D$6:$D$1004, D28)), 0) ) )} -> - | K28: =_xlfn.MAXIFS('Dev 조치사항'!$K$6:$K$1004, 'Dev 조치사항'!$D$6:$D$1004, D28) -> 46315
D29: AD230_TC_024 | E29: 선택 없이 삭제한다. (체크X) | F29: 체크박스 선택 없이 삭제 클릭 | G29: "선택된 데이터가 없습니다" 팝업, 삭제되지 않음 | H29: {=INDEX('Dev 조치사항'!$H$6:$H$1004, MATCH(1, ('Dev 조치사항'!$D$6:$D$1004=D29)*('Dev 조치사항'!$K$6:$K$1004=_xlfn.MAXIFS('Dev 조치사항'!$K$6:$K$1004, 'Dev 조치사항'!$D$6:$D$1004, D29)), 0))} -> 최신영 | I29: {=INDEX('Dev 조치사항'!$I$6:$I$1004, MATCH(1, ('Dev 조치사항'!$D$6:$D$1004=D29)*('Dev 조치사항'!$K$6:$K$1004=_xlfn.MAXIFS('Dev 조치사항'!$K$6:$K$1004, 'Dev 조치사항'!$D$6:$D$1004, D29)), 0))} -> 정상 | J29: {=IF( INDEX('Dev 조치사항'!$J$6:$J$1004, MATCH(1, ('Dev 조치사항'!$D$6:$D$1004=D29)* ('Dev 조치사항'!$K$6:$K$1004=_xlfn.MAXIFS('Dev 조치사항'!$K$6:$K$1004, 'Dev 조치사항'!$D$6:$D$1004, D29)), 0) ) = "", "-", INDEX('Dev 조치사항'!$J$6:$J$1004, MATCH(1, ('Dev 조치사항'!$D$6:$D$1004=D29)* ('Dev 조치사항'!$K$6:$K$1004=_xlfn.MAXIFS('Dev 조치사항'!$K$6:$K$1004, 'Dev 조치사항'!$D$6:$D$1004, D29)), 0) ) )} -> [개선] 목록에서 아무것도 체크하지 않고 [삭제] → '선택하세요' 같은 안내 메시지 없음 (확인창이 뜨면 Cancel) | K29: =_xlfn.MAXIFS('Dev 조치사항'!$K$6:$K$1004, 'Dev 조치사항'!$D$6:$D$1004, D29) -> 46315
C30: Excel | D30: AD230_TC_025 | E30: 목록을 Excel로 다운로드한다. | F30: 1. 조건 검색 2. Excel 버튼 클릭 후 파일 열기 | G30: 조회된 데이터가 담긴 Excel 파일이 받아지고, 행 수와 열 이름이 목록과 같음 (조회 결과가 없으면 헤더만 있음) | H30: {=INDEX('Dev 조치사항'!$H$6:$H$1004, MATCH(1, ('Dev 조치사항'!$D$6:$D$1004=D30)*('Dev 조치사항'!$K$6:$K$1004=_xlfn.MAXIFS('Dev 조치사항'!$K$6:$K$1004, 'Dev 조치사항'!$D$6:$D$1004, D30)), 0))} -> 최신영 | I30: {=INDEX('Dev 조치사항'!$I$6:$I$1004, MATCH(1, ('Dev 조치사항'!$D$6:$D$1004=D30)*('Dev 조치사항'!$K$6:$K$1004=_xlfn.MAXIFS('Dev 조치사항'!$K$6:$K$1004, 'Dev 조치사항'!$D$6:$D$1004, D30)), 0))} -> 정상 | J30: {=IF( INDEX('Dev 조치사항'!$J$6:$J$1004, MATCH(1, ('Dev 조치사항'!$D$6:$D$1004=D30)* ('Dev 조치사항'!$K$6:$K$1004=_xlfn.MAXIFS('Dev 조치사항'!$K$6:$K$1004, 'Dev 조치사항'!$D$6:$D$1004, D30)), 0) ) = "", "-", INDEX('Dev 조치사항'!$J$6:$J$1004, MATCH(1, ('Dev 조치사항'!$D$6:$D$1004=D30)* ('Dev 조치사항'!$K$6:$K$1004=_xlfn.MAXIFS('Dev 조치사항'!$K$6:$K$1004, 'Dev 조치사항'!$D$6:$D$1004, D30)), 0) ) )} -> - | K30: =_xlfn.MAXIFS('Dev 조치사항'!$K$6:$K$1004, 'Dev 조치사항'!$D$6:$D$1004, D30) -> 46315
C31: Setting | D31: AD230_TC_026 | E31: Setting(사용자정의)에서 설정을 바꾸면 화면에 반영되는지 확인한다. | F31: 목록 Setting: 칼럼 숨기기/보이기, 정렬값·너비 수정, 리스트 길이 수정, 초기화 검색 Setting: 필드 숨기기/보이기, 정렬값 수정, 초기화 Tab 설정: 상세 탭 숨기기 후 초기화 (끝나면 원래 값으로 되돌림) | G31: 바꾼 설정이 목록·검색 영역·상세 탭에 반영되고, 되돌리거나 초기화하면 원래대로 돌아옴 ※ Setting 은 개인 저장 (내 계정에만 적용) | H31: {=INDEX('Dev 조치사항'!$H$6:$H$1004, MATCH(1, ('Dev 조치사항'!$D$6:$D$1004=D31)*('Dev 조치사항'!$K$6:$K$1004=_xlfn.MAXIFS('Dev 조치사항'!$K$6:$K$1004, 'Dev 조치사항'!$D$6:$D$1004, D31)), 0))} -> 최신영 | I31: {=INDEX('Dev 조치사항'!$I$6:$I$1004, MATCH(1, ('Dev 조치사항'!$D$6:$D$1004=D31)*('Dev 조치사항'!$K$6:$K$1004=_xlfn.MAXIFS('Dev 조치사항'!$K$6:$K$1004, 'Dev 조치사항'!$D$6:$D$1004, D31)), 0))} -> 정상 | J31: {=IF( INDEX('Dev 조치사항'!$J$6:$J$1004, MATCH(1, ('Dev 조치사항'!$D$6:$D$1004=D31)* ('Dev 조치사항'!$K$6:$K$1004=_xlfn.MAXIFS('Dev 조치사항'!$K$6:$K$1004, 'Dev 조치사항'!$D$6:$D$1004, D31)), 0) ) = "", "-", INDEX('Dev 조치사항'!$J$6:$J$1004, MATCH(1, ('Dev 조치사항'!$D$6:$D$1004=D31)* ('Dev 조치사항'!$K$6:$K$1004=_xlfn.MAXIFS('Dev 조치사항'!$K$6:$K$1004, 'Dev 조치사항'!$D$6:$D$1004, D31)), 0) ) )} -> - | K31: =_xlfn.MAXIFS('Dev 조치사항'!$K$6:$K$1004, 'Dev 조치사항'!$D$6:$D$1004, D31) -> 46315
C32: 일정생성 | D32: AD230_TC_027 | E32: TBM 정기점검주기의 일정을 생성한다. | F32: 1. 저장된 정기점검주기(설비 포함) 상세에서 일정생성 클릭 → OK 2. [정기점검계획] 메뉴에서 해당 예방작업번호 조회 | G32: 완료 메시지 표시, 정기점검계획에 설비별 계획이 생성되고 첫 일정은 설비의 최초작업예정일 기준, 이후 일정은 주기 간격 | H32: {=INDEX('Dev 조치사항'!$H$6:$H$1004, MATCH(1, ('Dev 조치사항'!$D$6:$D$1004=D32)*('Dev 조치사항'!$K$6:$K$1004=_xlfn.MAXIFS('Dev 조치사항'!$K$6:$K$1004, 'Dev 조치사항'!$D$6:$D$1004, D32)), 0))} -> 최신영 | I32: {=INDEX('Dev 조치사항'!$I$6:$I$1004, MATCH(1, ('Dev 조치사항'!$D$6:$D$1004=D32)*('Dev 조치사항'!$K$6:$K$1004=_xlfn.MAXIFS('Dev 조치사항'!$K$6:$K$1004, 'Dev 조치사항'!$D$6:$D$1004, D32)), 0))} -> 정상 | J32: {=IF( INDEX('Dev 조치사항'!$J$6:$J$1004, MATCH(1, ('Dev 조치사항'!$D$6:$D$1004=D32)* ('Dev 조치사항'!$K$6:$K$1004=_xlfn.MAXIFS('Dev 조치사항'!$K$6:$K$1004, 'Dev 조치사항'!$D$6:$D$1004, D32)), 0) ) = "", "-", INDEX('Dev 조치사항'!$J$6:$J$1004, MATCH(1, ('Dev 조치사항'!$D$6:$D$1004=D32)* ('Dev 조치사항'!$K$6:$K$1004=_xlfn.MAXIFS('Dev 조치사항'!$K$6:$K$1004, 'Dev 조치사항'!$D$6:$D$1004, D32)), 0) ) )} -> - | K32: =_xlfn.MAXIFS('Dev 조치사항'!$K$6:$K$1004, 'Dev 조치사항'!$D$6:$D$1004, D32) -> 46315
D33: AD230_TC_028 | E33: 저장 전에 일정생성을 누른다. | F33: 생성 클릭 후 값만 입력하고 저장하지 않은 상태에서 일정생성 클릭 | G33: 저장이 필요하다는 안내가 뜨고 일정이 생성되지 않음 | H33: {=INDEX('Dev 조치사항'!$H$6:$H$1004, MATCH(1, ('Dev 조치사항'!$D$6:$D$1004=D33)*('Dev 조치사항'!$K$6:$K$1004=_xlfn.MAXIFS('Dev 조치사항'!$K$6:$K$1004, 'Dev 조치사항'!$D$6:$D$1004, D33)), 0))} -> 최신영 | I33: {=INDEX('Dev 조치사항'!$I$6:$I$1004, MATCH(1, ('Dev 조치사항'!$D$6:$D$1004=D33)*('Dev 조치사항'!$K$6:$K$1004=_xlfn.MAXIFS('Dev 조치사항'!$K$6:$K$1004, 'Dev 조치사항'!$D$6:$D$1004, D33)), 0))} -> 정상 | J33: {=IF( INDEX('Dev 조치사항'!$J$6:$J$1004, MATCH(1, ('Dev 조치사항'!$D$6:$D$1004=D33)* ('Dev 조치사항'!$K$6:$K$1004=_xlfn.MAXIFS('Dev 조치사항'!$K$6:$K$1004, 'Dev 조치사항'!$D$6:$D$1004, D33)), 0) ) = "", "-", INDEX('Dev 조치사항'!$J$6:$J$1004, MATCH(1, ('Dev 조치사항'!$D$6:$D$1004=D33)* ('Dev 조치사항'!$K$6:$K$1004=_xlfn.MAXIFS('Dev 조치사항'!$K$6:$K$1004, 'Dev 조치사항'!$D$6:$D$1004, D33)), 0) ) )} -> [개선] 저장 전에 [일정생성] → 확인창·안내 없이 아무 반응 없음. (저장 후 일정생성도 완료 안내는 없음) | K33: =_xlfn.MAXIFS('Dev 조치사항'!$K$6:$K$1004, 'Dev 조치사항'!$D$6:$D$1004, D33) -> 46315
C34: Linked | D34: AD230_TC_029 | E34: 점검일정을 확인한다. | F34: 상세의 Linked → 점검일정 클릭 | G34: 해당 예방작업번호의 점검일정이 팝업(목록(조건))으로 열림 | H34: {=INDEX('Dev 조치사항'!$H$6:$H$1004, MATCH(1, ('Dev 조치사항'!$D$6:$D$1004=D34)*('Dev 조치사항'!$K$6:$K$1004=_xlfn.MAXIFS('Dev 조치사항'!$K$6:$K$1004, 'Dev 조치사항'!$D$6:$D$1004, D34)), 0))} -> 최신영 | I34: {=INDEX('Dev 조치사항'!$I$6:$I$1004, MATCH(1, ('Dev 조치사항'!$D$6:$D$1004=D34)*('Dev 조치사항'!$K$6:$K$1004=_xlfn.MAXIFS('Dev 조치사항'!$K$6:$K$1004, 'Dev 조치사항'!$D$6:$D$1004, D34)), 0))} -> 정상 | J34: {=IF( INDEX('Dev 조치사항'!$J$6:$J$1004, MATCH(1, ('Dev 조치사항'!$D$6:$D$1004=D34)* ('Dev 조치사항'!$K$6:$K$1004=_xlfn.MAXIFS('Dev 조치사항'!$K$6:$K$1004, 'Dev 조치사항'!$D$6:$D$1004, D34)), 0) ) = "", "-", INDEX('Dev 조치사항'!$J$6:$J$1004, MATCH(1, ('Dev 조치사항'!$D$6:$D$1004=D34)* ('Dev 조치사항'!$K$6:$K$1004=_xlfn.MAXIFS('Dev 조치사항'!$K$6:$K$1004, 'Dev 조치사항'!$D$6:$D$1004, D34)), 0) ) )} -> - | K34: =_xlfn.MAXIFS('Dev 조치사항'!$K$6:$K$1004, 'Dev 조치사항'!$D$6:$D$1004, D34) -> 46315
D35: AD230_TC_030 | E35: 연간점검일정을 확인한다. | F35: 상세의 Linked → 연간점검일정 클릭 | G35: 해당 예방작업번호의 연간점검일정이 팝업(카렌다(연간))으로 열림 | H35: {=INDEX('Dev 조치사항'!$H$6:$H$1004, MATCH(1, ('Dev 조치사항'!$D$6:$D$1004=D35)*('Dev 조치사항'!$K$6:$K$1004=_xlfn.MAXIFS('Dev 조치사항'!$K$6:$K$1004, 'Dev 조치사항'!$D$6:$D$1004, D35)), 0))} -> 최신영 | I35: {=INDEX('Dev 조치사항'!$I$6:$I$1004, MATCH(1, ('Dev 조치사항'!$D$6:$D$1004=D35)*('Dev 조치사항'!$K$6:$K$1004=_xlfn.MAXIFS('Dev 조치사항'!$K$6:$K$1004, 'Dev 조치사항'!$D$6:$D$1004, D35)), 0))} -> 정상 | J35: {=IF( INDEX('Dev 조치사항'!$J$6:$J$1004, MATCH(1, ('Dev 조치사항'!$D$6:$D$1004=D35)* ('Dev 조치사항'!$K$6:$K$1004=_xlfn.MAXIFS('Dev 조치사항'!$K$6:$K$1004, 'Dev 조치사항'!$D$6:$D$1004, D35)), 0) ) = "", "-", INDEX('Dev 조치사항'!$J$6:$J$1004, MATCH(1, ('Dev 조치사항'!$D$6:$D$1004=D35)* ('Dev 조치사항'!$K$6:$K$1004=_xlfn.MAXIFS('Dev 조치사항'!$K$6:$K$1004, 'Dev 조치사항'!$D$6:$D$1004, D35)), 0) ) )} -> - | K35: =_xlfn.MAXIFS('Dev 조치사항'!$K$6:$K$1004, 'Dev 조치사항'!$D$6:$D$1004, D35) -> 46315
B36: 설비 | C36: 탭조회 | D36: AD230_TC_031 | E36: 설비 목록을 조회한다. | F36: 상세 하단 설비 목록 확인 | G36: 등록된 설비가 표시되고 제목 옆 숫자, Total 과 행 수가 일치함 | H36: {=INDEX('Dev 조치사항'!$H$6:$H$1004, MATCH(1, ('Dev 조치사항'!$D$6:$D$1004=D36)*('Dev 조치사항'!$K$6:$K$1004=_xlfn.MAXIFS('Dev 조치사항'!$K$6:$K$1004, 'Dev 조치사항'!$D$6:$D$1004, D36)), 0))} -> 최신영 | I36: {=INDEX('Dev 조치사항'!$I$6:$I$1004, MATCH(1, ('Dev 조치사항'!$D$6:$D$1004=D36)*('Dev 조치사항'!$K$6:$K$1004=_xlfn.MAXIFS('Dev 조치사항'!$K$6:$K$1004, 'Dev 조치사항'!$D$6:$D$1004, D36)), 0))} -> 정상 | J36: {=IF( INDEX('Dev 조치사항'!$J$6:$J$1004, MATCH(1, ('Dev 조치사항'!$D$6:$D$1004=D36)* ('Dev 조치사항'!$K$6:$K$1004=_xlfn.MAXIFS('Dev 조치사항'!$K$6:$K$1004, 'Dev 조치사항'!$D$6:$D$1004, D36)), 0) ) = "", "-", INDEX('Dev 조치사항'!$J$6:$J$1004, MATCH(1, ('Dev 조치사항'!$D$6:$D$1004=D36)* ('Dev 조치사항'!$K$6:$K$1004=_xlfn.MAXIFS('Dev 조치사항'!$K$6:$K$1004, 'Dev 조치사항'!$D$6:$D$1004, D36)), 0) ) )} -> - | K36: =_xlfn.MAXIFS('Dev 조치사항'!$K$6:$K$1004, 'Dev 조치사항'!$D$6:$D$1004, D36) -> 46315
C37: 탭생성 | D37: AD230_TC_032 | E37: 설비를 추가한다. | F37: 설비 목록의 생성 → 설비 돋보기(Lov)에서 설비 조회·선택 → 최초작업예정일 입력 → 저장 → OK | G37: 선택한 설비가 목록에 추가되고 설비번호·설비명·설비위치가 Lov에서 고른 값과 같음 | H37: {=INDEX('Dev 조치사항'!$H$6:$H$1004, MATCH(1, ('Dev 조치사항'!$D$6:$D$1004=D37)*('Dev 조치사항'!$K$6:$K$1004=_xlfn.MAXIFS('Dev 조치사항'!$K$6:$K$1004, 'Dev 조치사항'!$D$6:$D$1004, D37)), 0))} -> 최신영 | I37: {=INDEX('Dev 조치사항'!$I$6:$I$1004, MATCH(1, ('Dev 조치사항'!$D$6:$D$1004=D37)*('Dev 조치사항'!$K$6:$K$1004=_xlfn.MAXIFS('Dev 조치사항'!$K$6:$K$1004, 'Dev 조치사항'!$D$6:$D$1004, D37)), 0))} -> 정상 | J37: {=IF( INDEX('Dev 조치사항'!$J$6:$J$1004, MATCH(1, ('Dev 조치사항'!$D$6:$D$1004=D37)* ('Dev 조치사항'!$K$6:$K$1004=_xlfn.MAXIFS('Dev 조치사항'!$K$6:$K$1004, 'Dev 조치사항'!$D$6:$D$1004, D37)), 0) ) = "", "-", INDEX('Dev 조치사항'!$J$6:$J$1004, MATCH(1, ('Dev 조치사항'!$D$6:$D$1004=D37)* ('Dev 조치사항'!$K$6:$K$1004=_xlfn.MAXIFS('Dev 조치사항'!$K$6:$K$1004, 'Dev 조치사항'!$D$6:$D$1004, D37)), 0) ) )} -> - | K37: =_xlfn.MAXIFS('Dev 조치사항'!$K$6:$K$1004, 'Dev 조치사항'!$D$6:$D$1004, D37) -> 46315
D38: AD230_TC_033 | E38: 설비를 필수값 없이 추가한다. | F38: 설비 목록의 생성 → 설비를 고르지 않고 저장 → OK | G38: 필수값 누락 팝업, 저장되지 않음 | H38: {=INDEX('Dev 조치사항'!$H$6:$H$1004, MATCH(1, ('Dev 조치사항'!$D$6:$D$1004=D38)*('Dev 조치사항'!$K$6:$K$1004=_xlfn.MAXIFS('Dev 조치사항'!$K$6:$K$1004, 'Dev 조치사항'!$D$6:$D$1004, D38)), 0))} -> 최신영 | I38: {=INDEX('Dev 조치사항'!$I$6:$I$1004, MATCH(1, ('Dev 조치사항'!$D$6:$D$1004=D38)*('Dev 조치사항'!$K$6:$K$1004=_xlfn.MAXIFS('Dev 조치사항'!$K$6:$K$1004, 'Dev 조치사항'!$D$6:$D$1004, D38)), 0))} -> 정상 | J38: {=IF( INDEX('Dev 조치사항'!$J$6:$J$1004, MATCH(1, ('Dev 조치사항'!$D$6:$D$1004=D38)* ('Dev 조치사항'!$K$6:$K$1004=_xlfn.MAXIFS('Dev 조치사항'!$K$6:$K$1004, 'Dev 조치사항'!$D$6:$D$1004, D38)), 0) ) = "", "-", INDEX('Dev 조치사항'!$J$6:$J$1004, MATCH(1, ('Dev 조치사항'!$D$6:$D$1004=D38)* ('Dev 조치사항'!$K$6:$K$1004=_xlfn.MAXIFS('Dev 조치사항'!$K$6:$K$1004, 'Dev 조치사항'!$D$6:$D$1004, D38)), 0) ) )} -> - | K38: =_xlfn.MAXIFS('Dev 조치사항'!$K$6:$K$1004, 'Dev 조치사항'!$D$6:$D$1004, D38) -> 46315
C39: 탭수정 | D39: AD230_TC_034 | E39: 설비의 최초작업예정일·시행여부를 수정한다. | F39: 설비 행 클릭 → 최초작업예정일, 시행여부 변경 → 저장 → OK | G39: 변경 내용이 설비 목록에 반영됨 | H39: {=INDEX('Dev 조치사항'!$H$6:$H$1004, MATCH(1, ('Dev 조치사항'!$D$6:$D$1004=D39)*('Dev 조치사항'!$K$6:$K$1004=_xlfn.MAXIFS('Dev 조치사항'!$K$6:$K$1004, 'Dev 조치사항'!$D$6:$D$1004, D39)), 0))} -> 최신영 | I39: {=INDEX('Dev 조치사항'!$I$6:$I$1004, MATCH(1, ('Dev 조치사항'!$D$6:$D$1004=D39)*('Dev 조치사항'!$K$6:$K$1004=_xlfn.MAXIFS('Dev 조치사항'!$K$6:$K$1004, 'Dev 조치사항'!$D$6:$D$1004, D39)), 0))} -> 정상 | J39: {=IF( INDEX('Dev 조치사항'!$J$6:$J$1004, MATCH(1, ('Dev 조치사항'!$D$6:$D$1004=D39)* ('Dev 조치사항'!$K$6:$K$1004=_xlfn.MAXIFS('Dev 조치사항'!$K$6:$K$1004, 'Dev 조치사항'!$D$6:$D$1004, D39)), 0) ) = "", "-", INDEX('Dev 조치사항'!$J$6:$J$1004, MATCH(1, ('Dev 조치사항'!$D$6:$D$1004=D39)* ('Dev 조치사항'!$K$6:$K$1004=_xlfn.MAXIFS('Dev 조치사항'!$K$6:$K$1004, 'Dev 조치사항'!$D$6:$D$1004, D39)), 0) ) )} -> - | K39: =_xlfn.MAXIFS('Dev 조치사항'!$K$6:$K$1004, 'Dev 조치사항'!$D$6:$D$1004, D39) -> 46315
C40: 탭삭제 | D40: AD230_TC_035 | E40: 설비를 삭제한다. (체크O / 체크X) | F40: ① 체크 후 삭제 → OK ② 체크 없이 삭제 | G40: ① 선택한 설비만 삭제됨 ② "선택된 데이터가 없습니다" 팝업 | H40: {=INDEX('Dev 조치사항'!$H$6:$H$1004, MATCH(1, ('Dev 조치사항'!$D$6:$D$1004=D40)*('Dev 조치사항'!$K$6:$K$1004=_xlfn.MAXIFS('Dev 조치사항'!$K$6:$K$1004, 'Dev 조치사항'!$D$6:$D$1004, D40)), 0))} -> 최신영 | I40: {=INDEX('Dev 조치사항'!$I$6:$I$1004, MATCH(1, ('Dev 조치사항'!$D$6:$D$1004=D40)*('Dev 조치사항'!$K$6:$K$1004=_xlfn.MAXIFS('Dev 조치사항'!$K$6:$K$1004, 'Dev 조치사항'!$D$6:$D$1004, D40)), 0))} -> 정상 | J40: {=IF( INDEX('Dev 조치사항'!$J$6:$J$1004, MATCH(1, ('Dev 조치사항'!$D$6:$D$1004=D40)* ('Dev 조치사항'!$K$6:$K$1004=_xlfn.MAXIFS('Dev 조치사항'!$K$6:$K$1004, 'Dev 조치사항'!$D$6:$D$1004, D40)), 0) ) = "", "-", INDEX('Dev 조치사항'!$J$6:$J$1004, MATCH(1, ('Dev 조치사항'!$D$6:$D$1004=D40)* ('Dev 조치사항'!$K$6:$K$1004=_xlfn.MAXIFS('Dev 조치사항'!$K$6:$K$1004, 'Dev 조치사항'!$D$6:$D$1004, D40)), 0) ) )} -> [개선] 체크 없이 [삭제] → '선택하세요' 안내 없이 바로 '삭제 하시겠습니까?' 확인창이 뜸 (Cancel 로 닫음, 지워진 것 없음). 100305AG17 체크 삭제 → 2 → 1행, 100302AG13 은 남음 (정상). | K40: =_xlfn.MAXIFS('Dev 조치사항'!$K$6:$K$1004, 'Dev 조치사항'!$D$6:$D$1004, D40) -> 46315
C41: 탭Excel | D41: AD230_TC_036 | E41: 설비 목록을 Excel로 다운로드한다. | F41: 설비 목록의 Excel 클릭 | G41: 설비 목록이 담긴 Excel 파일이 받아짐 (데이터가 없으면 헤더만) | H41: {=INDEX('Dev 조치사항'!$H$6:$H$1004, MATCH(1, ('Dev 조치사항'!$D$6:$D$1004=D41)*('Dev 조치사항'!$K$6:$K$1004=_xlfn.MAXIFS('Dev 조치사항'!$K$6:$K$1004, 'Dev 조치사항'!$D$6:$D$1004, D41)), 0))} -> 최신영 | I41: {=INDEX('Dev 조치사항'!$I$6:$I$1004, MATCH(1, ('Dev 조치사항'!$D$6:$D$1004=D41)*('Dev 조치사항'!$K$6:$K$1004=_xlfn.MAXIFS('Dev 조치사항'!$K$6:$K$1004, 'Dev 조치사항'!$D$6:$D$1004, D41)), 0))} -> 정상 | J41: {=IF( INDEX('Dev 조치사항'!$J$6:$J$1004, MATCH(1, ('Dev 조치사항'!$D$6:$D$1004=D41)* ('Dev 조치사항'!$K$6:$K$1004=_xlfn.MAXIFS('Dev 조치사항'!$K$6:$K$1004, 'Dev 조치사항'!$D$6:$D$1004, D41)), 0) ) = "", "-", INDEX('Dev 조치사항'!$J$6:$J$1004, MATCH(1, ('Dev 조치사항'!$D$6:$D$1004=D41)* ('Dev 조치사항'!$K$6:$K$1004=_xlfn.MAXIFS('Dev 조치사항'!$K$6:$K$1004, 'Dev 조치사항'!$D$6:$D$1004, D41)), 0) ) )} -> - | K41: =_xlfn.MAXIFS('Dev 조치사항'!$K$6:$K$1004, 'Dev 조치사항'!$D$6:$D$1004, D41) -> 46315
B42: 표준작업 | C42: 탭생성/삭제 | D42: AD230_TC_037 | E42: 표준작업을 추가하고 삭제한다. | F42: 표준작업 목록의 생성 → 표준작업 Lov에서 선택 → 저장 → 체크 후 삭제 | G42: 추가 시 목록에 표시되고, 삭제 시 목록에서 사라짐 | H42: {=INDEX('Dev 조치사항'!$H$6:$H$1004, MATCH(1, ('Dev 조치사항'!$D$6:$D$1004=D42)*('Dev 조치사항'!$K$6:$K$1004=_xlfn.MAXIFS('Dev 조치사항'!$K$6:$K$1004, 'Dev 조치사항'!$D$6:$D$1004, D42)), 0))} -> 최신영 | I42: {=INDEX('Dev 조치사항'!$I$6:$I$1004, MATCH(1, ('Dev 조치사항'!$D$6:$D$1004=D42)*('Dev 조치사항'!$K$6:$K$1004=_xlfn.MAXIFS('Dev 조치사항'!$K$6:$K$1004, 'Dev 조치사항'!$D$6:$D$1004, D42)), 0))} -> 정상 | J42: {=IF( INDEX('Dev 조치사항'!$J$6:$J$1004, MATCH(1, ('Dev 조치사항'!$D$6:$D$1004=D42)* ('Dev 조치사항'!$K$6:$K$1004=_xlfn.MAXIFS('Dev 조치사항'!$K$6:$K$1004, 'Dev 조치사항'!$D$6:$D$1004, D42)), 0) ) = "", "-", INDEX('Dev 조치사항'!$J$6:$J$1004, MATCH(1, ('Dev 조치사항'!$D$6:$D$1004=D42)* ('Dev 조치사항'!$K$6:$K$1004=_xlfn.MAXIFS('Dev 조치사항'!$K$6:$K$1004, 'Dev 조치사항'!$D$6:$D$1004, D42)), 0) ) )} -> - | K42: =_xlfn.MAXIFS('Dev 조치사항'!$K$6:$K$1004, 'Dev 조치사항'!$D$6:$D$1004, D42) -> 46315
...

Sheet Dev 조치사항
A2: ="Dream 4.1 "&CLEAN(A6)&" 단위테스트 실행 로그" -> Dream 4.1 정기점검주기_AD230 단위테스트 실행 로그
A4: 공통
A5: 메뉴명 | B5: 탭 명 | C5: 기능 | D5: 테스트ID | E5: CASE | F5: STEP | G5: 테스트 예상 결과 | H5: QA | I5: QA결과 (정상/오류) | J5: QA내용 | K5: QA날짜 | L5: 첨부파일 | M5: Dev | N5: 조치결과 (완료/불가/보류) | O5: 조치내용 | P5: 조치날짜
A6: 정기점검주기_AD230 | B6: 목록(조건) | C6: 검색 | D6: AD230_TC_001 | E6: =IFERROR(VLOOKUP($D6, '테스트 케이스'!$D$6:$G$1001, 2, FALSE), "") -> 검색 필드의 기본값을 확인한다. | F6: =IFERROR(VLOOKUP($D6, '테스트 케이스'!$D$6:$G$1001, 3, FALSE), "") -> 메뉴 접속 후 목록(조건) 탭 클릭 | G6: =IFERROR(VLOOKUP($D6, '테스트 케이스'!$D$6:$G$1001, 4, FALSE), "") -> 시행여부 = Y 로 입력되어 있고, 나머지 검색 필드(예방작업번호, 작업명, 설비, 설비위치, 공장명, 부서명, 작업그룹명, 담당자, 거래처)는 비어 있음 | H6: 최신영 | I6: 정상 | K6: 46315
C7: 검색 | D7: AD230_TC_002 | E7: =IFERROR(VLOOKUP($D7, '테스트 케이스'!$D$6:$G$1001, 2, FALSE), "") -> 설비 Lov 팝업의 데이터를 확인한다. | F7: =IFERROR(VLOOKUP($D7, '테스트 케이스'!$D$6:$G$1001, 3, FALSE), "") -> 설비 필드의 돋보기(Lov) 클릭 → 팝업의 목록(위치) 탭 Total 확인 | G7: =IFERROR(VLOOKUP($D7, '테스트 케이스'!$D$6:$G$1001, 4, FALSE), "") -> "설비" Lov 팝업이 열리고, 목록 건수와 내용이 [설비자산 > 설비] 메뉴 목록과 일치함 | H7: 최신영 | I7: 정상 | K7: 46315
D8: AD230_TC_003 | E8: =IFERROR(VLOOKUP($D8, '테스트 케이스'!$D$6:$G$1001, 2, FALSE), "") -> 그 외 검색 필드 Lov 팝업의 데이터를 확인한다. | F8: =IFERROR(VLOOKUP($D8, '테스트 케이스'!$D$6:$G$1001, 3, FALSE), "") -> 설비위치, 공장명, 부서명, 작업그룹명, 담당자, 거래처, 시행여부의 돋보기(Lov)를 하나씩 클릭 | G8: =IFERROR(VLOOKUP($D8, '테스트 케이스'!$D$6:$G$1001, 4, FALSE), "") -> 각 Lov 팝업이 열리고, 목록이 원본 메뉴(설비위치설정, 공장설정, 부서, 작업그룹, 사원, 거래처, 시스템코드 IS_USE)와 일치함 | H8: 최신영 | I8: 정상 | K8: 46315
D9: AD230_TC_004 | E9: =IFERROR(VLOOKUP($D9, '테스트 케이스'!$D$6:$G$1001, 2, FALSE), "") -> 조건 하나로 정기점검주기를 검색한다. | F9: =IFERROR(VLOOKUP($D9, '테스트 케이스'!$D$6:$G$1001, 3, FALSE), "") -> 검색 필드마다 실제 데이터 값 1개씩 입력(Lov 필드는 Lov에서 선택) 후 검색 버튼 클릭 | G9: =IFERROR(VLOOKUP($D9, '테스트 케이스'!$D$6:$G$1001, 4, FALSE), "") -> 입력한 조건에 맞는 데이터만 목록에 표시되고, 우측 하단 Total 숫자와 조회 건수가 일치함 | H9: 최신영 | I9: 정상 | K9: 46315
D10: AD230_TC_005 | E10: =IFERROR(VLOOKUP($D10, '테스트 케이스'!$D$6:$G$1001, 2, FALSE), "") -> 여러 조건을 조합하여 검색한다. | F10: =IFERROR(VLOOKUP($D10, '테스트 케이스'!$D$6:$G$1001, 3, FALSE), "") -> ① 공장명 + 시행여부 ② 설비 + 부서명 을 함께 입력 후 검색 | G10: =IFERROR(VLOOKUP($D10, '테스트 케이스'!$D$6:$G$1001, 4, FALSE), "") -> 모든 조건을 동시에 만족하는 데이터만 표시됨 | H10: 최신영 | I10: 정상 | K10: 46315
D11: AD230_TC_006 | E11: =IFERROR(VLOOKUP($D11, '테스트 케이스'!$D$6:$G$1001, 2, FALSE), "") -> 정기점검주기 전체를 검색한다. | F11: =IFERROR(VLOOKUP($D11, '테스트 케이스'!$D$6:$G$1001, 3, FALSE), "") -> 검색 필드의 값을 모두 지운 뒤 검색 버튼 클릭 | G11: =IFERROR(VLOOKUP($D11, '테스트 케이스'!$D$6:$G$1001, 4, FALSE), "") -> 시행여부 Y/N 구분 없이 등록된 전체 데이터가 표시되고 Total n/n 이 전체 건수와 일치함 | H11: 최신영 | I11: 정상 | K11: 46315
D12: AD230_TC_007 | E12: =IFERROR(VLOOKUP($D12, '테스트 케이스'!$D$6:$G$1001, 2, FALSE), "") -> 검색 결과가 없는 조건으로 검색한다. | F12: =IFERROR(VLOOKUP($D12, '테스트 케이스'!$D$6:$G$1001, 3, FALSE), "") -> 존재하지 않는 작업명 입력 후 검색 | G12: =IFERROR(VLOOKUP($D12, '테스트 케이스'!$D$6:$G$1001, 4, FALSE), "") -> 목록이 비어 있고 Total 0/0 표시, 오류 팝업 없음 | H12: 최신영 | I12: 정상 | K12: 46315
B13: 목록(위치), 목록(종류) | C13: 검색 | D13: AD230_TC_008 | E13: =IFERROR(VLOOKUP($D13, '테스트 케이스'!$D$6:$G$1001, 2, FALSE), "") -> 트리에서 위치/종류를 선택하여 조회한다. | F13: =IFERROR(VLOOKUP($D13, '테스트 케이스'!$D$6:$G$1001, 3, FALSE), "") -> ① 목록(위치) 탭에서 위치명 트리의 위치 클릭 ② 목록(종류) 탭에서 설비종류 트리의 종류 클릭 | G13: =IFERROR(VLOOKUP($D13, '테스트 케이스'!$D$6:$G$1001, 4, FALSE), "") -> 선택한 위치/종류에 속한 설비의 정기점검주기만 오른쪽 목록에 표시됨 | H13: 최신영 | I13: 정상 | K13: 46315
B14: 목록(위치), 목록(종류), 목록(조건) | C14: 조회 | D14: AD230_TC_009 | E14: =IFERROR(VLOOKUP($D14, '테스트 케이스'!$D$6:$G$1001, 2, FALSE), "") -> 조회된 목록을 정렬한다. | F14: =IFERROR(VLOOKUP($D14, '테스트 케이스'!$D$6:$G$1001, 3, FALSE), "") -> 목록 그리드 헤더(예방작업번호, 작업명, 설비번호) 클릭 2회 | G14: =IFERROR(VLOOKUP($D14, '테스트 케이스'!$D$6:$G$1001, 4, FALSE), "") -> 선택한 열 기준으로 오름차순 → 내림차순 정렬됨 | H14: 최신영 | I14: 정상 | K14: 46315
C15: 조회 | D15: AD230_TC_010 | E15: =IFERROR(VLOOKUP($D15, '테스트 케이스'!$D$6:$G$1001, 2, FALSE), "") -> 목록 건수 표시를 확인한다. | F15: =IFERROR(VLOOKUP($D15, '테스트 케이스'!$D$6:$G$1001, 3, FALSE), "") -> 전체 검색 후 목록을 끝까지 스크롤 | G15: =IFERROR(VLOOKUP($D15, '테스트 케이스'!$D$6:$G$1001, 4, FALSE), "") -> Total a/b 에서 a 는 화면에 불러온 건수, b 는 전체 건수이며 스크롤 시 끝까지 불러오면 a = b | H15: 최신영 | I15: 정상 | K15: 46315
D16: AD230_TC_011 | E16: =IFERROR(VLOOKUP($D16, '테스트 케이스'!$D$6:$G$1001, 2, FALSE), "") -> (행 클릭) 상세정보를 조회한다. | F16: =IFERROR(VLOOKUP($D16, '테스트 케이스'!$D$6:$G$1001, 3, FALSE), "") -> 목록의 데이터 행 클릭 | G16: =IFERROR(VLOOKUP($D16, '테스트 케이스'!$D$6:$G$1001, 4, FALSE), "") -> 목록 하단에 상세(정기점검주기설정 : 번호 / 작업명)가 열리고 해당 데이터 값이 표시됨 | H16: 최신영 | I16: 정상 | K16: 46315
D17: AD230_TC_012 | E17: =IFERROR(VLOOKUP($D17, '테스트 케이스'!$D$6:$G$1001, 2, FALSE), "") -> (상세보기 버튼) 상세정보를 조회한다. | F17: =IFERROR(VLOOKUP($D17, '테스트 케이스'!$D$6:$G$1001, 3, FALSE), "") -> 목록에서 행 선택 후 상세보기 버튼 클릭 | G17: =IFERROR(VLOOKUP($D17, '테스트 케이스'!$D$6:$G$1001, 4, FALSE), "") -> 선택한 데이터의 상세가 팝업창으로 열리며 하단 상세와 내용이 같음 | H17: 최신영 | I17: 정상 | K17: 46315
D18: AD230_TC_013 | E18: =IFERROR(VLOOKUP($D18, '테스트 케이스'!$D$6:$G$1001, 2, FALSE), "") -> 목록과 상세의 값이 일치하는지 확인한다. | F18: =IFERROR(VLOOKUP($D18, '테스트 케이스'!$D$6:$G$1001, 3, FALSE), "") -> 목록 한 행의 예방작업번호, 작업명, 설비, 작업그룹명, 담당자, 일정생성방법, 주기를 상세 값과 비교 | G18: =IFERROR(VLOOKUP($D18, '테스트 케이스'!$D$6:$G$1001, 4, FALSE), "") -> 목록과 상세의 값이 모두 같음 | H18: 최신영 | I18: 정상 | K18: 46315
D19: AD230_TC_014 | E19: =IFERROR(VLOOKUP($D19, '테스트 케이스'!$D$6:$G$1001, 2, FALSE), "") -> (목록) 데이터 표시 형식을 확인한다. | F19: =IFERROR(VLOOKUP($D19, '테스트 케이스'!$D$6:$G$1001, 3, FALSE), "") -> 목록의 숫자, 날짜, 텍스트, 코드 열 확인 | G19: =IFERROR(VLOOKUP($D19, '테스트 케이스'!$D$6:$G$1001, 4, FALSE), "") -> 숫자: 천단위 쉼표, 오른쪽 정렬 / 날짜: yyyy-mm-dd, 가운데 정렬 / 텍스트: 왼쪽 정렬 / 코드: 가운데 정렬 | H19: 최신영 | I19: 정상 | K19: 46315
D20: AD230_TC_015 | E20: =IFERROR(VLOOKUP($D20, '테스트 케이스'!$D$6:$G$1001, 2, FALSE), "") -> (상세) 데이터 표시 형식을 확인한다. | F20: =IFERROR(VLOOKUP($D20, '테스트 케이스'!$D$6:$G$1001, 3, FALSE), "") -> 상세의 숫자(주기, 몇일전 일정생성?, 예상작업시간), 날짜 필드 확인 | G20: =IFERROR(VLOOKUP($D20, '테스트 케이스'!$D$6:$G$1001, 4, FALSE), "") -> 숫자는 오른쪽 정렬, 날짜는 yyyy-mm-dd | H20: 최신영 | I20: 정상 | K20: 46315
D21: AD230_TC_016 | E21: =IFERROR(VLOOKUP($D21, '테스트 케이스'!$D$6:$G$1001, 2, FALSE), "") -> 읽기전용 필드를 확인한다. | F21: =IFERROR(VLOOKUP($D21, '테스트 케이스'!$D$6:$G$1001, 3, FALSE), "") -> 상세에서 작업종류, 작업형태, 예방작업번호 클릭 후 입력 시도 | G21: =IFERROR(VLOOKUP($D21, '테스트 케이스'!$D$6:$G$1001, 4, FALSE), "") -> 회색으로 표시되고 값을 수정할 수 없음 | H21: 최신영 | I21: 정상 | K21: 46315
C22: 닫기 | D22: AD230_TC_017 | E22: =IFERROR(VLOOKUP($D22, '테스트 케이스'!$D$6:$G$1001, 2, FALSE), "") -> 상세를 닫는다. | F22: =IFERROR(VLOOKUP($D22, '테스트 케이스'!$D$6:$G$1001, 3, FALSE), "") -> ① 하단 상세의 닫기(ⓧ) 클릭 ② 상세보기 팝업의 X 클릭 | G22: =IFERROR(VLOOKUP($D22, '테스트 케이스'!$D$6:$G$1001, 4, FALSE), "") -> 상세(팝업)가 닫히고 목록 화면만 남음 | H22: 최신영 | I22: 정상 | K22: 46315
C23: 생성 | D23: AD230_TC_018 | E23: =IFERROR(VLOOKUP($D23, '테스트 케이스'!$D$6:$G$1001, 2, FALSE), "") -> 생성 시 기본값을 확인한다. | F23: =IFERROR(VLOOKUP($D23, '테스트 케이스'!$D$6:$G$1001, 3, FALSE), "") -> 목록의 생성 버튼 클릭 (목록(위치)/(종류)에서는 작업형태 선택) | G23: =IFERROR(VLOOKUP($D23, '테스트 케이스'!$D$6:$G$1001, 4, FALSE), "") -> 빈 상세가 열리고 기본값이 채워짐: 작업종류·작업형태 = 정기점검, 예방작업번호 자동 부여, 시행여부 Y, 일정생성방법 TBM, 몇일전 일정생성? 7, 공장·부서명 = 로그인 사용자 소속 | H23: 최신영 | I23: 정상 | K23: 46315
D24: AD230_TC_019 | E24: =IFERROR(VLOOKUP($D24, '테스트 케이스'!$D$6:$G$1001, 2, FALSE), "") -> 필수값을 모두 넣어 정기점검주기를 생성한다. | F24: =IFERROR(VLOOKUP($D24, '테스트 케이스'!$D$6:$G$1001, 3, FALSE), "") -> 1. 생성 클릭 2. 작업명, 주기(숫자+주기구분), 근무달력 입력(Lov 선택), 그 외 담당자·작업그룹 입력 3. 저장 → OK | G24: =IFERROR(VLOOKUP($D24, '테스트 케이스'!$D$6:$G$1001, 4, FALSE), "") -> 저장 완료, 목록에 새 행 추가, 상세 제목에 예방작업번호 / 작업명 표시 | H24: 최신영 | I24: 정상 | K24: 46315
D25: AD230_TC_020 | E25: =IFERROR(VLOOKUP($D25, '테스트 케이스'!$D$6:$G$1001, 2, FALSE), "") -> 필수값을 하나씩 비우고 저장한다. | F25: =IFERROR(VLOOKUP($D25, '테스트 케이스'!$D$6:$G$1001, 3, FALSE), "") -> 작업명, 일정생성방법, 주기, 몇일전 일정생성?, 근무달력, 부서명을 하나씩 비운 채 저장 → OK | G25: =IFERROR(VLOOKUP($D25, '테스트 케이스'!$D$6:$G$1001, 4, FALSE), "") -> 각각 필수값 누락 팝업이 뜨고 저장되지 않음 (6건 모두) | H25: 최신영 | I25: 정상 | K25: 46315
C26: 수정 | D26: AD230_TC_021 | E26: =IFERROR(VLOOKUP($D26, '테스트 케이스'!$D$6:$G$1001, 2, FALSE), "") -> 저장된 정기점검주기를 수정한다. | F26: =IFERROR(VLOOKUP($D26, '테스트 케이스'!$D$6:$G$1001, 3, FALSE), "") -> 상세에서 작업명, 주기, 담당자, 비고 변경 후 저장 → OK | G26: =IFERROR(VLOOKUP($D26, '테스트 케이스'!$D$6:$G$1001, 4, FALSE), "") -> 변경 내용이 상세와 목록에 반영됨 (팝업에서 수정한 경우 재검색 후 반영) | H26: 최신영 | I26: 정상 | K26: 46315
D27: AD230_TC_022 | E27: =IFERROR(VLOOKUP($D27, '테스트 케이스'!$D$6:$G$1001, 2, FALSE), "") -> 필수값을 지우고 수정한다. | F27: =IFERROR(VLOOKUP($D27, '테스트 케이스'!$D$6:$G$1001, 3, FALSE), "") -> 상세에서 작업명을 지운 뒤 저장 → OK | G27: =IFERROR(VLOOKUP($D27, '테스트 케이스'!$D$6:$G$1001, 4, FALSE), "") -> 필수값 누락 팝업이 뜨고 수정되지 않음 | H27: 최신영 | I27: 정상 | K27: 46315
C28: 삭제 | D28: AD230_TC_023 | E28: =IFERROR(VLOOKUP($D28, '테스트 케이스'!$D$6:$G$1001, 2, FALSE), "") -> 선택한 정기점검주기를 삭제한다. (체크O) | F28: =IFERROR(VLOOKUP($D28, '테스트 케이스'!$D$6:$G$1001, 3, FALSE), "") -> 목록 좌측 체크박스로 이 테스트에서 만든 데이터 선택 → 삭제 → OK (탭별로 확인) | G28: =IFERROR(VLOOKUP($D28, '테스트 케이스'!$D$6:$G$1001, 4, FALSE), "") -> 선택한 데이터가 삭제되고 목록에서 사라짐 | H28: 최신영 | I28: 정상 | K28: 46315
D29: AD230_TC_024 | E29: =IFERROR(VLOOKUP($D29, '테스트 케이스'!$D$6:$G$1001, 2, FALSE), "") -> 선택 없이 삭제한다. (체크X) | F29: =IFERROR(VLOOKUP($D29, '테스트 케이스'!$D$6:$G$1001, 3, FALSE), "") -> 체크박스 선택 없이 삭제 클릭 | G29: =IFERROR(VLOOKUP($D29, '테스트 케이스'!$D$6:$G$1001, 4, FALSE), "") -> "선택된 데이터가 없습니다" 팝업, 삭제되지 않음 | H29: 최신영 | I29: 정상 | J29: [개선] 목록에서 아무것도 체크하지 않고 [삭제] → '선택하세요' 같은 안내 메시지 없음 (확인창이 뜨면 Cancel) | K29: 46315
C30: Excel | D30: AD230_TC_025 | E30: =IFERROR(VLOOKUP($D30, '테스트 케이스'!$D$6:$G$1001, 2, FALSE), "") -> 목록을 Excel로 다운로드한다. | F30: =IFERROR(VLOOKUP($D30, '테스트 케이스'!$D$6:$G$1001, 3, FALSE), "") -> 1. 조건 검색 2. Excel 버튼 클릭 후 파일 열기 | G30: =IFERROR(VLOOKUP($D30, '테스트 케이스'!$D$6:$G$1001, 4, FALSE), "") -> 조회된 데이터가 담긴 Excel 파일이 받아지고, 행 수와 열 이름이 목록과 같음 (조회 결과가 없으면 헤더만 있음) | H30: 최신영 | I30: 정상 | K30: 46315
C31: Setting | D31: AD230_TC_026 | E31: =IFERROR(VLOOKUP($D31, '테스트 케이스'!$D$6:$G$1001, 2, FALSE), "") -> Setting(사용자정의)에서 설정을 바꾸면 화면에 반영되는지 확인한다. | F31: =IFERROR(VLOOKUP($D31, '테스트 케이스'!$D$6:$G$1001, 3, FALSE), "") -> 목록 Setting: 칼럼 숨기기/보이기, 정렬값·너비 수정, 리스트 길이 수정, 초기화 검색 Setting: 필드 숨기기/보이기, 정렬값 수정, 초기화 Tab 설정: 상세 탭 숨기기 후 초기화 (끝나면 원래 값으로 되돌림) | G31: =IFERROR(VLOOKUP($D31, '테스트 케이스'!$D$6:$G$1001, 4, FALSE), "") -> 바꾼 설정이 목록·검색 영역·상세 탭에 반영되고, 되돌리거나 초기화하면 원래대로 돌아옴 ※ Setting 은 개인 저장 (내 계정에만 적용) | H31: 최신영 | I31: 정상 | K31: 46315
C32: 일정생성 | D32: AD230_TC_027 | E32: =IFERROR(VLOOKUP($D32, '테스트 케이스'!$D$6:$G$1001, 2, FALSE), "") -> TBM 정기점검주기의 일정을 생성한다. | F32: =IFERROR(VLOOKUP($D32, '테스트 케이스'!$D$6:$G$1001, 3, FALSE), "") -> 1. 저장된 정기점검주기(설비 포함) 상세에서 일정생성 클릭 → OK 2. [정기점검계획] 메뉴에서 해당 예방작업번호 조회 | G32: =IFERROR(VLOOKUP($D32, '테스트 케이스'!$D$6:$G$1001, 4, FALSE), "") -> 완료 메시지 표시, 정기점검계획에 설비별 계획이 생성되고 첫 일정은 설비의 최초작업예정일 기준, 이후 일정은 주기 간격 | H32: 최신영 | I32: 정상 | K32: 46315
D33: AD230_TC_028 | E33: =IFERROR(VLOOKUP($D33, '테스트 케이스'!$D$6:$G$1001, 2, FALSE), "") -> 저장 전에 일정생성을 누른다. | F33: =IFERROR(VLOOKUP($D33, '테스트 케이스'!$D$6:$G$1001, 3, FALSE), "") -> 생성 클릭 후 값만 입력하고 저장하지 않은 상태에서 일정생성 클릭 | G33: =IFERROR(VLOOKUP($D33, '테스트 케이스'!$D$6:$G$1001, 4, FALSE), "") -> 저장이 필요하다는 안내가 뜨고 일정이 생성되지 않음 | H33: 최신영 | I33: 정상 | J33: [개선] 저장 전에 [일정생성] → 확인창·안내 없이 아무 반응 없음. (저장 후 일정생성도 완료 안내는 없음) | K33: 46315
C34: Linked | D34: AD230_TC_029 | E34: =IFERROR(VLOOKUP($D34, '테스트 케이스'!$D$6:$G$1001, 2, FALSE), "") -> 점검일정을 확인한다. | F34: =IFERROR(VLOOKUP($D34, '테스트 케이스'!$D$6:$G$1001, 3, FALSE), "") -> 상세의 Linked → 점검일정 클릭 | G34: =IFERROR(VLOOKUP($D34, '테스트 케이스'!$D$6:$G$1001, 4, FALSE), "") -> 해당 예방작업번호의 점검일정이 팝업(목록(조건))으로 열림 | H34: 최신영 | I34: 정상 | K34: 46315
D35: AD230_TC_030 | E35: =IFERROR(VLOOKUP($D35, '테스트 케이스'!$D$6:$G$1001, 2, FALSE), "") -> 연간점검일정을 확인한다. | F35: =IFERROR(VLOOKUP($D35, '테스트 케이스'!$D$6:$G$1001, 3, FALSE), "") -> 상세의 Linked → 연간점검일정 클릭 | G35: =IFERROR(VLOOKUP($D35, '테스트 케이스'!$D$6:$G$1001, 4, FALSE), "") -> 해당 예방작업번호의 연간점검일정이 팝업(카렌다(연간))으로 열림 | H35: 최신영 | I35: 정상 | K35: 46315
B36: 설비 | C36: 탭조회 | D36: AD230_TC_031 | E36: =IFERROR(VLOOKUP($D36, '테스트 케이스'!$D$6:$G$1001, 2, FALSE), "") -> 설비 목록을 조회한다. | F36: =IFERROR(VLOOKUP($D36, '테스트 케이스'!$D$6:$G$1001, 3, FALSE), "") -> 상세 하단 설비 목록 확인 | G36: =IFERROR(VLOOKUP($D36, '테스트 케이스'!$D$6:$G$1001, 4, FALSE), "") -> 등록된 설비가 표시되고 제목 옆 숫자, Total 과 행 수가 일치함 | H36: 최신영 | I36: 정상 | K36: 46315
C37: 탭생성 | D37: AD230_TC_032 | E37: =IFERROR(VLOOKUP($D37, '테스트 케이스'!$D$6:$G$1001, 2, FALSE), "") -> 설비를 추가한다. | F37: =IFERROR(VLOOKUP($D37, '테스트 케이스'!$D$6:$G$1001, 3, FALSE), "") -> 설비 목록의 생성 → 설비 돋보기(Lov)에서 설비 조회·선택 → 최초작업예정일 입력 → 저장 → OK | G37: =IFERROR(VLOOKUP($D37, '테스트 케이스'!$D$6:$G$1001, 4, FALSE), "") -> 선택한 설비가 목록에 추가되고 설비번호·설비명·설비위치가 Lov에서 고른 값과 같음 | H37: 최신영 | I37: 정상 | K37: 46315
D38: AD230_TC_033 | E38: =IFERROR(VLOOKUP($D38, '테스트 케이스'!$D$6:$G$1001, 2, FALSE), "") -> 설비를 필수값 없이 추가한다. | F38: =IFERROR(VLOOKUP($D38, '테스트 케이스'!$D$6:$G$1001, 3, FALSE), "") -> 설비 목록의 생성 → 설비를 고르지 않고 저장 → OK | G38: =IFERROR(VLOOKUP($D38, '테스트 케이스'!$D$6:$G$1001, 4, FALSE), "") -> 필수값 누락 팝업, 저장되지 않음 | H38: 최신영 | I38: 정상 | K38: 46315
C39: 탭수정 | D39: AD230_TC_034 | E39: =IFERROR(VLOOKUP($D39, '테스트 케이스'!$D$6:$G$1001, 2, FALSE), "") -> 설비의 최초작업예정일·시행여부를 수정한다. | F39: =IFERROR(VLOOKUP($D39, '테스트 케이스'!$D$6:$G$1001, 3, FALSE), "") -> 설비 행 클릭 → 최초작업예정일, 시행여부 변경 → 저장 → OK | G39: =IFERROR(VLOOKUP($D39, '테스트 케이스'!$D$6:$G$1001, 4, FALSE), "") -> 변경 내용이 설비 목록에 반영됨 | H39: 최신영 | I39: 정상 | K39: 46315
C40: 탭삭제 | D40: AD230_TC_035 | E40: =IFERROR(VLOOKUP($D40, '테스트 케이스'!$D$6:$G$1001, 2, FALSE), "") -> 설비를 삭제한다. (체크O / 체크X) | F40: =IFERROR(VLOOKUP($D40, '테스트 케이스'!$D$6:$G$1001, 3, FALSE), "") -> ① 체크 후 삭제 → OK ② 체크 없이 삭제 | G40: =IFERROR(VLOOKUP($D40, '테스트 케이스'!$D$6:$G$1001, 4, FALSE), "") -> ① 선택한 설비만 삭제됨 ② "선택된 데이터가 없습니다" 팝업 | H40: 최신영 | I40: 정상 | J40: [개선] 체크 없이 [삭제] → '선택하세요' 안내 없이 바로 '삭제 하시겠습니까?' 확인창이 뜸 (Cancel 로 닫음, 지워진 것 없음). 100305AG17 체크 삭제 → 2 → 1행, 100302AG13 은 남음 (정상). | K40: 46315 | L40: TC_041_체크없이삭제_확인창.png (점검항목 목록과 같은 동작)
C41: 탭Excel | D41: AD230_TC_036 | E41: =IFERROR(VLOOKUP($D41, '테스트 케이스'!$D$6:$G$1001, 2, FALSE), "") -> 설비 목록을 Excel로 다운로드한다. | F41: =IFERROR(VLOOKUP($D41, '테스트 케이스'!$D$6:$G$1001, 3, FALSE), "") -> 설비 목록의 Excel 클릭 | G41: =IFERROR(VLOOKUP($D41, '테스트 케이스'!$D$6:$G$1001, 4, FALSE), "") -> 설비 목록이 담긴 Excel 파일이 받아짐 (데이터가 없으면 헤더만) | H41: 최신영 | I41: 정상 | K41: 46315
B42: 표준작업 | C42: 탭생성/삭제 | D42: AD230_TC_037 | E42: =IFERROR(VLOOKUP($D42, '테스트 케이스'!$D$6:$G$1001, 2, FALSE), "") -> 표준작업을 추가하고 삭제한다. | F42: =IFERROR(VLOOKUP($D42, '테스트 케이스'!$D$6:$G$1001, 3, FALSE), "") -> 표준작업 목록의 생성 → 표준작업 Lov에서 선택 → 저장 → 체크 후 삭제 | G42: =IFERROR(VLOOKUP($D42, '테스트 케이스'!$D$6:$G$1001, 4, FALSE), "") -> 추가 시 목록에 표시되고, 삭제 시 목록에서 사라짐 | H42: 최신영 | I42: 정상 | K42: 46315
...
